Workbook

Sheet Cover
B2: =Cover!$C$7&" ("&Cover!$C$8&": "&Cover!$C$9&")" -> Grab Holdings Limited (NASDAQ: GRAB)
B4: Last Updated: | C4: =TODAY() -> 46034
B5: COMPANY INFORMATION
B7: Company Name: | C7: Grab Holdings Limited
B8: Exchange: | C8: NASDAQ
B9: Ticker: | C9: GRAB
B10: Applied Currency: | C10: USD Mn
B11: Scenario: | C11: Base Case
B13: Valuation
B15: DCF - Perpetual Growth Method | C15: =DCF!D51 -> 5.4653114 | D15: 0.4
B16: DCF - Exit Multiple Method | C16: =DCF!N51 -> 10.769891 | D16: 0.4
B17: Relative Valuation - EV/CY 2026 EBITDA | C17: ='Trading Comps'!F204 -> 3.5697554 | D17: 0.2
B18: Target Price | C18: =SUMPRODUCT(C15:C17,D15:D17) -> 7.2080319 | D18: =SUM(D15:D17) -> 1
B19: Current Price: | C19: 5.27
B20: Upside/(Downside): | C20: =(C18-C19)/C19 -> 0.36774798
B22: BUSINESS DESCRIPTION
B23: Grab is a Singapore-based technology company that began as a ride-hailing service and has evolved into a leading super app in Southeast Asia, now offering a broad suite of services including transportation, food and package delivery, and digital payments. The firm's success and research focus span technology innovation, market strategy, competitive positioning, AI applications, and economic impact studies across its regional markets
B29: STYLE GUIDE
B31: Number Format | F31: General Format | G31: Colour Format
B32: _(0.0%_);(0.0%);- | C32: 0.105 | F32: Hardcoded Numbers | G32: #0000FF
B33: _(* #,##0.0_);_(* (#,##0.0);_(* "-"??_);_(@_) | C33: -100000 | F33: Assumptions | G33: #FFFFCC
B34: #,##0.0"x";(#,##0.0)"x" | C34: 10.0x | F34: From Another Sheet | G34: #00B050
B35: "$"#,##0.00 | C35: $10.55 | F35: Dollar Values | G35: #000000
B36: #,##0.0;(#,##0.0) | C36: -20334.118 | F36: Formula | G36: #000000
C127: Adjustments:

Sheet Valuations>>

Sheet 3FS
B1: =Cover!$C$7&" ("&Cover!$C$8&": "&Cover!$C$9&")" -> Grab Holdings Limited (NASDAQ: GRAB)
B3: 12M Target Price: | C3: =Cover!$C$18 -> 7.2080319
B4: Scenario: | C4: Base Case
D5: Historical (31 Dec) | I5: Forecasted (31 Dec)
B6: ="In "&Cover!$C$10&", unless stated otherwise" -> In USD Mn, unless stated otherwise | C6: Units | D6: 20 | E6: =D6+1 -> 21 | F6: =E6+1 -> 22 | G6: =F6+1 -> 23 | H6: =G6+1 -> 24 | I6: =H6+1 -> 25 | J6: =I6+1 -> 26 | K6: =J6+1 -> 27 | L6: =K6+1 -> 28 | M6: =L6+1 -> 29 | O6: Notes:
B8: Deliveries | C8: USD Mns | D8: 5 | E8: 148 | F8: 724 | G8: 1310 | H8: 1493 | I8: ='Revenue Build'!K11 -> 1777.4296 | J8: ='Revenue Build'!L11 -> 2109.9432 | K8: ='Revenue Build'!M11 -> 2528.1524 | L8: ='Revenue Build'!N11 -> 3029.4183 | M8: ='Revenue Build'!O11 -> 3627.8214
B9: Mobility | C9: USD Mns | D9: 438 | E9: 456 | F9: 643 | G9: 871 | H9: 1047 | I9: ='Revenue Build'!K12 -> 1346.1042 | J9: ='Revenue Build'!L12 -> 1729.3739 | K9: ='Revenue Build'!M12 -> 2236.1567 | L9: ='Revenue Build'!N12 -> 2888.0171 | M9: ='Revenue Build'!O12 -> 3724.1225
B10: Financial Services | C10: USD Mns | D10: -10 | E10: 27 | F10: 64 | G10: 177 | H10: 253 | I10: ='Revenue Build'!K13 -> 317.85641 | J10: ='Revenue Build'!L13 -> 394.52885 | K10: ='Revenue Build'!M13 -> 484.23552 | L10: ='Revenue Build'!N13 -> 589.61205 | M10: ='Revenue Build'!O13 -> 719.12533
B11: Enterprise, Others and New Initiatives | C11: USD Mns | D11: 36 | E11: 44 | F11: 2 | G11: 1 | H11: 4 | I11: ='Revenue Build'!K14 -> 5.7676768 | J11: ='Revenue Build'!L14 -> 8.3165238 | K11: ='Revenue Build'!M14 -> 11.991755 | L11: ='Revenue Build'!N14 -> 17.291142 | M11: ='Revenue Build'!O14 -> 24.93243
B12: Total Revenues | C12: USD Mns | D12: =SUM(D8:D11) -> 469 | E12: =SUM(E8:E11) -> 675 | F12: =SUM(F8:F11) -> 1433 | G12: =SUM(G8:G11) -> 2359 | H12: =SUM(H8:H11) -> 2797 | I12: =SUM(I8:I11) -> 3447.158 | J12: =SUM(J8:J11) -> 4242.1624 | K12: =SUM(K8:K11) -> 5260.5364 | ... M12: =SUM(M8:M11) -> 8096.0017
B14: Cost of Revenues | C14: USD Mns | D14: -963 | E14: -1070 | F14: -1356 | G14: -1499 | H14: -1623 | I14: =Projections!L17 -> -1914.0847 | J14: =Projections!M17 -> -2249.4684 | K14: =Projections!N17 -> -2657.9627 | L14: =Projections!O17 -> -3133.4086 | M14: =Projections!P17 -> -3685.8227
B15: Gross Profit | C15: USD Mns | D15: =SUM(D14,D12) -> -494 | E15: =SUM(E14,E12) -> -395 | F15: =SUM(F14,F12) -> 77 | G15: =SUM(G14,G12) -> 860 | H15: =SUM(H14,H12) -> 1174 | I15: =SUM(I14,I12) -> 1533.0733 | J15: =SUM(J14,J12) -> 1992.694 | K15: =SUM(K14,K12) -> 2602.5737 | ... M15: =SUM(M14,M12) -> 4410.179
B16: Gross Profit Margin | C16: % | D16: =D15/D12 -> -1.0533049 | E16: =E15/E12 -> -0.58518519 | F16: =F15/F12 -> 0.053733426 | G16: =G15/G12 -> 0.36456125 | H16: =H15/H12 -> 0.41973543 | I16: =I15/I12 -> 0.44473543 | J16: =J15/J12 -> 0.46973543 | K16: =K15/K12 -> 0.49473543 | ... M16: =M15/M12 -> 0.54473543
A18: x | B18: Operating Items
B19: Sales and Marketing Expenses | C19: USD Mns | D19: -151 | E19: -241 | F19: -278 | G19: -293 | H19: -324 | I19: =Projections!L28 -> -382.07747 | J19: =Projections!M28 -> -448.98368 | K19: =Projections!N28 -> -530.46407 | L19: =Projections!O28 -> -625.28216 | M19: =Projections!P28 -> -735.42782
B20: General and Administrative Expenses | C20: USD Mns | D20: -326 | E20: -544 | F20: -646 | G20: -550 | H20: -512 | I20: =Projections!L34 -> -613.77775 | J20: =Projections!M34 -> -734.12009 | K20: =Projections!N34 -> -884.05035 | L20: =Projections!O34 -> -1063.8147 | M20: =Projections!P34 -> -1279.5995
B21: Research and Development Expenses | C21: USD Mns | D21: -257 | E21: -356 | F21: -465 | G21: -421 | H21: -410 | I21: =Projections!L40 -> -505.30381 | J21: =Projections!M40 -> -600.62923 | K21: =Projections!N40 -> -718.51367 | L21: =Projections!O40 -> -858.50918 | M21: =Projections!P40 -> -1024.8375
B22: Other Income | C22: USD Mns | D22: 33 | E22: 12 | F22: 17 | G22: 17 | H22: 17 | I22: =Projections!L46 -> 40.894407 | J22: =Projections!M46 -> 50.325723 | K22: =Projections!N46 -> 62.406922 | L22: =Projections!O46 -> 77.39969 | M22: =Projections!P46 -> 96.044681
B23: Other Expenses | C23: USD Mns | D23: -40 | E23: -11 | F23: -12 | G23: -4 | H23: -4 | I23: =Projections!L52 -> -28.86664 | J23: =Projections!M52 -> -35.52404 | K23: =Projections!N52 -> -44.051945 | L23: =Projections!O52 -> -54.635075 | M23: =Projections!P52 -> -67.796246
B24: Net Impairment Losses on Financial Assets | C24: USD Mns | D24: -63 | E24: -19 | F24: -58 | G24: -72 | H24: -95 | I24: =Projections!L58 -> -117.08259 | J24: =Projections!M58 -> -144.08489 | K24: =Projections!N58 -> -178.67392 | L24: =Projections!O58 -> -221.59891 | M24: =Projections!P58 -> -274.98039
B25: Restructuring Costs | C25: USD Mns | D25: 0 | E25: -1 | F25: -8 | G25: -56 | H25: -14 | I25: =Projections!L64 -> -17.254276 | J25: =Projections!M64 -> -21.233562 | K25: =Projections!N64 -> -26.330894 | L25: =Projections!O64 -> -32.656682 | M25: =Projections!P64 -> -40.523426
B26: Net Change in Fair Value of Financial Assets and Liabilities | C26: USD Mns | D26: 0 | E26: 37 | F26: -294 | G26: -39 | H26: 0 | I26: =Projections!L70 -> 0 | J26: =Projections!M70 -> 0 | K26: =Projections!N70 -> 0 | L26: =Projections!O70 -> 0 | M26: =Projections!P70 -> 0
B27: Share Listing and Associated Expenses | C27: USD Mns | D27: 0 | E27: -353 | F27: 0 | G27: 0 | H27: 0 | I27: =Projections!L76 -> 0 | J27: =Projections!M76 -> 0 | K27: =Projections!N76 -> 0 | L27: =Projections!O76 -> 0 | M27: =Projections!P76 -> 0
B28: Total Operating Items: | C28: USD Mns | D28: =SUM(D19:D27) -> -804 | E28: =SUM(E19:E27) -> -1476 | F28: =SUM(F19:F27) -> -1744 | G28: =SUM(G19:G27) -> -1418 | H28: =SUM(H19:H27) -> -1342 | I28: =SUM(I19:I27) -> -1623.4681 | J28: =SUM(J19:J27) -> -1934.2498 | K28: =SUM(K19:K27) -> -2319.6779 | ... M28: =SUM(M19:M27) -> -3327.1202
B29: Operating Income | C29: USD Mns | D29: =SUM(D28,D15) -> -1298 | E29: =SUM(E28,E15) -> -1871 | F29: =SUM(F28,F15) -> -1667 | G29: =SUM(G28,G15) -> -558 | H29: =SUM(H28,H15) -> -168 | I29: =SUM(I28,I15) -> -90.394851 | J29: =SUM(J28,J15) -> 58.444237 | K29: =SUM(K28,K15) -> 282.89582 | ... M29: =SUM(M28,M15) -> 1083.0588
A31: x | B31: Non-Operating Items
B32: Non-operating Income/expense | C32: USD Mns | D32: -42 | E32: 0 | F32: 0 | G32: 0 | H32: 0 | I32: =Projections!L86 -> 0 | J32: =Projections!M86 -> 0 | K32: =Projections!N86 -> 0 | L32: =Projections!O86 -> 0 | M32: =Projections!P86 -> 0
B33: Finance Costs | C33: USD Mns | D33: -1448 | E33: -1701 | F33: -166 | G33: -99 | H33: -106 | I33: ='Debt & Equity'!M80 -> -23.845 | J33: ='Debt & Equity'!N80 -> -21.115 | K33: ='Debt & Equity'!O80 -> -21.115 | L33: ='Debt & Equity'!P80 -> -21.115 | M33: ='Debt & Equity'!Q80 -> -20.935
B34: Finance Income | C34: USD Mns | D34: 53 | E34: 28 | F34: 107 | G34: 198 | H34: 187 | I34: =Projections!L89 -> 257.39421 | J34: =Projections!M89 -> 316.75602 | K34: =Projections!N89 -> 392.79651 | L34: =Projections!O89 -> 487.16275 | M34: =Projections!P89 -> 604.51652
B35: Earnings Before Tax | C35: USD Mns | D35: =SUM(D32:D34,D29) -> -2735 | E35: =SUM(E32:E34,E29) -> -3544 | F35: =SUM(F32:F34,F29) -> -1726 | G35: =SUM(G32:G34,G29) -> -459 | H35: =SUM(H32:H34,H29) -> -87 | I35: =SUM(I32:I34,I29) -> 143.15436 | J35: =SUM(J32:J34,J29) -> 354.08526 | K35: =SUM(K32:K34,K29) -> 654.57733 | ... M35: =SUM(M32:M34,M29) -> 1666.6403
B36: Provision for Income Tax | C36: USD Mns | D36: -2 | E36: -3 | F36: -6 | G36: -19 | H36: -63 | I36: =Projections!L96 -> 0.49763971 | J36: =Projections!M96 -> 1.2308873 | K36: =Projections!N96 -> 2.2754716 | L36: =Projections!O96 -> 3.7469777 | M36: =Projections!P96 -> 5.793651
B37: Share of Loss of Equity Accounted Investee (net of Tax) | C37: USD Mns | D37: -8 | E37: -8 | F37: -8 | G37: -7 | H37: -8 | I37: =Projections!L99 -> -19.244427 | J37: =Projections!M99 -> -23.682693 | K37: =Projections!N99 -> -29.367963 | L37: =Projections!O99 -> -36.423383 | M37: =Projections!P99 -> -45.197497
B38: Minority Interest (After Tax) | C38: USD Mns | D38: 137 | E38: 106 | F38: 57 | G38: 51 | H38: 53 | I38: 0 | J38: 0 | K38: 0 | L38: 0 | M38: 0
B39: Net Income | C39: USD Mns | D39: =SUM(D35:D38) -> -2608 | E39: =SUM(E35:E38) -> -3449 | F39: =SUM(F35:F38) -> -1683 | G39: =SUM(G35:G38) -> -434 | H39: =SUM(H35:H38) -> -105 | I39: =SUM(I35:I38) -> 124.40757 | J39: =SUM(J35:J38) -> 331.63345 | K39: =SUM(K35:K38) -> 627.48484 | ... M39: =SUM(M35:M38) -> 1627.2364
B40: Net Income Margin | D40: =D39/D12 -> -5.5607676 | E40: =E39/E12 -> -5.1096296 | F40: =F39/F12 -> -1.1744592 | G40: =G39/G12 -> -0.18397626 | H40: =H39/H12 -> -0.037540222 | I40: =I39/I12 -> 0.036089896 | J40: =J39/J12 -> 0.078175567 | K40: =K39/K12 -> 0.11928153 | ... M40: =M39/M12 -> 0.2009926
B42: EBIT | C42: USD Mns | D42: =D35-D33 -> -1287 | E42: =E35-E33 -> -1843 | F42: =F35-F33 -> -1560 | G42: =G35-G33 -> -360 | H42: =H35-H33 -> 19 | I42: =I35-I33 -> 166.99936 | J42: =J35-J33 -> 375.20026 | K42: =K35-K33 -> 675.69233 | ... M42: =M35-M33 -> 1687.5753
B43: EBIT Margin | C43: % | D43: =D42/D12 -> -2.7441365 | E43: =E42/E12 -> -2.7303704 | F43: =F42/F12 -> -1.0886253 | G43: =G42/G12 -> -0.15260704 | H43: =H42/H12 -> 0.0067929925 | I43: =I42/I12 -> 0.048445519 | J43: =J42/J12 -> 0.088445519 | K43: =K42/K12 -> 0.12844552 | ... M43: =M42/M12 -> 0.20844552
B45: EBITDA | C45: USD Mns | D45: =D42+D112+D113 -> -900 | E45: =E42+E112+E113 -> -1498 | F45: =F42+F112+F113 -> -1410 | G45: =G42+G112+G113 -> -215 | H45: =H42+H112+H113 -> 166 | I45: =I42+I112+I113 -> 440.93236 | J45: =J42+J112+J113 -> 699.525 | K45: =K42+K112+K113 -> 1062.5059 | ... M45: =M42+M112+M113 -> 2067.7115
B46: EBITDA Margin | C46: % | D46: =D45/D12 -> -1.9189765 | E46: =E45/E12 -> -2.2192593 | F46: =F45/F12 -> -0.98394976 | G46: =G45/G12 -> -0.091140314 | H46: =H45/H12 -> 0.059349303 | I46: =I45/I12 -> 0.12791185 | J46: =J45/J12 -> 0.16489821 | K46: =K45/K12 -> 0.20197671 | ... M46: =M45/M12 -> 0.25539909
B49: Balance Sheet | D49: 20 | E49: =D49+1 -> 21 | F49: =E49+1 -> 22 | G49: =F49+1 -> 23 | H49: =G49+1 -> 24 | I49: =H49+1 -> 25 | J49: =I49+1 -> 26 | K49: =J49+1 -> 27 | L49: =K49+1 -> 28 | M49: =L49+1 -> 29
...

Sheet WACC
C1: =Cover!$C$7&" ("&Cover!$C$8&": "&Cover!$C$9&")" -> Grab Holdings Limited (NASDAQ: GRAB)
C3: 12M Target Price: | D3: =Cover!$C$18 -> 7.2080319
C4: Scenario: | D4: Base Case
C6: ="In "&Cover!$C$10&", unless stated otherwise" -> In USD Mn, unless stated otherwise | Q6: Notes:
C7: Fiscal year end date
A10: 1 | C10: WACC Summary
C12: Assumptions
D13: Country/Region | E13: Yield
C14: Risk Free Rate(1) | D14: USA | E14: 0.04079 | Q14: Trading Currency in USD, so use the US 10Y Note
C15: Tax Rate | E15: =O143 -> 0.2149891
C17: WACC Calculation
I19: D/E | L19: After-Tax | O19: Weightage
C20: Capital Structure | I20: Ratio | J20: %Debt | K20: %Equity | L20: COD | M20: COE | N20: WACC | O20: (%)
C21: Target Capital Structure - Current D/E | I21: =M96 -> 0.020856865 | J21: =I21/(1+I21) -> 0.020430744 | K21: =1-J21 -> 0.97956926 | L21: =$E$42 -> 0.11684102 | M21: =$E$51 -> 0.10429586 | N21: =SUMPRODUCT(J21:K21,L21:M21) -> 0.10455216 | O21: 0.5
C22: Target Capital Structure - Median Comps D/E | I22: =M97 -> 0.23563553 | J22: =I22/(1+I22) -> 0.19069986 | K22: =1-J22 -> 0.80930014 | L22: =$E$42 -> 0.11684102 | M22: =$E$51 -> 0.10429586 | N22: =SUMPRODUCT(J22:K22,L22:M22) -> 0.10668822 | O22: 0.5
C23: WACC | O23: =SUMPRODUCT(O21:O22,N21:N22) -> 0.10562019
A25: 2 | C25: Cost of Debt
C27: Synthetic Rating Method
F29: Historical (31 Dec) | K29: Forecasted (31 Dec)
C30: ICR Calculation | F30: 20 | G30: =F30+1 -> 21 | H30: =G30+1 -> 22 | I30: =H30+1 -> 23 | J30: =I30+1 -> 24 | K30: =J30+1 -> 25 | L30: =K30+1 -> 26 | M30: =L30+1 -> 27 | N30: =M30+1 -> 28 | O30: =N30+1 -> 29
C31: EBIT | F31: ='3FS'!D42 -> -1287 | G31: ='3FS'!E42 -> -1843 | H31: ='3FS'!F42 -> -1560 | I31: ='3FS'!G42 -> -360 | J31: ='3FS'!H42 -> 19 | K31: ='3FS'!I42 -> 166.99936 | L31: ='3FS'!J42 -> 375.20026 | M31: ='3FS'!K42 -> 675.69233 | ... O31: ='3FS'!M42 -> 1687.5753
C32: Interest Expense | F32: ='3FS'!D33 -> -1448 | G32: ='3FS'!E33 -> -1701 | H32: ='3FS'!F33 -> -166 | I32: ='3FS'!G33 -> -99 | J32: ='3FS'!H33 -> -106 | K32: ='3FS'!I33 -> -23.845 | L32: ='3FS'!J33 -> -21.115 | M32: ='3FS'!K33 -> -21.115 | ... O32: ='3FS'!M33 -> -20.935
C33: Interest Coverage Ratio | F33: =IFERROR(F31/ABS(F32),NA()) -> -0.88881215 | G33: =IFERROR(G31/ABS(G32),NA()) -> -1.0834803 | H33: =IFERROR(H31/ABS(H32),NA()) -> -9.3975904 | I33: =IFERROR(I31/ABS(I32),NA()) -> -3.6363636 | J33: =IFERROR(J31/ABS(J32),NA()) -> 0.17924528 | K33: =IFERROR(K31/ABS(K32),NA()) -> 7.0035378 | L33: =IFERROR(L31/ABS(L32),NA()) -> 17.769371 | M33: =IFERROR(M31/ABS(M32),NA()) -> 32.000584 | ... O33: =IFERROR(O31/ABS(O32),NA()) -> 80.610235
C35: Risk-Free Rate - US 10Y Government Bond Yield | E35: =E14 -> 0.04079 | H35: Rating | I35: Default Risk Spread | J35: Weight
C36: Average ICR | E36: =AVERAGE(F33:J33) -> -2.9654002 | F36: Synthetic Credit Rating | H36: =E37 -> D2/D | I36: =Damodaran!O11 -> 0.19 | J36: 0.5
C37: Synthetic Credit Rating | E37: =Damodaran!N11 -> D2/D | F37: Actual Credit Rating | H37: =E38 -> BB-/Ba3 | I37: =Damodaran!O17 -> 0.0261 | J37: 0.5
C38: Actual Credit Rating | E38: BB-/Ba3 | F38: Final Risk Spread | J38: =SUMPRODUCT(J36:J37,I36:I37) -> 0.10805
C39: Default risk spread - Damodaran's Estimates | E39: =J38 -> 0.10805
C40: Pre-Tax Cost of Debt | E40: =E35+E39 -> 0.14884
C41: Tax Rate | E41: =E15 -> 0.2149891
C42: After-Tax Cost of Debt | E42: =E40*(1-E41) -> 0.11684102
A44: 3 | C44: Cost of Equity
C46: Capital Asset Pricing Model (CAPM)
C47: Risk Free Rate | E47: =E14 -> 0.04079 | G47: Beta | H47: Weight
C48: Weighted Average Beta | E48: =G50 -> 0.6819609 | F48: Levered Beta | G48: =O98 -> 0.6819609 | H48: 1
C49: Equity Risk Premium | E49: =O113 -> 0.062787344 | F49: Regression Beta | G49: 1.0332297 | H49: 0
C50: Country Risk Premium | E50: =O128 -> 0.020687344 | F50: Weighted Beta | G50: =SUMPRODUCT(G48:G49,H48:H49) -> 0.6819609 | H50: =SUM(H48:H49) -> 1
C51: Cost of Equity | E51: =E47+E48*E49+E50 -> 0.10429586
A53: 4 | C53: Levered Beta
C55: Identified Peer Group
...

Sheet Trading Comps
B1: =Cover!$C$7&" ("&Cover!$C$8&": "&Cover!$C$9&")" -> Grab Holdings Limited (NASDAQ: GRAB)
B3: 12M Target Price | C3: =Cover!$C$18 -> 7.2080319
B4: Scenario | C4: =[1]Cover!D11 -> Base Case
E5: EV/EBITDA | H5: EV/Revenue | K5: P/E
E6: LTM | F6: 1 | G6: 2 | H6: LTM | I6: 1 | J6: 2 | K6: LTM | L6: 1 | M6: 2 | O6: Comments:
A8: x | B8: Mobility | O8: All values which returned "NM" were manually recomputed to zero
O9: Due to a lack of publicly traded comparables, Gojek was included as a competitor in certain markets which it may have exited from previously
B10: Singapore
B11: ='Raw Trading Comps'!A29 -> PT GoTo Gojek Tokopedia Tbk (IDX:GOTO) | E11: 0 | F11: =_xlfn.XLOOKUP($B11,'Raw Trading Comps'!$A$15:$A$32,'Raw Trading Comps'!H$15:H$32) -> 41.57 | G11: =_xlfn.XLOOKUP($B11,'Raw Trading Comps'!$A$15:$A$32,'Raw Trading Comps'!I$15:I$32) -> 21.65 | H11: =_xlfn.XLOOKUP($B11,'Raw Trading Comps'!$A$15:$A$32,'Raw Trading Comps'!J$15:J$32) -> 2.9 | I11: =_xlfn.XLOOKUP($B11,'Raw Trading Comps'!$A$15:$A$32,'Raw Trading Comps'!K$15:K$32) -> 2.8 | J11: =_xlfn.XLOOKUP($B11,'Raw Trading Comps'!$A$15:$A$32,'Raw Trading Comps'!L$15:L$32) -> 2.43 | K11: 0 | L11: 0 | M11: =_xlfn.XLOOKUP($B11,'Raw Trading Comps'!$A$15:$A$32,'Raw Trading Comps'!O$15:O$32) -> 86.32
B12: ='Raw Trading Comps'!A23 -> ComfortDelGro Corporation Limited (SGX:C52) | E12: =_xlfn.XLOOKUP($B12,'Raw Trading Comps'!$A$15:$A$32,'Raw Trading Comps'!G$15:G$32) -> 6 | F12: =_xlfn.XLOOKUP($B12,'Raw Trading Comps'!$A$15:$A$32,'Raw Trading Comps'!H$15:H$32) -> 5.51 | G12: =_xlfn.XLOOKUP($B12,'Raw Trading Comps'!$A$15:$A$32,'Raw Trading Comps'!I$15:I$32) -> 5.32 | H12: =_xlfn.XLOOKUP($B12,'Raw Trading Comps'!$A$15:$A$32,'Raw Trading Comps'!J$15:J$32) -> 0.9 | I12: =_xlfn.XLOOKUP($B12,'Raw Trading Comps'!$A$15:$A$32,'Raw Trading Comps'!K$15:K$32) -> 0.87 | J12: =_xlfn.XLOOKUP($B12,'Raw Trading Comps'!$A$15:$A$32,'Raw Trading Comps'!L$15:L$32) -> 0.85 | K12: =_xlfn.XLOOKUP($B12,'Raw Trading Comps'!$A$15:$A$32,'Raw Trading Comps'!M$15:M$32) -> 19.9 | L12: =_xlfn.XLOOKUP($B12,'Raw Trading Comps'!$A$15:$A$32,'Raw Trading Comps'!N$15:N$32) -> 13.65 | M12: =_xlfn.XLOOKUP($B12,'Raw Trading Comps'!$A$15:$A$32,'Raw Trading Comps'!O$15:O$32) -> 12.46
B13: Average | E13: =AVERAGE(E11:E12) -> 3 | F13: =AVERAGE(F11:F12) -> 23.54 | G13: =AVERAGE(G11:G12) -> 13.485 | H13: =AVERAGE(H11:H12) -> 1.9 | I13: =AVERAGE(I11:I12) -> 1.835 | J13: =AVERAGE(J11:J12) -> 1.64 | K13: =AVERAGE(K11:K12) -> 9.95 | L13: =AVERAGE(L11:L12) -> 6.825 | M13: =AVERAGE(M11:M12) -> 49.39
B14: Median | E14: =MEDIAN(E11:E12) -> 3 | F14: =MEDIAN(F11:F12) -> 23.54 | G14: =MEDIAN(G11:G12) -> 13.485 | H14: =MEDIAN(H11:H12) -> 1.9 | I14: =MEDIAN(I11:I12) -> 1.835 | J14: =MEDIAN(J11:J12) -> 1.64 | K14: =MEDIAN(K11:K12) -> 9.95 | L14: =MEDIAN(L11:L12) -> 6.825 | M14: =MEDIAN(M11:M12) -> 49.39
B15: 1st Quartile | E15: =_xlfn.PERCENTILE.INC(E11:E12,0.25) -> 1.5 | F15: =_xlfn.PERCENTILE.INC(F11:F12,0.25) -> 14.525 | G15: =_xlfn.PERCENTILE.INC(G11:G12,0.25) -> 9.4025 | H15: =_xlfn.PERCENTILE.INC(H11:H12,0.25) -> 1.4 | I15: =_xlfn.PERCENTILE.INC(I11:I12,0.25) -> 1.3525 | J15: =_xlfn.PERCENTILE.INC(J11:J12,0.25) -> 1.245 | K15: =_xlfn.PERCENTILE.INC(K11:K12,0.25) -> 4.975 | L15: =_xlfn.PERCENTILE.INC(L11:L12,0.25) -> 3.4125 | M15: =_xlfn.PERCENTILE.INC(M11:M12,0.25) -> 30.925
B16: 3rd Quartile | E16: =_xlfn.PERCENTILE.INC(E11:E12,0.75) -> 4.5 | F16: =_xlfn.PERCENTILE.INC(F11:F12,0.75) -> 32.555 | G16: =_xlfn.PERCENTILE.INC(G11:G12,0.75) -> 17.5675 | H16: =_xlfn.PERCENTILE.INC(H11:H12,0.75) -> 2.4 | I16: =_xlfn.PERCENTILE.INC(I11:I12,0.75) -> 2.3175 | J16: =_xlfn.PERCENTILE.INC(J11:J12,0.75) -> 2.035 | K16: =_xlfn.PERCENTILE.INC(K11:K12,0.75) -> 14.925 | L16: =_xlfn.PERCENTILE.INC(L11:L12,0.75) -> 10.2375 | M16: =_xlfn.PERCENTILE.INC(M11:M12,0.75) -> 67.855
B18: Malaysia
B19: ='Raw Trading Comps'!A29 -> PT GoTo Gojek Tokopedia Tbk (IDX:GOTO) | E19: 0 | F19: =_xlfn.XLOOKUP($B19,'Raw Trading Comps'!$A$15:$A$32,'Raw Trading Comps'!H$15:H$32) -> 41.57 | G19: =_xlfn.XLOOKUP($B19,'Raw Trading Comps'!$A$15:$A$32,'Raw Trading Comps'!I$15:I$32) -> 21.65 | H19: =_xlfn.XLOOKUP($B19,'Raw Trading Comps'!$A$15:$A$32,'Raw Trading Comps'!J$15:J$32) -> 2.9 | I19: =_xlfn.XLOOKUP($B19,'Raw Trading Comps'!$A$15:$A$32,'Raw Trading Comps'!K$15:K$32) -> 2.8 | J19: =_xlfn.XLOOKUP($B19,'Raw Trading Comps'!$A$15:$A$32,'Raw Trading Comps'!L$15:L$32) -> 2.43 | K19: 0 | L19: 0 | M19: =_xlfn.XLOOKUP($B19,'Raw Trading Comps'!$A$15:$A$32,'Raw Trading Comps'!O$15:O$32) -> 86.32
B20: Average | E20: =AVERAGE(E19:E19) -> 0 | F20: =AVERAGE(F19:F19) -> 41.57 | G20: =AVERAGE(G19:G19) -> 21.65 | H20: =AVERAGE(H19:H19) -> 2.9 | I20: =AVERAGE(I19:I19) -> 2.8 | J20: =AVERAGE(J19:J19) -> 2.43 | K20: =AVERAGE(K19:K19) -> 0 | L20: =AVERAGE(L19:L19) -> 0 | M20: =AVERAGE(M19:M19) -> 86.32
B21: Median | E21: =MEDIAN(E19:E19) -> 0 | F21: =MEDIAN(F19:F19) -> 41.57 | G21: =MEDIAN(G19:G19) -> 21.65 | H21: =MEDIAN(H19:H19) -> 2.9 | I21: =MEDIAN(I19:I19) -> 2.8 | J21: =MEDIAN(J19:J19) -> 2.43 | K21: =MEDIAN(K19:K19) -> 0 | L21: =MEDIAN(L19:L19) -> 0 | M21: =MEDIAN(M19:M19) -> 86.32
B22: 1st Quartile | E22: =_xlfn.PERCENTILE.INC(E19:E19,0.25) -> 0 | F22: =_xlfn.PERCENTILE.INC(F19:F19,0.25) -> 41.57 | G22: =_xlfn.PERCENTILE.INC(G19:G19,0.25) -> 21.65 | H22: =_xlfn.PERCENTILE.INC(H19:H19,0.25) -> 2.9 | I22: =_xlfn.PERCENTILE.INC(I19:I19,0.25) -> 2.8 | J22: =_xlfn.PERCENTILE.INC(J19:J19,0.25) -> 2.43 | K22: =_xlfn.PERCENTILE.INC(K19:K19,0.25) -> 0 | L22: =_xlfn.PERCENTILE.INC(L19:L19,0.25) -> 0 | M22: =_xlfn.PERCENTILE.INC(M19:M19,0.25) -> 86.32
B23: 3rd Quartile | E23: =_xlfn.PERCENTILE.INC(E19:E19,0.75) -> 0 | F23: =_xlfn.PERCENTILE.INC(F19:F19,0.75) -> 41.57 | G23: =_xlfn.PERCENTILE.INC(G19:G19,0.75) -> 21.65 | H23: =_xlfn.PERCENTILE.INC(H19:H19,0.75) -> 2.9 | I23: =_xlfn.PERCENTILE.INC(I19:I19,0.75) -> 2.8 | J23: =_xlfn.PERCENTILE.INC(J19:J19,0.75) -> 2.43 | K23: =_xlfn.PERCENTILE.INC(K19:K19,0.75) -> 0 | L23: =_xlfn.PERCENTILE.INC(L19:L19,0.75) -> 0 | M23: =_xlfn.PERCENTILE.INC(M19:M19,0.75) -> 86.32
B25: Indonesia
B26: ='Raw Trading Comps'!A29 -> PT GoTo Gojek Tokopedia Tbk (IDX:GOTO) | E26: 0 | F26: =_xlfn.XLOOKUP($B26,'Raw Trading Comps'!$A$15:$A$32,'Raw Trading Comps'!H$15:H$32) -> 41.57 | G26: =_xlfn.XLOOKUP($B26,'Raw Trading Comps'!$A$15:$A$32,'Raw Trading Comps'!I$15:I$32) -> 21.65 | H26: =_xlfn.XLOOKUP($B26,'Raw Trading Comps'!$A$15:$A$32,'Raw Trading Comps'!J$15:J$32) -> 2.9 | I26: =_xlfn.XLOOKUP($B26,'Raw Trading Comps'!$A$15:$A$32,'Raw Trading Comps'!K$15:K$32) -> 2.8 | J26: =_xlfn.XLOOKUP($B26,'Raw Trading Comps'!$A$15:$A$32,'Raw Trading Comps'!L$15:L$32) -> 2.43 | K26: 0 | L26: 0 | M26: =_xlfn.XLOOKUP($B26,'Raw Trading Comps'!$A$15:$A$32,'Raw Trading Comps'!O$15:O$32) -> 86.32
B27: ='Raw Trading Comps'!A27 -> PT Blue Bird Tbk (IDX:BIRD) | E27: =_xlfn.XLOOKUP($B27,'Raw Trading Comps'!$A$15:$A$32,'Raw Trading Comps'!G$15:G$32) -> 4 | F27: =_xlfn.XLOOKUP($B27,'Raw Trading Comps'!$A$15:$A$32,'Raw Trading Comps'!H$15:H$32) -> 3.91 | G27: =_xlfn.XLOOKUP($B27,'Raw Trading Comps'!$A$15:$A$32,'Raw Trading Comps'!I$15:I$32) -> 3.44 | H27: =_xlfn.XLOOKUP($B27,'Raw Trading Comps'!$A$15:$A$32,'Raw Trading Comps'!J$15:J$32) -> 1 | I27: =_xlfn.XLOOKUP($B27,'Raw Trading Comps'!$A$15:$A$32,'Raw Trading Comps'!K$15:K$32) -> 0.93 | J27: =_xlfn.XLOOKUP($B27,'Raw Trading Comps'!$A$15:$A$32,'Raw Trading Comps'!L$15:L$32) -> 0.85 | K27: =_xlfn.XLOOKUP($B27,'Raw Trading Comps'!$A$15:$A$32,'Raw Trading Comps'!M$15:M$32) -> 10.3 | L27: =_xlfn.XLOOKUP($B27,'Raw Trading Comps'!$A$15:$A$32,'Raw Trading Comps'!N$15:N$32) -> 6.75 | M27: =_xlfn.XLOOKUP($B27,'Raw Trading Comps'!$A$15:$A$32,'Raw Trading Comps'!O$15:O$32) -> 6.12
B28: Average | E28: =AVERAGE(E26:E27) -> 2 | F28: =AVERAGE(F26:F27) -> 22.74 | G28: =AVERAGE(G26:G27) -> 12.545 | H28: =AVERAGE(H26:H27) -> 1.95 | I28: =AVERAGE(I26:I27) -> 1.865 | J28: =AVERAGE(J26:J27) -> 1.64 | K28: =AVERAGE(K26:K27) -> 5.15 | L28: =AVERAGE(L26:L27) -> 3.375 | M28: =AVERAGE(M26:M27) -> 46.22
B29: Median | E29: =MEDIAN(E26:E27) -> 2 | F29: =MEDIAN(F26:F27) -> 22.74 | G29: =MEDIAN(G26:G27) -> 12.545 | H29: =MEDIAN(H26:H27) -> 1.95 | I29: =MEDIAN(I26:I27) -> 1.865 | J29: =MEDIAN(J26:J27) -> 1.64 | K29: =MEDIAN(K26:K27) -> 5.15 | L29: =MEDIAN(L26:L27) -> 3.375 | M29: =MEDIAN(M26:M27) -> 46.22
B30: 1st Quartile | E30: =_xlfn.PERCENTILE.INC(E26:E27,0.25) -> 1 | F30: =_xlfn.PERCENTILE.INC(F26:F27,0.25) -> 13.325 | G30: =_xlfn.PERCENTILE.INC(G26:G27,0.25) -> 7.9925 | H30: =_xlfn.PERCENTILE.INC(H26:H27,0.25) -> 1.475 | I30: =_xlfn.PERCENTILE.INC(I26:I27,0.25) -> 1.3975 | J30: =_xlfn.PERCENTILE.INC(J26:J27,0.25) -> 1.245 | K30: =_xlfn.PERCENTILE.INC(K26:K27,0.25) -> 2.575 | L30: =_xlfn.PERCENTILE.INC(L26:L27,0.25) -> 1.6875 | M30: =_xlfn.PERCENTILE.INC(M26:M27,0.25) -> 26.17
B31: 3rd Quartile | E31: =_xlfn.PERCENTILE.INC(E26:E27,0.75) -> 3 | F31: =_xlfn.PERCENTILE.INC(F26:F27,0.75) -> 32.155 | G31: =_xlfn.PERCENTILE.INC(G26:G27,0.75) -> 17.0975 | H31: =_xlfn.PERCENTILE.INC(H26:H27,0.75) -> 2.425 | I31: =_xlfn.PERCENTILE.INC(I26:I27,0.75) -> 2.3325 | J31: =_xlfn.PERCENTILE.INC(J26:J27,0.75) -> 2.035 | K31: =_xlfn.PERCENTILE.INC(K26:K27,0.75) -> 7.725 | L31: =_xlfn.PERCENTILE.INC(L26:L27,0.75) -> 5.0625 | M31: =_xlfn.PERCENTILE.INC(M26:M27,0.75) -> 66.27
B33: Philippines
B34: ='Raw Trading Comps'!A29 -> PT GoTo Gojek Tokopedia Tbk (IDX:GOTO) | E34: 0 | F34: =_xlfn.XLOOKUP($B34,'Raw Trading Comps'!$A$15:$A$32,'Raw Trading Comps'!H$15:H$32) -> 41.57 | G34: =_xlfn.XLOOKUP($B34,'Raw Trading Comps'!$A$15:$A$32,'Raw Trading Comps'!I$15:I$32) -> 21.65 | H34: =_xlfn.XLOOKUP($B34,'Raw Trading Comps'!$A$15:$A$32,'Raw Trading Comps'!J$15:J$32) -> 2.9 | I34: =_xlfn.XLOOKUP($B34,'Raw Trading Comps'!$A$15:$A$32,'Raw Trading Comps'!K$15:K$32) -> 2.8 | J34: =_xlfn.XLOOKUP($B34,'Raw Trading Comps'!$A$15:$A$32,'Raw Trading Comps'!L$15:L$32) -> 2.43 | K34: 0 | L34: 0 | M34: =_xlfn.XLOOKUP($B34,'Raw Trading Comps'!$A$15:$A$32,'Raw Trading Comps'!O$15:O$32) -> 86.32
B35: Average | E35: =AVERAGE(E34:E34) -> 0 | F35: =AVERAGE(F34:F34) -> 41.57 | G35: =AVERAGE(G34:G34) -> 21.65 | H35: =AVERAGE(H34:H34) -> 2.9 | I35: =AVERAGE(I34:I34) -> 2.8 | J35: =AVERAGE(J34:J34) -> 2.43 | K35: =AVERAGE(K34:K34) -> 0 | L35: =AVERAGE(L34:L34) -> 0 | M35: =AVERAGE(M34:M34) -> 86.32
B36: Median | E36: =MEDIAN(E34:E34) -> 0 | F36: =MEDIAN(F34:F34) -> 41.57 | G36: =MEDIAN(G34:G34) -> 21.65 | H36: =MEDIAN(H34:H34) -> 2.9 | I36: =MEDIAN(I34:I34) -> 2.8 | J36: =MEDIAN(J34:J34) -> 2.43 | K36: =MEDIAN(K34:K34) -> 0 | L36: =MEDIAN(L34:L34) -> 0 | M36: =MEDIAN(M34:M34) -> 86.32
B37: 1st Quartile | E37: =_xlfn.PERCENTILE.INC(E34:E34,0.25) -> 0 | F37: =_xlfn.PERCENTILE.INC(F34:F34,0.25) -> 41.57 | G37: =_xlfn.PERCENTILE.INC(G34:G34,0.25) -> 21.65 | H37: =_xlfn.PERCENTILE.INC(H34:H34,0.25) -> 2.9 | I37: =_xlfn.PERCENTILE.INC(I34:I34,0.25) -> 2.8 | J37: =_xlfn.PERCENTILE.INC(J34:J34,0.25) -> 2.43 | K37: =_xlfn.PERCENTILE.INC(K34:K34,0.25) -> 0 | L37: =_xlfn.PERCENTILE.INC(L34:L34,0.25) -> 0 | M37: =_xlfn.PERCENTILE.INC(M34:M34,0.25) -> 86.32
B38: 3rd Quartile | E38: =_xlfn.PERCENTILE.INC(E34:E34,0.75) -> 0 | F38: =_xlfn.PERCENTILE.INC(F34:F34,0.75) -> 41.57 | G38: =_xlfn.PERCENTILE.INC(G34:G34,0.75) -> 21.65 | H38: =_xlfn.PERCENTILE.INC(H34:H34,0.75) -> 2.9 | I38: =_xlfn.PERCENTILE.INC(I34:I34,0.75) -> 2.8 | J38: =_xlfn.PERCENTILE.INC(J34:J34,0.75) -> 2.43 | K38: =_xlfn.PERCENTILE.INC(K34:K34,0.75) -> 0 | L38: =_xlfn.PERCENTILE.INC(L34:L34,0.75) -> 0 | M38: =_xlfn.PERCENTILE.INC(M34:M34,0.75) -> 86.32
B40: Thailand
B41: ='Raw Trading Comps'!A29 -> PT GoTo Gojek Tokopedia Tbk (IDX:GOTO) | E41: 0 | F41: =_xlfn.XLOOKUP($B41,'Raw Trading Comps'!$A$15:$A$32,'Raw Trading Comps'!H$15:H$32) -> 41.57 | G41: =_xlfn.XLOOKUP($B41,'Raw Trading Comps'!$A$15:$A$32,'Raw Trading Comps'!I$15:I$32) -> 21.65 | H41: =_xlfn.XLOOKUP($B41,'Raw Trading Comps'!$A$15:$A$32,'Raw Trading Comps'!J$15:J$32) -> 2.9 | I41: =_xlfn.XLOOKUP($B41,'Raw Trading Comps'!$A$15:$A$32,'Raw Trading Comps'!K$15:K$32) -> 2.8 | J41: =_xlfn.XLOOKUP($B41,'Raw Trading Comps'!$A$15:$A$32,'Raw Trading Comps'!L$15:L$32) -> 2.43 | K41: 0 | L41: 0 | M41: =_xlfn.XLOOKUP($B41,'Raw Trading Comps'!$A$15:$A$32,'Raw Trading Comps'!O$15:O$32) -> 86.32
B42: ='Raw Trading Comps'!A24 -> BTS Group Holdings Public Company Limited (SET:BTS) | E42: =_xlfn.XLOOKUP($B42,'Raw Trading Comps'!$A$15:$A$32,'Raw Trading Comps'!G$15:G$32) -> 55 | F42: =_xlfn.XLOOKUP($B42,'Raw Trading Comps'!$A$15:$A$32,'Raw Trading Comps'!H$15:H$32) -> 29.55 | G42: =_xlfn.XLOOKUP($B42,'Raw Trading Comps'!$A$15:$A$32,'Raw Trading Comps'!I$15:I$32) -> 23.74 | H42: =_xlfn.XLOOKUP($B42,'Raw Trading Comps'!$A$15:$A$32,'Raw Trading Comps'!J$15:J$32) -> 10.8 | I42: =_xlfn.XLOOKUP($B42,'Raw Trading Comps'!$A$15:$A$32,'Raw Trading Comps'!K$15:K$32) -> 10.85 | J42: =_xlfn.XLOOKUP($B42,'Raw Trading Comps'!$A$15:$A$32,'Raw Trading Comps'!L$15:L$32) -> 10.09 | K42: =_xlfn.XLOOKUP($B42,'Raw Trading Comps'!$A$15:$A$32,'Raw Trading Comps'!M$15:M$32) -> 55.7 | L42: =_xlfn.XLOOKUP($B42,'Raw Trading Comps'!$A$15:$A$32,'Raw Trading Comps'!N$15:N$32) -> 69 | M42: =_xlfn.XLOOKUP($B42,'Raw Trading Comps'!$A$15:$A$32,'Raw Trading Comps'!O$15:O$32) -> 46.55
B43: Average | E43: =AVERAGE(E41:E42) -> 27.5 | F43: =AVERAGE(F41:F42) -> 35.56 | G43: =AVERAGE(G41:G42) -> 22.695 | H43: =AVERAGE(H41:H42) -> 6.85 | I43: =AVERAGE(I41:I42) -> 6.825 | J43: =AVERAGE(J41:J42) -> 6.26 | K43: =AVERAGE(K41:K42) -> 27.85 | L43: =AVERAGE(L41:L42) -> 34.5 | M43: =AVERAGE(M41:M42) -> 66.435
B44: Median | E44: =MEDIAN(E41:E42) -> 27.5 | F44: =MEDIAN(F41:F42) -> 35.56 | G44: =MEDIAN(G41:G42) -> 22.695 | H44: =MEDIAN(H41:H42) -> 6.85 | I44: =MEDIAN(I41:I42) -> 6.825 | J44: =MEDIAN(J41:J42) -> 6.26 | K44: =MEDIAN(K41:K42) -> 27.85 | L44: =MEDIAN(L41:L42) -> 34.5 | M44: =MEDIAN(M41:M42) -> 66.435
B45: 1st Quartile | E45: =_xlfn.PERCENTILE.INC(E41:E42,0.25) -> 13.75 | F45: =_xlfn.PERCENTILE.INC(F41:F42,0.25) -> 32.555 | G45: =_xlfn.PERCENTILE.INC(G41:G42,0.25) -> 22.1725 | H45: =_xlfn.PERCENTILE.INC(H41:H42,0.25) -> 4.875 | I45: =_xlfn.PERCENTILE.INC(I41:I42,0.25) -> 4.8125 | J45: =_xlfn.PERCENTILE.INC(J41:J42,0.25) -> 4.345 | K45: =_xlfn.PERCENTILE.INC(K41:K42,0.25) -> 13.925 | L45: =_xlfn.PERCENTILE.INC(L41:L42,0.25) -> 17.25 | M45: =_xlfn.PERCENTILE.INC(M41:M42,0.25) -> 56.4925
B46: 3rd Quartile | E46: =_xlfn.PERCENTILE.INC(E41:E42,0.75) -> 41.25 | F46: =_xlfn.PERCENTILE.INC(F41:F42,0.75) -> 38.565 | G46: =_xlfn.PERCENTILE.INC(G41:G42,0.75) -> 23.2175 | H46: =_xlfn.PERCENTILE.INC(H41:H42,0.75) -> 8.825 | I46: =_xlfn.PERCENTILE.INC(I41:I42,0.75) -> 8.8375 | J46: =_xlfn.PERCENTILE.INC(J41:J42,0.75) -> 8.175 | K46: =_xlfn.PERCENTILE.INC(K41:K42,0.75) -> 41.775 | L46: =_xlfn.PERCENTILE.INC(L41:L42,0.75) -> 51.75 | M46: =_xlfn.PERCENTILE.INC(M41:M42,0.75) -> 76.3775
...

Sheet DCF
C1: =Cover!$C$7&" ("&Cover!$C$8&": "&Cover!$C$9&")" -> Grab Holdings Limited (NASDAQ: GRAB)
C3: 12M Target Price: | D3: =Cover!$C$18 -> 7.2080319
C4: Upside: | D4: =D81 -> 0.36622391
C5: Scenario: | D5: Base Case
E6: Historical (31 Dec) | J6: Forecasted (31 Dec)
C7: ="In "&Cover!$C$10&", unless stated otherwise" -> In USD Mn, unless stated otherwise | E7: 20 | F7: =E7+1 -> 21 | G7: =F7+1 -> 22 | H7: =G7+1 -> 23 | I7: =H7+1 -> 24 | J7: =I7+1 -> 25 | K7: =J7+1 -> 26 | L7: =K7+1 -> 27 | M7: =L7+1 -> 28 | N7: =M7+1 -> 29 | P7: Notes:
C8: Fiscal year end date | E8: 44196 | F8: =EOMONTH(E8,12) -> 44561 | G8: =EOMONTH(F8,12) -> 44926 | H8: =EOMONTH(G8,12) -> 45291 | I8: =EOMONTH(H8,12) -> 45657 | J8: =EOMONTH(I8,12) -> 46022 | K8: =EOMONTH(J8,12) -> 46387 | L8: =EOMONTH(K8,12) -> 46752 | M8: =EOMONTH(L8,12) -> 47118 | N8: =EOMONTH(M8,12) -> 47483
A10: 1 | C10: DCF Model | E10: 20 | F10: =E10+1 -> 21 | G10: =F10+1 -> 22 | H10: =G10+1 -> 23 | I10: =H10+1 -> 24 | J10: =I10+1 -> 25 | K10: =J10+1 -> 26 | L10: =K10+1 -> 27 | M10: =L10+1 -> 28 | N10: =M10+1 -> 29
C12: General Assumptions
C13: WACC: | D13: =WACC!O23 -> 0.10562019
C14: Tax Rate: | D14: =WACC!E15 -> 0.2149891
C15: Valuation Date: | D15: 46028
C17: Revenue | E17: ='3FS'!D12 -> 469 | F17: ='3FS'!E12 -> 675 | G17: ='3FS'!F12 -> 1433 | H17: ='3FS'!G12 -> 2359 | I17: ='3FS'!H12 -> 2797 | J17: ='3FS'!I12 -> 3447.158 | K17: ='3FS'!J12 -> 4242.1624 | L17: ='3FS'!K12 -> 5260.5364 | ... N17: ='3FS'!M12 -> 8096.0017
C18: %yoy | F18: =F17/E17-1 -> 0.43923241 | G18: =G17/F17-1 -> 1.122963 | H18: =H17/G17-1 -> 0.64619679 | I18: =I17/H17-1 -> 0.18567189 | J18: =J17/I17-1 -> 0.23244832 | K18: =K17/J17-1 -> 0.23062606 | L18: =L17/K17-1 -> 0.24006011 | M18: =M17/L17-1 -> 0.24024207 | N18: =N17/M17-1 -> 0.24089233
C20: EBITDA | E20: ='3FS'!D45 -> -900 | F20: ='3FS'!E45 -> -1498 | G20: ='3FS'!F45 -> -1410 | H20: ='3FS'!G45 -> -215 | I20: ='3FS'!H45 -> 166 | J20: ='3FS'!I45 -> 440.93236 | K20: ='3FS'!J45 -> 699.525 | L20: ='3FS'!K45 -> 1062.5059 | ... N20: ='3FS'!M45 -> 2067.7115
C21: %revenue | E21: =E20/E17 -> -1.9189765 | F21: =F20/F17 -> -2.2192593 | G21: =G20/G17 -> -0.98394976 | H21: =H20/H17 -> -0.091140314 | I21: =I20/I17 -> 0.059349303 | J21: =J20/J17 -> 0.12791185 | K21: =K20/K17 -> 0.16489821 | L21: =L20/L17 -> 0.20197671 | ... N21: =N20/N17 -> 0.25539909
C23: EBIT | E23: ='3FS'!D42 -> -1287 | F23: ='3FS'!E42 -> -1843 | G23: ='3FS'!F42 -> -1560 | H23: ='3FS'!G42 -> -360 | I23: ='3FS'!H42 -> 19 | J23: ='3FS'!I42 -> 166.99936 | K23: ='3FS'!J42 -> 375.20026 | L23: ='3FS'!K42 -> 675.69233 | ... N23: ='3FS'!M42 -> 1687.5753
C24: %revenue | E24: =E23/E17 -> -2.7441365 | F24: =F23/F17 -> -2.7303704 | G24: =G23/G17 -> -1.0886253 | H24: =H23/H17 -> -0.15260704 | I24: =I23/I17 -> 0.0067929925 | J24: =J23/J17 -> 0.048445519 | K24: =K23/K17 -> 0.088445519 | L24: =L23/L17 -> 0.12844552 | ... N24: =N23/N17 -> 0.20844552
C26: Tax rate | J26: =D14 -> 0.2149891 | K26: =J26 -> 0.2149891 | L26: =K26 -> 0.2149891 | M26: =L26 -> 0.2149891 | N26: =M26 -> 0.2149891
C27: NOPAT | J27: =J23*(1-J26) -> 131.09632 | K27: =K23*(1-K26) -> 294.53629 | L27: =L23*(1-L26) -> 530.42585 | M27: =M23*(1-M26) -> 862.72353 | N27: =N23*(1-N26) -> 1324.765
C28: (+) D&A | J28: =SUM('3FS'!I112:I113) -> 273.933 | K28: =SUM('3FS'!J112:J113) -> 324.32474 | L28: =SUM('3FS'!K112:K113) -> 386.81352 | M28: =SUM('3FS'!L112:L113) -> 366.34083 | N28: =SUM('3FS'!M112:M113) -> 380.13622
C29: (-) Capital Expenditures | J29: =SUM('3FS'!I134:I135) -> -246.75585 | K29: =SUM('3FS'!J134:J135) -> -303.66419 | L29: =SUM('3FS'!K134:K135) -> -376.56184 | M29: =SUM('3FS'!L134:L135) -> -467.02784 | N29: =SUM('3FS'!M134:M135) -> -579.53126
C30: (-) Increases in Net Working Capital | J30: =SUM('3FS'!I115:I119) -> 117.39704 | K30: =SUM('3FS'!J115:J119) -> 179.9799 | L30: =SUM('3FS'!K115:K119) -> 230.5482 | M30: =SUM('3FS'!L115:L119) -> 280.53874 | N30: =SUM('3FS'!M115:M119) -> 361.37809
C31: UFCF | J31: =SUM(J27:J30) -> 275.67051 | K31: =SUM(K27:K30) -> 495.17674 | L31: =SUM(L27:L30) -> 771.22572 | M31: =SUM(M27:M30) -> 1042.5753 | N31: =SUM(N27:N30) -> 1486.748
C32: Discount Factor | J32: =YEARFRAC(D15,J8)/2 -> 0.0083333333 | K32: =J32+1 -> 1.0083333 | L32: =K32+1 -> 2.0083333 | M32: =L32+1 -> 3.0083333 | N32: =M32+1 -> 4.0083333
C33: PV of UFCF | J33: =J31/(1+J32)^$D$13 -> 275.42898 | K33: =K31/(1+K32)^$D$13 -> 460.01783 | L33: =L31/(1+L32)^$D$13 -> 686.53175 | M33: =M31/(1+M32)^$D$13 -> 900.37257 | N33: =N31/(1+N32)^$D$13 -> 1254.11
A35: 2 | C35: DCF Value Summary
C37: Gordon Growth Method | I37: EV/EBITDA Exit Multiple Method
C38: Terminal Growth Rate | D38: 0.04 | I38: Terminal Multiple - EV/EBITDA | N38: ='Trading Comps'!F194 -> 26.884175 | P38: 4.0% Terminal Growth Rate selected is meaningfully under the weighted average 20 year average GDP growth rate of Grabs countries of operations
C39: FY2029 UFCF x (1+g) | D39: =N31*(1+D38) -> 1546.218 | I39: FY2029 EBITDA | N39: =N20 -> 2067.7115
C40: Terminal Value in FY29E | D40: =D39/(D13-D38) -> 23563.143 | I40: Terminal Value in FY29E | N40: =N38*N39 -> 55588.717
C41: PV of Terminal Value | D41: =D40/(1+D13)^N32 -> 15756.001 | I41: PV of Terminal Value | N41: =N40/(1+D13)^N32 -> 37170.587
C42: PV of Stage 1 Cash Flows | D42: =SUM(J33:N33) -> 3576.4612 | I42: PV of Stage 1 Cash Flows | N42: =SUM(J33:N33) -> 3576.4612
A43: x | C43: Implied Enterprise Value | D43: =SUM(D41:D42) -> 19332.462 | I43: Implied Enterprise Value | N43: =SUM(N41:N42) -> 40747.049
C44: (+) Cash and Cash Equivalents | D44: ='3FS'!H53 -> 2964 | I44: (+) Cash and Cash Equivalents | N44: =D44 -> 2964
C45: (+) Other Financial Assets | D45: 0 | I45: (+) Short-Term Investments | N45: =D45 -> 0
C46: (+) Investments in associates and joint ventures | D46: ='3FS'!H64 -> 131 | I46: (+) Investments in associates and joint ventures | N46: =D46 -> 131
C47: (-) MV of Total Debt | D47: =-'3FS'!H78-'3FS'!H86 -> -364 | I47: (-) MV of Total Debt | N47: =D47 -> -364
C48: (-) Non-Controlling Interest | D48: 0 | I48: (-) Non-Controlling Interest | N48: =D48 -> 0
C49: Implied Equity Value | D49: =SUM(D43:D48) -> 22063.462 | I49: Implied Equity Value | N49: =SUM(N43:N48) -> 43478.049
...

Sheet Reverse DCF
C1: =Cover!$C$7&" ("&Cover!$C$8&": "&Cover!$C$9&")" -> Grab Holdings Limited (NASDAQ: GRAB)
C3: 12M Target Price: | D3: =Cover!$C$18 -> 7.2080319
C4: Upside: | D4: =Cover!$C$20 -> 0.36774798
C5: Scenario: | D5: Base Case
E6: Historical (31 Dec) | J6: Forecasted (31 Dec)
C7: ="In "&Cover!$C$10&", unless stated otherwise" -> In USD Mn, unless stated otherwise | E7: 20 | F7: =E7+1 -> 21 | G7: =F7+1 -> 22 | H7: =G7+1 -> 23 | I7: =H7+1 -> 24 | J7: =I7+1 -> 25 | K7: =J7+1 -> 26 | L7: =K7+1 -> 27 | M7: =L7+1 -> 28 | N7: =M7+1 -> 29 | P7: Notes:
E8: 44196 | F8: =EOMONTH(E8,12) -> 44561 | G8: =EOMONTH(F8,12) -> 44926 | H8: =EOMONTH(G8,12) -> 45291 | I8: =EOMONTH(H8,12) -> 45657 | J8: =EOMONTH(I8,12) -> 46022 | K8: =EOMONTH(J8,12) -> 46387 | L8: =EOMONTH(K8,12) -> 46752 | M8: =EOMONTH(L8,12) -> 47118 | N8: =EOMONTH(M8,12) -> 47483 | P8: Utilising the same operating assumptions as my initial discounted cash flow model (WACC, Tax Rate and Terminal growth rate, 5 year Revenue CAGR the street expects for Grab is 26.2%
A10: 1 | C10: Reverse DCF Model | P10: Can argue that my revenue build was conservative to reflect a margin of safety before arriving at my target price where Grab still trades at a meaningful discount
C12: General Assumptions
C13: WACC: | D13: =WACC!O23 -> 0.10562019
C14: Tax Rate: | D14: =WACC!E15 -> 0.2149891
C15: Valuation Date: | D15: 46016
C16: 5 Year Revenue CAGR: | D16: 0.16
C17: Terminal Growth Rate: | D17: 0.04
C19: Revenue | E19: ='3FS'!D12 -> 469 | F19: ='3FS'!E12 -> 675 | G19: ='3FS'!F12 -> 1433 | H19: ='3FS'!G12 -> 2359 | I19: ='3FS'!H12 -> 2797 | J19: =I19*(1+J20) -> 3244.52 | K19: =J19*(1+K20) -> 3763.6432 | L19: =K19*(1+L20) -> 4365.8261 | M19: =L19*(1+M20) -> 5064.3583 | N19: =M19*(1+N20) -> 5874.6556
C20: %yoy | F20: =(F19-E19)/E19 -> 0.43923241 | G20: =(G19-F19)/F19 -> 1.122963 | H20: =(H19-G19)/G19 -> 0.64619679 | I20: =(I19-H19)/H19 -> 0.18567189 | J20: =$D$16 -> 0.16 | K20: =$D$16 -> 0.16 | L20: =$D$16 -> 0.16 | M20: =$D$16 -> 0.16 | N20: =$D$16 -> 0.16
C22: EBIT | E22: ='3FS'!D42 -> -1287 | F22: ='3FS'!E42 -> -1843 | G22: ='3FS'!F42 -> -1560 | H22: ='3FS'!G42 -> -360 | I22: ='3FS'!H42 -> 19 | J22: =J19*J23 -> 55.081879 | K22: =K19*K23 -> 270.28731 | L22: =L19*L23 -> 466.77422 | M22: =M19*M23 -> 642.74527 | N22: =N19*N23 -> 863.07762
C23: % EBIT Margin | E23: =E22/'3FS'!D12 -> -2.7441365 | F23: =F22/'3FS'!E12 -> -2.7303704 | G23: =G22/'3FS'!F12 -> -1.0886253 | H23: =H22/'3FS'!G12 -> -0.15260704 | I23: =I22/'3FS'!H12 -> 0.0067929925 | J23: 0.016976896 | K23: 0.071815339 | L23: 0.10691544 | M23: =L23+2% -> 0.12691544 | N23: =M23+2% -> 0.14691544
C25: Tax Rate | J25: =$D$14 -> 0.2149891 | K25: =$D$14 -> 0.2149891 | L25: =$D$14 -> 0.2149891 | M25: =$D$14 -> 0.2149891 | N25: =$D$14 -> 0.2149891
C26: NOPAT | J26: =J22-(J22*J25) -> 43.239876 | K26: =K22-(K22*K25) -> 212.17849 | L26: =L22-(L22*L25) -> 366.42286 | M26: =M22-(M22*M25) -> 504.56204 | N26: =N22-(N22*N25) -> 677.52534
C27: % NOPAT Margin
C28: (+) D&A | J28: =SUM('3FS'!I112:I113) -> 273.933 | K28: =SUM('3FS'!J112:J113) -> 324.32474 | L28: =SUM('3FS'!K112:K113) -> 386.81352 | M28: =SUM('3FS'!L112:L113) -> 366.34083 | N28: =SUM('3FS'!M112:M113) -> 380.13622
C29: (-) Capital Expenditures | J29: ='3FS'!I134+'3FS'!I135 -> -246.75585 | K29: ='3FS'!J134+'3FS'!J135 -> -303.66419 | L29: ='3FS'!K134+'3FS'!K135 -> -376.56184 | M29: ='3FS'!L134+'3FS'!L135 -> -467.02784 | N29: ='3FS'!M134+'3FS'!M135 -> -579.53126
C30: (-) Increases in Net Working Capital | J30: =SUM('3FS'!I115:I119) -> 117.39704 | K30: =SUM('3FS'!J115:J119) -> 179.9799 | L30: =SUM('3FS'!K115:K119) -> 230.5482 | M30: =SUM('3FS'!L115:L119) -> 280.53874 | N30: =SUM('3FS'!M115:M119) -> 361.37809
C31: UFCF | J31: =SUM(J28:J30,J26) -> 187.81406 | K31: =SUM(K28:K30,K26) -> 412.81894 | L31: =SUM(L28:L30,L26) -> 607.22273 | M31: =SUM(M28:M30,M26) -> 684.41377 | N31: =SUM(N28:N30,N26) -> 839.50839
C32: Discount Factor | J32: =YEARFRAC(D15,J8)/2 -> 0.0083333333 | K32: =J32+1 -> 1.0083333 | L32: =K32+1 -> 2.0083333 | M32: =L32+1 -> 3.0083333 | N32: =M32+1 -> 4.0083333
C33: PV of UFCF | J33: =J31/(1+J32)^$D$13 -> 187.64951 | K33: =K31/(1+K32)^$D$13 -> 383.50765 | L33: =L31/(1+L32)^$D$13 -> 540.53913 | M33: =M31/(1+M32)^$D$13 -> 591.06274 | N33: =N31/(1+N32)^$D$13 -> 708.14681
A35: 2 | C35: DCF Value Summary
C37: Gordon Growth Method | I37: EV/EBITDA Exit Multiple Method
C38: Terminal Growth Rate | D38: =D17 -> 0.04 | I38: Terminal Multiple - EV/EBITDA | N38: ='Trading Comps'!F194 -> 26.884175
C39: FY2029 UFCF x (1+g) | D39: =N31*(1+D38) -> 873.08872 | I39: FY2029 EBITDA | N39: =N22+N28 -> 1243.2138
C40: Terminal Value in FY29E | D40: =D39/(D13-D38) -> 13305.184 | I40: Terminal Value in FY29E | N40: =N38*N39 -> 33422.778
C41: PV of Terminal Value | D41: =D40/(1+D13)^N32 -> 8896.7965 | I41: PV of Terminal Value | N41: =N40/(1+D13)^N32 -> 22348.857
C42: PV of Stage 1 Cash Flows | D42: =SUM(J33:N33) -> 2410.9059 | I42: PV of Stage 1 Cash Flows | N42: =SUM(J33:N33) -> 2410.9059
C43: Implied Enterprise Value | D43: =SUM(D41:D42) -> 11307.702 | I43: Implied Enterprise Value | N43: =SUM(N41:N42) -> 24759.763
C44: (+) Cash and Cash Equivalents | D44: =DCF!D44 -> 2964 | I44: (+) Cash and Cash Equivalents | N44: 2964
C45: (+) Other Financial Assets | D45: =DCF!D45 -> 0 | I45: (+) Short-Term Investments | N45: 0
C46: (+) Investments in associates and joint ventures | D46: =DCF!D46 -> 131 | I46: (+) Investments in associates and joint ventures | N46: 131
C47: (-) MV of Total Debt | D47: =DCF!D47 -> -364 | I47: (-) MV of Total Debt | N47: -364
C48: (-) Non-Controlling Interest | D48: =DCF!D48 -> 0 | I48: (-) Non-Controlling Interest | N48: 0
...

Sheet Terminal Growth Rate
B1: =Cover!$C$7&" ("&Cover!$C$8&": "&Cover!$C$9&")" -> Grab Holdings Limited (NASDAQ: GRAB)
B3: 12M Target Price | C3: =Cover!$C$18 -> 7.2080319
B4: Scenario | C4: =[1]Cover!D11 -> Base Case
A8: x | B8: Series Name | C8: Series Code | D8: Country Name | E8: Country Code | F8: 2005 [YR2005] | G8: 2006 [YR2006] | H8: 2007 [YR2007] | I8: 2008 [YR2008] | J8: 2009 [YR2009] | K8: 2010 [YR2010] | L8: 2011 [YR2011] | M8: 2012 [YR2012] | N8: 2013 [YR2013] | O8: 2014 [YR2014] | P8: 2015 [YR2015] | Q8: 2016 [YR2016] | R8: 2017 [YR2017] | S8: 2018 [YR2018] | T8: 2019 [YR2019] | U8: 2020 [YR2020] | V8: 2021 [YR2021] | W8: 2022 [YR2022] | X8: 2023 [YR2023] | Y8: 2024 [YR2024]
B9: GDP growth (annual %) | C9: NY.GDP.MKTP.KD.ZG | D9: Afghanistan | E9: AFG | F9: ='GDP Growth Rates'!E2/100 -> 0.11229715 | G9: ='GDP Growth Rates'!F2/100 -> 0.053574032 | H9: ='GDP Growth Rates'!G2/100 -> 0.1382632 | I9: ='GDP Growth Rates'!H2/100 -> 0.039249838 | J9: ='GDP Growth Rates'!I2/100 -> 0.21390528 | K9: ='GDP Growth Rates'!J2/100 -> 0.14362441 | L9: ='GDP Growth Rates'!K2/100 -> 0.0042635478 | M9: ='GDP Growth Rates'!L2/100 -> 0.12752287 | ... Y9: ='GDP Growth Rates'!X2/100 -> #VALUE!
B10: GDP growth (annual %) | C10: NY.GDP.MKTP.KD.ZG | D10: Albania | E10: ALB | F10: ='GDP Growth Rates'!E3/100 -> 0.051308219 | G10: ='GDP Growth Rates'!F3/100 -> 0.060189812 | H10: ='GDP Growth Rates'!G3/100 -> 0.065000926 | I10: ='GDP Growth Rates'!H3/100 -> 0.069070623 | J10: ='GDP Growth Rates'!I3/100 -> 0.026907515 | K10: ='GDP Growth Rates'!J3/100 -> 0.029731544 | L10: ='GDP Growth Rates'!K3/100 -> 0.024635168 | M10: ='GDP Growth Rates'!L3/100 -> 0.0098412988 | ... Y10: ='GDP Growth Rates'!X3/100 -> 0.039617191
B11: GDP growth (annual %) | C11: NY.GDP.MKTP.KD.ZG | D11: Algeria | E11: DZA | F11: ='GDP Growth Rates'!E4/100 -> 0.054 | G11: ='GDP Growth Rates'!F4/100 -> 0.029 | H11: ='GDP Growth Rates'!G4/100 -> 0.031 | I11: ='GDP Growth Rates'!H4/100 -> 0.025 | J11: ='GDP Growth Rates'!I4/100 -> 0.012 | K11: ='GDP Growth Rates'!J4/100 -> 0.048 | L11: ='GDP Growth Rates'!K4/100 -> 0.03 | M11: ='GDP Growth Rates'!L4/100 -> 0.024 | ... Y11: ='GDP Growth Rates'!X4/100 -> 0.033
B12: GDP growth (annual %) | C12: NY.GDP.MKTP.KD.ZG | D12: American Samoa | E12: ASM | F12: ='GDP Growth Rates'!E5/100 -> -0.0040816327 | G12: ='GDP Growth Rates'!F5/100 -> -0.040983607 | H12: ='GDP Growth Rates'!G5/100 -> 0.018518519 | I12: ='GDP Growth Rates'!H5/100 -> -0.026573427 | J12: ='GDP Growth Rates'!I5/100 -> -0.041666667 | K12: ='GDP Growth Rates'!J5/100 -> 0.0029985007 | L12: ='GDP Growth Rates'!K5/100 -> 0 | M12: ='GDP Growth Rates'!L5/100 -> -0.043348281 | ... Y12: ='GDP Growth Rates'!X5/100 -> #VALUE!
B13: GDP growth (annual %) | C13: NY.GDP.MKTP.KD.ZG | D13: Andorra | E13: AND | F13: ='GDP Growth Rates'!E6/100 -> 0.05397796 | G13: ='GDP Growth Rates'!F6/100 -> 0.048086887 | H13: ='GDP Growth Rates'!G6/100 -> 0.015531881 | I13: ='GDP Growth Rates'!H6/100 -> -0.055591864 | J13: ='GDP Growth Rates'!I6/100 -> -0.053028465 | K13: ='GDP Growth Rates'!J6/100 -> -0.01974958 | L13: ='GDP Growth Rates'!K6/100 -> -8.0697534e-05 | M13: ='GDP Growth Rates'!L6/100 -> -0.049744437 | ... Y13: ='GDP Growth Rates'!X6/100 -> 0.033718203
B14: GDP growth (annual %) | C14: NY.GDP.MKTP.KD.ZG | D14: Angola | E14: AGO | F14: ='GDP Growth Rates'!E7/100 -> 0.1503 | G14: ='GDP Growth Rates'!F7/100 -> 0.1155 | H14: ='GDP Growth Rates'!G7/100 -> 0.1401 | I14: ='GDP Growth Rates'!H7/100 -> 0.1117 | J14: ='GDP Growth Rates'!I7/100 -> 0.0086 | K14: ='GDP Growth Rates'!J7/100 -> 0.043983759 | L14: ='GDP Growth Rates'!K7/100 -> 0.034720531 | M14: ='GDP Growth Rates'!L7/100 -> 0.085421071 | ... Y14: ='GDP Growth Rates'!X7/100 -> 0.044239045
B15: GDP growth (annual %) | C15: NY.GDP.MKTP.KD.ZG | D15: Antigua and Barbuda | E15: ATG | F15: ='GDP Growth Rates'!E8/100 -> 0.064736894 | G15: ='GDP Growth Rates'!F8/100 -> 0.12708147 | H15: ='GDP Growth Rates'!G8/100 -> 0.093151827 | I15: ='GDP Growth Rates'!H8/100 -> -0.00014006598 | J15: ='GDP Growth Rates'!I8/100 -> -0.11962879 | K15: ='GDP Growth Rates'!J8/100 -> -0.078405068 | L15: ='GDP Growth Rates'!K8/100 -> -0.019587426 | M15: ='GDP Growth Rates'!L8/100 -> 0.033731427 | ... Y15: ='GDP Growth Rates'!X8/100 -> 0.043275215
B16: GDP growth (annual %) | C16: NY.GDP.MKTP.KD.ZG | D16: Argentina | E16: ARG | F16: ='GDP Growth Rates'!E9/100 -> 0.088516599 | G16: ='GDP Growth Rates'!F9/100 -> 0.080471515 | H16: ='GDP Growth Rates'!G9/100 -> 0.090076509 | I16: ='GDP Growth Rates'!H9/100 -> 0.040572331 | J16: ='GDP Growth Rates'!I9/100 -> -0.059185251 | K16: ='GDP Growth Rates'!J9/100 -> 0.10125398 | L16: ='GDP Growth Rates'!K9/100 -> 0.060039517 | M16: ='GDP Growth Rates'!L9/100 -> -0.010264205 | ... Y16: ='GDP Growth Rates'!X9/100 -> -0.017191051
B17: GDP growth (annual %) | C17: NY.GDP.MKTP.KD.ZG | D17: Armenia | E17: ARM | F17: ='GDP Growth Rates'!E10/100 -> 0.139 | G17: ='GDP Growth Rates'!F10/100 -> 0.132 | H17: ='GDP Growth Rates'!G10/100 -> 0.137 | I17: ='GDP Growth Rates'!H10/100 -> 0.069 | J17: ='GDP Growth Rates'!I10/100 -> -0.141 | K17: ='GDP Growth Rates'!J10/100 -> 0.022 | L17: ='GDP Growth Rates'!K10/100 -> 0.047 | M17: ='GDP Growth Rates'!L10/100 -> 0.072 | ... Y17: ='GDP Growth Rates'!X10/100 -> 0.059
B18: GDP growth (annual %) | C18: NY.GDP.MKTP.KD.ZG | D18: Aruba | E18: ABW | F18: ='GDP Growth Rates'!E11/100 -> -0.0038313767 | G18: ='GDP Growth Rates'!F11/100 -> 0.011274115 | H18: ='GDP Growth Rates'!G11/100 -> 0.030895444 | I18: ='GDP Growth Rates'!H11/100 -> 0.018357552 | J18: ='GDP Growth Rates'!I11/100 -> -0.11677741 | K18: ='GDP Growth Rates'!J11/100 -> -0.027334568 | L18: ='GDP Growth Rates'!K11/100 -> 0.033692372 | M18: ='GDP Growth Rates'!L11/100 -> -0.010407999 | ... Y18: ='GDP Growth Rates'!X11/100 -> #VALUE!
B19: GDP growth (annual %) | C19: NY.GDP.MKTP.KD.ZG | D19: Australia | E19: AUS | F19: ='GDP Growth Rates'!E12/100 -> 0.031541675 | G19: ='GDP Growth Rates'!F12/100 -> 0.027553461 | H19: ='GDP Growth Rates'!G12/100 -> 0.037733217 | I19: ='GDP Growth Rates'!H12/100 -> 0.03586267 | J19: ='GDP Growth Rates'!I12/100 -> 0.018925558 | K19: ='GDP Growth Rates'!J12/100 -> 0.022199803 | L19: ='GDP Growth Rates'!K12/100 -> 0.024070802 | M19: ='GDP Growth Rates'!L12/100 -> 0.039167094 | ... Y19: ='GDP Growth Rates'!X12/100 -> 0.014311125
B20: GDP growth (annual %) | C20: NY.GDP.MKTP.KD.ZG | D20: Austria | E20: AUT | F20: ='GDP Growth Rates'!E13/100 -> 0.023203651 | G20: ='GDP Growth Rates'!F13/100 -> 0.03269336 | H20: ='GDP Growth Rates'!G13/100 -> 0.037752247 | I20: ='GDP Growth Rates'!H13/100 -> 0.014533056 | J20: ='GDP Growth Rates'!I13/100 -> -0.035862647 | K20: ='GDP Growth Rates'!J13/100 -> 0.018089824 | L20: ='GDP Growth Rates'!K13/100 -> 0.02927468 | M20: ='GDP Growth Rates'!L13/100 -> 0.0062824624 | ... Y20: ='GDP Growth Rates'!X13/100 -> -0.011735405
... B274: GDP growth (annual %) | C274: NY.GDP.MKTP.KD.ZG | D274: World | E274: WLD | F274: ='GDP Growth Rates'!E267/100 -> 0.040386153 | G274: ='GDP Growth Rates'!F267/100 -> 0.044712212 | H274: ='GDP Growth Rates'!G267/100 -> 0.043855832 | I274: ='GDP Growth Rates'!H267/100 -> 0.020739527 | J274: ='GDP Growth Rates'!I267/100 -> -0.013195982 | K274: ='GDP Growth Rates'!J267/100 -> 0.045271471 | L274: ='GDP Growth Rates'!K267/100 -> 0.03347311 | M274: ='GDP Growth Rates'!L267/100 -> 0.027072811 | ... Y274: ='GDP Growth Rates'!X267/100 -> 0.02863263
A276: x | C276: 2005 | D276: =C276+1 -> 2006 | E276: =D276+1 -> 2007 | F276: =E276+1 -> 2008 | G276: =F276+1 -> 2009 | H276: =G276+1 -> 2010 | I276: =H276+1 -> 2011 | J276: =I276+1 -> 2012 | K276: =J276+1 -> 2013 | ... V276: =U276+1 -> 2024
B277: Singapore | C277: =_xlfn.XLOOKUP($B277,$D$9:$D$274,F$9:F$274) -> 0.073663224 | D277: =_xlfn.XLOOKUP($B277,$D$9:$D$274,G$9:G$274) -> 0.090067661 | E277: =_xlfn.XLOOKUP($B277,$D$9:$D$274,H$9:H$274) -> 0.090215195 | F277: =_xlfn.XLOOKUP($B277,$D$9:$D$274,I$9:I$274) -> 0.018634835 | G277: =_xlfn.XLOOKUP($B277,$D$9:$D$274,J$9:J$274) -> 0.0012795338 | H277: =_xlfn.XLOOKUP($B277,$D$9:$D$274,K$9:K$274) -> 0.1451975 | I277: =_xlfn.XLOOKUP($B277,$D$9:$D$274,L$9:L$274) -> 0.062149342 | J277: =_xlfn.XLOOKUP($B277,$D$9:$D$274,M$9:M$274) -> 0.044354976 | ... V277: =_xlfn.XLOOKUP($B277,$D$9:$D$274,Y$9:Y$274) -> 0.043880236
B278: Malaysia | C278: =_xlfn.XLOOKUP($B278,$D$9:$D$274,F$9:F$274) -> 0.053321392 | D278: =_xlfn.XLOOKUP($B278,$D$9:$D$274,G$9:G$274) -> 0.055848471 | E278: =_xlfn.XLOOKUP($B278,$D$9:$D$274,H$9:H$274) -> 0.062987859 | F278: =_xlfn.XLOOKUP($B278,$D$9:$D$274,I$9:I$274) -> 0.048317699 | G278: =_xlfn.XLOOKUP($B278,$D$9:$D$274,J$9:J$274) -> -0.015135287 | H278: =_xlfn.XLOOKUP($B278,$D$9:$D$274,K$9:K$274) -> 0.074248474 | I278: =_xlfn.XLOOKUP($B278,$D$9:$D$274,L$9:L$274) -> 0.052939128 | J278: =_xlfn.XLOOKUP($B278,$D$9:$D$274,M$9:M$274) -> 0.054734542 | ... V278: =_xlfn.XLOOKUP($B278,$D$9:$D$274,Y$9:Y$274) -> 0.051141555
B279: Indonesia | C279: =_xlfn.XLOOKUP($B279,$D$9:$D$274,F$9:F$274) -> 0.056925713 | D279: =_xlfn.XLOOKUP($B279,$D$9:$D$274,G$9:G$274) -> 0.055009518 | E279: =_xlfn.XLOOKUP($B279,$D$9:$D$274,H$9:H$274) -> 0.063450222 | F279: =_xlfn.XLOOKUP($B279,$D$9:$D$274,I$9:I$274) -> 0.060137036 | G279: =_xlfn.XLOOKUP($B279,$D$9:$D$274,J$9:J$274) -> 0.046288712 | H279: =_xlfn.XLOOKUP($B279,$D$9:$D$274,K$9:K$274) -> 0.062238542 | I279: =_xlfn.XLOOKUP($B279,$D$9:$D$274,L$9:L$274) -> 0.061697842 | J279: =_xlfn.XLOOKUP($B279,$D$9:$D$274,M$9:M$274) -> 0.060300507 | ... V279: =_xlfn.XLOOKUP($B279,$D$9:$D$274,Y$9:Y$274) -> 0.050303447
B280: Philippines | C280: =_xlfn.XLOOKUP($B280,$D$9:$D$274,F$9:F$274) -> 0.049425051 | D280: =_xlfn.XLOOKUP($B280,$D$9:$D$274,G$9:G$274) -> 0.053164168 | E280: =_xlfn.XLOOKUP($B280,$D$9:$D$274,H$9:H$274) -> 0.065192916 | F280: =_xlfn.XLOOKUP($B280,$D$9:$D$274,I$9:I$274) -> 0.043444873 | G280: =_xlfn.XLOOKUP($B280,$D$9:$D$274,J$9:J$274) -> 0.014483231 | H280: =_xlfn.XLOOKUP($B280,$D$9:$D$274,K$9:K$274) -> 0.073345 | I280: =_xlfn.XLOOKUP($B280,$D$9:$D$274,L$9:L$274) -> 0.038582328 | J280: =_xlfn.XLOOKUP($B280,$D$9:$D$274,M$9:M$274) -> 0.068969517 | ... V280: =_xlfn.XLOOKUP($B280,$D$9:$D$274,Y$9:Y$274) -> 0.056920161
B281: Thailand | C281: =_xlfn.XLOOKUP($B281,$D$9:$D$274,F$9:F$274) -> 0.041876384 | D281: =_xlfn.XLOOKUP($B281,$D$9:$D$274,G$9:G$274) -> 0.049678109 | E281: =_xlfn.XLOOKUP($B281,$D$9:$D$274,H$9:H$274) -> 0.054351517 | F281: =_xlfn.XLOOKUP($B281,$D$9:$D$274,I$9:I$274) -> 0.017256988 | G281: =_xlfn.XLOOKUP($B281,$D$9:$D$274,J$9:J$274) -> -0.0069061823 | H281: =_xlfn.XLOOKUP($B281,$D$9:$D$274,K$9:K$274) -> 0.075133905 | I281: =_xlfn.XLOOKUP($B281,$D$9:$D$274,L$9:L$274) -> 0.0084013208 | J281: =_xlfn.XLOOKUP($B281,$D$9:$D$274,M$9:M$274) -> 0.072427962 | ... V281: =_xlfn.XLOOKUP($B281,$D$9:$D$274,Y$9:Y$274) -> 0.025259618
B282: Vietnam | C282: 0.0629 | D282: 0.0629 | E282: 0.0629 | F282: 0.0629 | G282: 0.0629 | H282: 0.0629 | I282: 0.0629 | J282: 0.0629 | K282: 0.0629 | L282: 0.0629 | M282: 0.0629 | N282: 0.0629 | O282: 0.0629 | P282: 0.0629 | Q282: 0.0629 | R282: 0.0629 | S282: 0.0629 | T282: 0.0629 | U282: 0.0629 | V282: 0.0629
B283: Rest of Southeast Asia | C283: =AVERAGE(C284:C285) -> 0.13436142 | D283: =AVERAGE(D284:D285) -> 0.12009731 | E283: =AVERAGE(E284:E285) -> 0.11194947 | F283: =AVERAGE(F284:F285) -> 0.088658357 | G283: =AVERAGE(G284:G285) -> 0.073123938 | H283: =AVERAGE(H284:H285) -> 0.073556789 | I283: =AVERAGE(I284:I285) -> 0.064390703 | J283: =AVERAGE(J284:J285) -> 0.074914635 | ... V283: =AVERAGE(V284:V285) -> 0.025218841
B284: Cambodia | C284: =_xlfn.XLOOKUP($B284,$D$9:$D$274,F$9:F$274) -> 0.13303334 | D284: =_xlfn.XLOOKUP($B284,$D$9:$D$274,G$9:G$274) -> 0.1094336 | E284: =_xlfn.XLOOKUP($B284,$D$9:$D$274,H$9:H$274) -> 0.10398458 | F284: =_xlfn.XLOOKUP($B284,$D$9:$D$274,I$9:I$274) -> 0.074763661 | G284: =_xlfn.XLOOKUP($B284,$D$9:$D$274,J$9:J$274) -> 0.040747785 | H284: =_xlfn.XLOOKUP($B284,$D$9:$D$274,K$9:K$274) -> 0.050769184 | I284: =_xlfn.XLOOKUP($B284,$D$9:$D$274,L$9:L$274) -> 0.072866581 | J284: =_xlfn.XLOOKUP($B284,$D$9:$D$274,M$9:M$274) -> 0.076502566 | ... V284: =_xlfn.XLOOKUP($B284,$D$9:$D$274,Y$9:Y$274) -> 0.060158146
B285: Myanmar | C285: =_xlfn.XLOOKUP($B285,$D$9:$D$274,F$9:F$274) -> 0.1356895 | D285: =_xlfn.XLOOKUP($B285,$D$9:$D$274,G$9:G$274) -> 0.13076101 | E285: =_xlfn.XLOOKUP($B285,$D$9:$D$274,H$9:H$274) -> 0.11991435 | F285: =_xlfn.XLOOKUP($B285,$D$9:$D$274,I$9:I$274) -> 0.10255305 | G285: =_xlfn.XLOOKUP($B285,$D$9:$D$274,J$9:J$274) -> 0.10550009 | H285: =_xlfn.XLOOKUP($B285,$D$9:$D$274,K$9:K$274) -> 0.096344395 | I285: =_xlfn.XLOOKUP($B285,$D$9:$D$274,L$9:L$274) -> 0.055914824 | J285: =_xlfn.XLOOKUP($B285,$D$9:$D$274,M$9:M$274) -> 0.073326704 | ... V285: =_xlfn.XLOOKUP($B285,$D$9:$D$274,Y$9:Y$274) -> -0.0097204641
A287: x | B287: Revenue Split | L287: Revenue (USD Mns) | M287: Split | N287: Average GDP Growth
B288: Singapore | L288: ='Revenue Build'!J29 -> 578 | M288: =L288/SUM($L$288:$L$294) -> 0.20664998 | N288: =AVERAGE($C277:$V277) -> 0.046765109
B289: Malaysia | L289: ='Revenue Build'!J30 -> 816 | M289: =L289/SUM($L$288:$L$294) -> 0.29174115 | N289: =AVERAGE($C278:$V278) -> 0.044713475
B290: Indonesia | L290: ='Revenue Build'!J31 -> 643 | M290: =L290/SUM($L$288:$L$294) -> 0.22988917 | N290: =AVERAGE($C279:$V279) -> 0.049682718
B291: Philippines | L291: ='Revenue Build'!J32 -> 265 | M291: =L291/SUM($L$288:$L$294) -> 0.094744369 | N291: =AVERAGE($C280:$V280) -> 0.05081819
B292: Thailand | L292: ='Revenue Build'!J33 -> 252 | M292: =L292/SUM($L$288:$L$294) -> 0.090096532 | N292: =AVERAGE($C281:$V281) -> 0.027302249
B293: Vietnam | L293: ='Revenue Build'!J34 -> 228 | M293: =L293/SUM($L$288:$L$294) -> 0.08151591 | N293: =AVERAGE($C282:$V282) -> 0.0629
B294: Rest of Southeast Asia | L294: ='Revenue Build'!J35 -> 15 | M294: =L294/SUM($L$288:$L$294) -> 0.0053628888 | N294: =AVERAGE($C283:$V283) -> 0.062762684
B295: Weighted Average GDP Growth Rate | N295: =SUMPRODUCT(M288:M294,N288:N294) -> 0.046868804

Sheet Drivers>>

Sheet Debt & Equity
C1: =Cover!$C$7&" ("&Cover!$C$8&": "&Cover!$C$9&")" -> Grab Holdings Limited (NASDAQ: GRAB)
C3: 12M Target Price: | E3: =Cover!$C$18 -> 7.2080319
C4: Scenario: | E4: =Cover!$C$11 -> Base Case
H5: Historical (31 Jan) | M5: Forecast (31 Jan)
C6: ="In "&Cover!$C$10&", unless stated otherwise" -> In USD Mn, unless stated otherwise | H6: 20 | I6: =H6+1 -> 21 | J6: =I6+1 -> 22 | K6: =J6+1 -> 23 | L6: =K6+1 -> 24 | M6: =L6+1 -> 25 | N6: =M6+1 -> 26 | O6: =N6+1 -> 27 | P6: =O6+1 -> 28 | ... R6: =Q6+1 -> 30 | T6: Comments:
C7: Fiscal year end date | H7: 44196 | I7: =EOMONTH(H7,12) -> 44561 | J7: =EOMONTH(I7,12) -> 44926 | K7: =EOMONTH(J7,12) -> 45291 | L7: =EOMONTH(K7,12) -> 45657 | M7: =EOMONTH(L7,12) -> 46022 | N7: =EOMONTH(M7,12) -> 46387 | O7: =EOMONTH(N7,12) -> 46752 | P7: =EOMONTH(O7,12) -> 47118 | Q7: =EOMONTH(P7,12) -> 47483
A9: 1 | C9: Debt Schedule | H9: 20 | I9: =H9+1 -> 21 | J9: =I9+1 -> 22 | K9: =J9+1 -> 23 | L9: =K9+1 -> 24 | M9: 25 | N9: =M9+1 -> 26 | O9: =N9+1 -> 27 | P9: =O9+1 -> 28 | Q9: =P9+1 -> 29
C11: Financial Debt, Current | H11: ='3FS'!D78 -> 140 | I11: ='3FS'!E78 -> 144 | J11: ='3FS'!F78 -> 117 | K11: ='3FS'!G78 -> 125 | L11: ='3FS'!H78 -> 123 | M11: =MAX(L11+M36+M62,0) -> 1584 | N11: =MAX(M11+N36+N62,0) -> 1584 | O11: =MAX(N11+O36+O62,0) -> 1584 | P11: =MAX(O11+P36+P62,0) -> 75 | Q11: =MAX(P11+Q36+Q62,0) -> 0
C12: Financial Debt, Non-Current | H12: ='3FS'!D86 -> 111 | I12: ='3FS'!E86 -> 2031 | J12: ='3FS'!F86 -> 1248 | K12: ='3FS'!G86 -> 668 | L12: ='3FS'!H86 -> 241 | M12: =M41-M11 -> 241 | N12: =N41-N11 -> 241 | O12: =O41-O11 -> 241 | P12: =P41-P11 -> 241 | Q12: =Q41-Q11 -> 158
C13: Total Debt | H13: =SUM(H11:H12) -> 251 | I13: =SUM(I11:I12) -> 2175 | J13: =SUM(J11:J12) -> 1365 | K13: =SUM(K11:K12) -> 793 | L13: =SUM(L11:L12) -> 364 | M13: =SUM(M11:M12) -> 1825 | N13: =SUM(N11:N12) -> 1825 | O13: =SUM(O11:O12) -> 1825 | ... Q13: =SUM(Q11:Q12) -> 158
C16: Revolver Schedule | H16: 21 | I16: =H16+1 -> 22 | J16: =I16+1 -> 23 | K16: =J16+1 -> 24 | L16: =K16+1 -> 25 | M16: 26 | N16: =M16+1 -> 27 | O16: =N16+1 -> 28 | P16: =O16+1 -> 29 | Q16: =P16+1 -> 30
C18: CIRCULARITY | F18: OFF
C20: Revenue | H20: ='3FS'!D12 -> 469 | I20: ='3FS'!E12 -> 675 | J20: ='3FS'!F12 -> 1433 | K20: ='3FS'!G12 -> 2359 | L20: ='3FS'!H12 -> 2797 | M20: ='3FS'!I12 -> 3447.158 | N20: ='3FS'!J12 -> 4242.1624 | O20: ='3FS'!K12 -> 5260.5364 | ... Q20: ='3FS'!M12 -> 8096.0017
C22: Beginning Cash and Equivalents | M22: ='3FS'!H53 -> 2964 | N22: ='3FS'!I53 -> 3387.2668 | O22: ='3FS'!J53 -> 3227.6697 | P22: ='3FS'!K53 -> 3232.7186 | Q22: ='3FS'!L53 -> 1940.4896
C23: (+) Cash Flow from Operations + Investing | M23: ='3FS'!I131+'3FS'!I142 -> -1037.7332 | N23: ='3FS'!J131+'3FS'!J142 -> -159.5971 | O23: ='3FS'!K131+'3FS'!K142 -> 5.04889 | P23: ='3FS'!L131+'3FS'!L142 -> 216.77099 | Q23: ='3FS'!M131+'3FS'!M142 -> 615.01748
C24: (-) Debt Principal Repayments | M24: =M40 -> -39 | N24: =N40 -> 0 | O24: =O40 -> 0 | P24: =P40 -> -1509 | Q24: =Q40 -> -158
C25: (-) Mandatory Lease Repayments | M25: 0 | N25: 0 | O25: 0 | P25: 0 | Q25: 0
C26: (-) Dividends | M26: 0 | N26: 0 | O26: 0 | P26: 0 | Q26: 0
C27: (-) Minimum Cash Balance | F27: 0.05 | M27: =-M20*$F$27 -> -172.3579 | N27: =-N20*$F$27 -> -212.10812 | O27: =-O20*$F$27 -> -263.02682 | P27: =-P20*$F$27 -> -326.21693 | Q27: =-Q20*$F$27 -> -404.80008
