Workbook
Name Company_Name: '[1]lbo(yx)'!#REF!
Name Company_Name: 'LBO Val'!#REF!
Name Company_Name: #REF!
Name Hist_Year: 'LBO Val'!$E$20
Name Hist_Year: #REF!
Name IQ_CH: 110000
Name IQ_CQ: 5000
Name IQ_CY: 10000
Name IQ_DAILY: 500000
Name IQ_FH: 100000
Name IQ_FQ: 500
Name IQ_FY: 1000
Name IQ_LTM: 2000
Name IQ_MONTH: 15000
Name IQ_NTM: 6000
Name IQ_WEEK: 50000
Name IQ_YTD: 3000
Name LTM_EBITDA: '[1]lbo(yx)'!$E$12
Name LTM_EBITDA: 'LBO Val'!$E$12
Name LTM_EBITDA: #REF!
Name Mezz_Equity_Pct: '[1]lbo(yx)'!#REF!
Name Mezz_Equity_Pct: 'LBO Val'!#REF!
Name Mezz_Equity_Pct: #REF!
Name Mezz_Investment: '[1]lbo(yx)'!#REF!
Name Mezz_Investment: 'LBO Val'!#REF!
Name Mezz_Investment: #REF!
Name Mgmt_Option_Pool: '[1]lbo(yx)'!#REF!
Name Mgmt_Option_Pool: 'LBO Val'!#REF!
Name Mgmt_Option_Pool: #REF!
Name Min_Cash: '[1]lbo(yx)'!$E$31
Name Min_Cash: 'LBO Val'!$E$29
Name Min_Cash: #REF!
Name Purchase_Multiple: 'LBO Val'!$K$17
Name Purchase_Multiple: #REF!
Name Sponsor_Equity: '[1]lbo(yx)'!$D$46
Name Sponsor_Equity: 'LBO Val'!$D$44
Name Sponsor_Equity: #REF!
Name Units: 'LBO Val'!#REF!
Name Units: #REF!

Sheet Cover Page
C3: =$E$9 -> Coinbase Global Inc., (NASDAQ: COIN)
C4: Financial Model
C8: Description | N8: Color Codes
C9: Company | E9: Coinbase Global Inc., (NASDAQ: COIN)
C10: Last updated: | E10: =NOW() -> 46130.691 | O10: X | P10: Hardcoded
C11: Project: | E11: PEC Case | O11: X | P11: Linked to other tab
C12: Short description: | E12: Financial Projections | O12: X | P12: Formula
C13: Operating Case | E13: Base Case | O13: X | P13: For Inputs
C14: Owner | E14: dillon.hj@u.nus.edu

Sheet Valuation>

Sheet 3FS
A1: ='Cover Page'!$C$3 -> Coinbase Global Inc., (NASDAQ: COIN) | E1: 2021 | F1: =E1+1 -> 2022 | G1: =F1+1 -> 2023 | H1: =G1+1 -> 2024 | I1: =H1+1 -> 2025 | J1: =I1+1 -> 2026 | K1: =J1+1 -> 2027 | L1: =K1+1 -> 2028 | M1: =L1+1 -> 2029 | N1: =M1+1 -> 2030 | P1: 2021 | Q1: =P1 -> 2021 | R1: =Q1 -> 2021 | S1: =R1 -> 2021 | T1: =S1+1 -> 2022 | U1: =T1 -> 2022 | V1: =U1 -> 2022 | W1: =V1 -> 2022 | X1: =W1+1 -> 2023 | Y1: =X1 -> 2023 | Z1: =Y1 -> 2023 | AA1: =Z1 -> 2023 | AB1: =AA1+1 -> 2024 | AC1: =AB1 -> 2024 | AD1: =AC1 -> 2024 | AE1: =AD1 -> 2024 | AF1: =AE1+1 -> 2025 | AG1: =AF1 -> 2025 | AH1: =AG1 -> 2025 | AI1: =AH1 -> 2025 | AJ1: =AI1+1 -> 2026 | AK1: =AJ1 -> 2026 | AL1: =AK1 -> 2026 | AM1: =AL1 -> 2026 | AN1: =AM1+1 -> 2027 | AO1: =AN1 -> 2027 | AP1: =AO1 -> 2027 | AQ1: =AP1 -> 2027 | AR1: =AQ1+1 -> 2028 | AS1: =AR1 -> 2028 | AT1: =AS1 -> 2028 | AU1: =AT1 -> 2028 | AV1: =AU1+1 -> 2029 | AW1: =AV1 -> 2029 | AX1: =AW1 -> 2029 | AY1: =AX1 -> 2029 | AZ1: =AY1+1 -> 2030 | BA1: =AZ1 -> 2030 | BB1: =BA1 -> 2030 | BC1: =BB1 -> 2030
A2: 3 Financial Statements | E2: Q4 | F2: Q4 | G2: Q4 | H2: Q4 | I2: Q4 | J2: Q4 | K2: Q4 | L2: Q4 | M2: Q4 | N2: Q4 | P2: Q1 | Q2: Q2 | R2: Q3 | S2: Q4 | T2: Q1 | U2: Q2 | V2: Q3 | W2: Q4 | X2: Q1 | Y2: Q2 | Z2: Q3 | AA2: Q4 | AB2: Q1 | AC2: Q2 | AD2: Q3 | AE2: Q4 | AF2: Q1 | AG2: Q2 | AH2: Q3 | AI2: Q4 | AJ2: Q1 | AK2: Q2 | AL2: Q3 | AM2: Q4 | AN2: Q1 | AO2: Q2 | AP2: Q3 | AQ2: Q4 | AR2: Q1 | AS2: Q2 | AT2: Q3 | AU2: Q4 | AV2: Q1 | AW2: Q2 | AX2: Q3 | AY2: Q4 | AZ2: Q1 | BA2: Q2 | BB2: Q3 | BC2: Q4
E3: 12 | F3: 12 | G3: 12 | H3: 12 | I3: 12 | J3: 12 | K3: 12 | L3: 12 | M3: 12 | N3: 12 | P3: 3 | Q3: 3 | R3: 3 | S3: 3 | T3: 3 | U3: 3 | V3: 3 | W3: 3 | X3: 3 | Y3: 3 | Z3: 3 | AA3: 3 | AB3: 3 | AC3: 3 | AD3: 3 | AE3: 3 | AF3: 3 | AG3: 3 | AH3: 3 | AI3: 3 | AJ3: 3 | AK3: 3 | AL3: 3 | AM3: 3 | AN3: 3 | AO3: 3 | AP3: 3 | AQ3: 3 | AR3: 3 | AS3: 3 | AT3: 3 | AU3: 3 | AV3: 3 | AW3: 3 | AX3: 3 | AY3: 3 | AZ3: 3 | BA3: 3 | BB3: 3 | BC3: 3
E4: 365 | F4: 365 | G4: 365 | H4: 366 | I4: 365 | J4: 365 | K4: 365 | L4: 366 | M4: 365 | N4: 365 | P4: 90 | Q4: =Q6-P6 -> 91 | R4: =R6-Q6 -> 92 | S4: =S6-R6 -> 92 | T4: =T6-S6 -> 90 | U4: =U6-T6 -> 91 | V4: =V6-U6 -> 92 | W4: =W6-V6 -> 92 | X4: =X6-W6 -> 90 | ... BC4: =BC6-BB6 -> 92
E5: Actuals | F5: Actuals | G5: Actuals | H5: Actuals | I5: Actuals | J5: Forecasted | K5: Forecasted | L5: Forecasted | M5: Forecasted | N5: Forecasted | P5: Actuals | Q5: Actuals | R5: Actuals | S5: Actuals | T5: Actuals | U5: Actuals | V5: Actuals | W5: Actuals | X5: Actuals | Y5: Actuals | Z5: Actuals | AA5: Actuals | AB5: Actuals | AC5: Actuals | AD5: Actuals | AE5: Actuals | AF5: Actuals | AG5: Actuals | AH5: Actuals | AI5: Actuals | AJ5: Forecasted | AK5: Forecasted | AL5: Forecasted | AM5: Forecasted | AN5: Forecasted | AO5: Forecasted | AP5: Forecasted | AQ5: Forecasted | AR5: Forecasted | AS5: Forecasted | AT5: Forecasted | AU5: Forecasted | AV5: Forecasted | AW5: Forecasted | AX5: Forecasted | AY5: Forecasted | AZ5: Forecasted | BA5: Forecasted | BB5: Forecasted | BC5: Forecasted
A6: In USD '000s, Unless Stated Otherwise | E6: 44561 | F6: =EOMONTH(E6,12) -> 44926 | G6: =EOMONTH(F6,12) -> 45291 | H6: =EOMONTH(G6,12) -> 45657 | I6: =EOMONTH(H6,12) -> 46022 | J6: =EOMONTH(I6,12) -> 46387 | K6: =EOMONTH(J6,12) -> 46752 | L6: =EOMONTH(K6,12) -> 47118 | M6: =EOMONTH(L6,12) -> 47483 | N6: =EOMONTH(M6,12) -> 47848 | P6: 44286 | Q6: =EOMONTH(P6,3) -> 44377 | R6: =EOMONTH(Q6,3) -> 44469 | S6: =EOMONTH(R6,3) -> 44561 | T6: =EOMONTH(S6,3) -> 44651 | U6: =EOMONTH(T6,3) -> 44742 | V6: =EOMONTH(U6,3) -> 44834 | W6: =EOMONTH(V6,3) -> 44926 | X6: =EOMONTH(W6,3) -> 45016 | ... BC6: =EOMONTH(BB6,3) -> 47848
A8: x | B8: P&L | D8: Units | E8: 21 | F8: =E8+1 -> 22 | G8: =F8+1 -> 23 | H8: =G8+1 -> 24 | I8: =H8+1 -> 25 | J8: =I8+1 -> 26 | K8: =J8+1 -> 27 | L8: =K8+1 -> 28 | M8: =L8+1 -> 29 | N8: =M8+1 -> 30 | P8: =P6 -> 44286 | Q8: =Q6 -> 44377 | R8: =R6 -> 44469 | S8: =S6 -> 44561 | T8: =T6 -> 44651 | U8: =U6 -> 44742 | V8: =V6 -> 44834 | W8: =W6 -> 44926 | ... BC8: =BC6 -> 47848
B10: Sales
B12: Revenues
B13: Net Revenues | D13: USD '000s | E13: =SUMIF($P$1:$AI$1,E$1,$P13:$AI13) -> 7354754 | F13: =SUMIF($P$1:$AI$1,F$1,$P13:$AI13) -> 3148815 | G13: =SUMIF($P$1:$AI$1,G$1,$P13:$AI13) -> 2926540 | H13: =SUMIF($P$1:$AI$1,H$1,$P13:$AI13) -> 6293246 | I13: =SUMIF($P$1:$AI$1,I$1,$P13:$AI13) -> 6883438 | J13: =SUMIFS($AJ13:$BC13,$AJ$1:$BC$1,J$1) -> 7476596.4 | K13: =SUMIFS($AJ13:$BC13,$AJ$1:$BC$1,K$1) -> 8407060.3 | L13: =SUMIFS($AJ13:$BC13,$AJ$1:$BC$1,L$1) -> 9466956 | M13: =SUMIFS($AJ13:$BC13,$AJ$1:$BC$1,M$1) -> 11048606 | N13: =SUMIFS($AJ13:$BC13,$AJ$1:$BC$1,N$1) -> 13606441 | P13: 1596981 | Q13: 2033011 | R13: 1234736 | S13: 2490026 | T13: 1164891 | U13: 802603 | V13: 576375 | W13: 604946 | X13: 736398 | Y13: 662500 | Z13: 623004 | AA13: 904638 | AB13: 1587677 | AC13: 1379942 | AD13: 1128597 | AE13: 2197030 | AF13: 1960319 | AG13: 1420096 | AH13: 1792984 | AI13: 1710039 | AJ13: =SUM('Revenue Build'!AI24) -> 1793000 | AK13: =SUM('Revenue Build'!AJ24) -> 1710000 | AL13: =SUM('Revenue Build'!AK24) -> 2301680.4 | AM13: =SUM('Revenue Build'!AL24) -> 1671916 | AN13: =SUM('Revenue Build'!AM24) -> 1877501.6 | AO13: =SUM('Revenue Build'!AN24) -> 1958998.9 | AP13: =SUM('Revenue Build'!AO24) -> 2670524.5 | AQ13: =SUM('Revenue Build'!AP24) -> 1900035.5 | ... BC13: =SUM('Revenue Build'!BB24) -> 3107259.8
B14: Other Revenues | D14: USD '000s | E14: =SUMIF($P$1:$AI$1,E$1,$P14:$AI14) -> 484691 | F14: =SUMIF($P$1:$AI$1,F$1,$P14:$AI14) -> 45393 | G14: =SUMIF($P$1:$AI$1,G$1,$P14:$AI14) -> 181843 | H14: =SUMIF($P$1:$AI$1,H$1,$P14:$AI14) -> 270782 | I14: =SUMIF($P$1:$AI$1,I$1,$P14:$AI14) -> 297887 | J14: =SUMIFS($AJ14:$BC14,$AJ$1:$BC$1,J$1) -> 283923.46 | K14: =SUMIFS($AJ14:$BC14,$AJ$1:$BC$1,K$1) -> 270602.65 | L14: =SUMIFS($AJ14:$BC14,$AJ$1:$BC$1,L$1) -> 257906.82 | M14: =SUMIFS($AJ14:$BC14,$AJ$1:$BC$1,M$1) -> 245806.63 | N14: =SUMIFS($AJ14:$BC14,$AJ$1:$BC$1,N$1) -> 234274.15 | P14: 204131 | Q14: 194951 | R14: 77172 | S14: 8437 | T14: 1545 | U14: 5722 | V14: 13964 | W14: 24162 | X14: 36131 | Y14: 45411 | Z14: 51144 | AA14: 49157 | AB14: 49893 | AC14: 69686 | AD14: 76596 | AE14: 74607 | AF14: 73976 | AG14: 77112 | AH14: 75709 | AI14: 71090 | AJ14: ='Revenue Build'!AK26 -> 70528.15 | AK14: ='Revenue Build'!AL26 -> 73482.708 | AL14: ='Revenue Build'!AM26 -> 72148.391 | AM14: ='Revenue Build'!AN26 -> 67764.209 | AN14: ='Revenue Build'!AO26 -> 67219.189 | AO14: ='Revenue Build'!AP26 -> 70035.128 | AP14: ='Revenue Build'!AQ26 -> 68763.413 | AQ14: ='Revenue Build'!AR26 -> 64584.923 | ... BC14: ='Revenue Build'!BD26 -> 55914.374
B15: Total Revenues | D15: USD '000s | E15: =SUM(E13:E14) -> 7839445 | F15: =SUM(F13:F14) -> 3194208 | G15: =SUM(G13:G14) -> 3108383 | H15: =SUM(H13:H14) -> 6564028 | I15: =SUM(I13:I14) -> 7181325 | J15: =SUM(J13:J14) -> 7760519.9 | K15: =SUM(K13:K14) -> 8677663 | L15: =SUM(L13:L14) -> 9724862.8 | ... N15: =SUM(N13:N14) -> 13840715 | P15: =SUM(P13:P14) -> 1801112 | Q15: =SUM(Q13:Q14) -> 2227962 | R15: =SUM(R13:R14) -> 1311908 | S15: =SUM(S13:S14) -> 2498463 | T15: =SUM(T13:T14) -> 1166436 | U15: =SUM(U13:U14) -> 808325 | V15: =SUM(V13:V14) -> 590339 | W15: =SUM(W13:W14) -> 629108 | ... BC15: =SUM(BC13:BC14) -> 3163174.1
B17: Net Revenues | D17: % | E17: =E13/E$15 -> 0.93817279 | F17: =F13/F$15 -> 0.98578897 | G17: =G13/G$15 -> 0.94149917 | H17: =H13/H$15 -> 0.95874759 | I17: =I13/I$15 -> 0.95851921 | J17: =J13/J$15 -> 0.96341438 | K17: =K13/K$15 -> 0.96881618 | L17: =L13/L$15 -> 0.97347964 | ... N17: =N13/N$15 -> 0.98307355 | P17: =P13/P$15 -> 0.88666391 | Q17: =Q13/Q$15 -> 0.91249806 | R17: =R13/R$15 -> 0.94117575 | S17: =S13/S$15 -> 0.99662312 | T17: =T13/T$15 -> 0.99867545 | U17: =U13/U$15 -> 0.99292116 | V17: =V13/V$15 -> 0.97634579 | W17: =W13/W$15 -> 0.96159324 | ... BC17: =BC13/BC$15 -> 0.98232333
B18: Other Revenues | D18: % | E18: =E14/E$15 -> 0.061827208 | F18: =F14/F$15 -> 0.014211034 | G18: =G14/G$15 -> 0.058500835 | H18: =H14/H$15 -> 0.041252414 | I18: =I14/I$15 -> 0.041480785 | J18: =J14/J$15 -> 0.036585624 | K18: =K14/K$15 -> 0.031183817 | L18: =L14/L$15 -> 0.026520355 | ... N18: =N14/N$15 -> 0.016926448 | P18: =P14/P$15 -> 0.11333609 | Q18: =Q14/Q$15 -> 0.087501941 | R18: =R14/R$15 -> 0.058824247 | S18: =S14/S$15 -> 0.0033768761 | T18: =T14/T$15 -> 0.0013245476 | U18: =U14/U$15 -> 0.0070788359 | V18: =V14/V$15 -> 0.023654205 | W18: =W14/W$15 -> 0.03840676 | ... BC18: =BC14/BC$15 -> 0.017676666
B20: Cost of Goods Sold | D20: USD '000s | E20: =SUMIF($P$1:$AI$1,E$1,$P20:$AI20) -> 0 | F20: =SUMIF($P$1:$AI$1,F$1,$P20:$AI20) -> 0 | G20: =SUMIF($P$1:$AI$1,G$1,$P20:$AI20) -> -125559 | H20: =SUMIF($P$1:$AI$1,H$1,$P20:$AI20) -> 0 | I20: =SUMIF($P$1:$AI$1,I$1,$P20:$AI20) -> 0 | J20: =SUMIFS($AJ20:$BC20,$AJ$1:$BC$1,J$1) -> 0 | K20: =SUMIFS($AJ20:$BC20,$AJ$1:$BC$1,K$1) -> 0 | L20: =SUMIFS($AJ20:$BC20,$AJ$1:$BC$1,L$1) -> 0 | M20: =SUMIFS($AJ20:$BC20,$AJ$1:$BC$1,M$1) -> 0 | N20: =SUMIFS($AJ20:$BC20,$AJ$1:$BC$1,N$1) -> 0 | P20: 0 | Q20: 0 | R20: 0 | S20: 0 | T20: 0 | U20: 0 | V20: 0 | W20: 0 | X20: 0 | Y20: 0 | Z20: 0 | AA20: -125559 | AB20: 0 | AC20: 0 | AD20: 0 | AE20: 0 | AF20: 0 | AG20: 0 | AH20: 0 | AI20: 0 | AJ20: =_xlfn.XLOOKUP($B20,'IS & BS Projections'!$B:$B,'IS & BS Projections'!AK:AK) -> 0 | AK20: =_xlfn.XLOOKUP($B20,'IS & BS Projections'!$B:$B,'IS & BS Projections'!AL:AL) -> 0 | AL20: =_xlfn.XLOOKUP($B20,'IS & BS Projections'!$B:$B,'IS & BS Projections'!AM:AM) -> 0 | AM20: =_xlfn.XLOOKUP($B20,'IS & BS Projections'!$B:$B,'IS & BS Projections'!AN:AN) -> 0 | AN20: =_xlfn.XLOOKUP($B20,'IS & BS Projections'!$B:$B,'IS & BS Projections'!AO:AO) -> 0 | AO20: =_xlfn.XLOOKUP($B20,'IS & BS Projections'!$B:$B,'IS & BS Projections'!AP:AP) -> 0 | AP20: =_xlfn.XLOOKUP($B20,'IS & BS Projections'!$B:$B,'IS & BS Projections'!AQ:AQ) -> 0 | AQ20: =_xlfn.XLOOKUP($B20,'IS & BS Projections'!$B:$B,'IS & BS Projections'!AR:AR) -> 0 | AR20: =_xlfn.XLOOKUP($B20,'IS & BS Projections'!$B:$B,'IS & BS Projections'!AS:AS) -> 0 | AS20: =_xlfn.XLOOKUP($B20,'IS & BS Projections'!$B:$B,'IS & BS Projections'!AT:AT) -> 0 | AT20: =_xlfn.XLOOKUP($B20,'IS & BS Projections'!$B:$B,'IS & BS Projections'!AU:AU) -> 0 | AU20: =_xlfn.XLOOKUP($B20,'IS & BS Projections'!$B:$B,'IS & BS Projections'!AV:AV) -> 0 | AV20: =_xlfn.XLOOKUP($B20,'IS & BS Projections'!$B:$B,'IS & BS Projections'!AW:AW) -> 0 | AW20: =_xlfn.XLOOKUP($B20,'IS & BS Projections'!$B:$B,'IS & BS Projections'!AX:AX) -> 0 | AX20: =_xlfn.XLOOKUP($B20,'IS & BS Projections'!$B:$B,'IS & BS Projections'!AY:AY) -> 0 | AY20: =_xlfn.XLOOKUP($B20,'IS & BS Projections'!$B:$B,'IS & BS Projections'!AZ:AZ) -> 0 | AZ20: =_xlfn.XLOOKUP($B20,'IS & BS Projections'!$B:$B,'IS & BS Projections'!BA:BA) -> 0 | BA20: =_xlfn.XLOOKUP($B20,'IS & BS Projections'!$B:$B,'IS & BS Projections'!BB:BB) -> 0 | BB20: =_xlfn.XLOOKUP($B20,'IS & BS Projections'!$B:$B,'IS & BS Projections'!BC:BC) -> 0 | BC20: =_xlfn.XLOOKUP($B20,'IS & BS Projections'!$B:$B,'IS & BS Projections'!BD:BD) -> 0
B22: Gross Profit | D22: USD '000s | E22: =SUM(E15,E20) -> 7839445 | F22: =SUM(F15,F20) -> 3194208 | G22: =SUM(G15,G20) -> 2982824 | H22: =SUM(H15,H20) -> 6564028 | I22: =SUM(I15,I20) -> 7181325 | J22: =SUM(J15,J20) -> 7760519.9 | K22: =SUM(K15,K20) -> 8677663 | L22: =SUM(L15,L20) -> 9724862.8 | ... N22: =SUM(N15,N20) -> 13840715 | P22: =SUM(P15,P20) -> 1801112 | Q22: =SUM(Q15,Q20) -> 2227962 | R22: =SUM(R15,R20) -> 1311908 | S22: =SUM(S15,S20) -> 2498463 | T22: =SUM(T15,T20) -> 1166436 | U22: =SUM(U15,U20) -> 808325 | V22: =SUM(V15,V20) -> 590339 | W22: =SUM(W15,W20) -> 629108 | ... BC22: =SUM(BC15,BC20) -> 3163174.1
B23: Gross Profit Margin | D23: % | E23: =E22/E$15 -> 1 | F23: =F22/F$15 -> 1 | G23: =G22/G$15 -> 0.95960633 | H23: =H22/H$15 -> 1 | I23: =I22/I$15 -> 1 | J23: =J22/J$15 -> 1 | K23: =K22/K$15 -> 1 | L23: =L22/L$15 -> 1 | ... N23: =N22/N$15 -> 1 | P23: =P22/P$15 -> 1 | Q23: =Q22/Q$15 -> 1 | R23: =R22/R$15 -> 1 | S23: =S22/S$15 -> 1 | T23: =T22/T$15 -> 1 | U23: =U22/U$15 -> 1 | V23: =V22/V$15 -> 1 | W23: =W22/W$15 -> 1 | ... BC23: =BC22/BC$15 -> 1
B25: Transaction Expenses | D25: USD '000s | E25: =SUMIF($P$1:$AI$1,E$1,$P25:$AI25) -> -1267924 | F25: =SUMIF($P$1:$AI$1,F$1,$P25:$AI25) -> -629880 | G25: =SUMIF($P$1:$AI$1,G$1,$P25:$AI25) -> -295146 | H25: =SUMIF($P$1:$AI$1,H$1,$P25:$AI25) -> -897707 | I25: =SUMIF($P$1:$AI$1,I$1,$P25:$AI25) -> -1020230 | J25: =SUMIFS($AJ25:$BC25,$AJ$1:$BC$1,J$1) -> -1087847.8 | K25: =SUMIFS($AJ25:$BC25,$AJ$1:$BC$1,K$1) -> -1217922.3 | L25: =SUMIFS($AJ25:$BC25,$AJ$1:$BC$1,L$1) -> -1366029.7 | M25: =SUMIFS($AJ25:$BC25,$AJ$1:$BC$1,M$1) -> -1588200.3 | N25: =SUMIFS($AJ25:$BC25,$AJ$1:$BC$1,N$1) -> -1948753.5 | P25: -234066 | Q25: -335426 | R25: -197251 | S25: -501181 | T25: -277826 | U25: -167187 | V25: -101876 | W25: -82991 | X25: -96369 | Y25: -108200 | Z25: -90577 | AA25: 0 | AB25: -217407 | AC25: -191477 | AD25: -171781 | AE25: -317042 | AF25: -303026 | AG25: -245261 | AH25: -253318 | AI25: -218625 | AJ25: =_xlfn.XLOOKUP($B25,'IS & BS Projections'!$B:$B,'IS & BS Projections'!AK:AK) -> -247405.65 | AK25: =_xlfn.XLOOKUP($B25,'IS & BS Projections'!$B:$B,'IS & BS Projections'!AL:AL) -> -272594.76 | AL25: =_xlfn.XLOOKUP($B25,'IS & BS Projections'!$B:$B,'IS & BS Projections'!AM:AM) -> -338351.35 | AM25: =_xlfn.XLOOKUP($B25,'IS & BS Projections'!$B:$B,'IS & BS Projections'!AN:AN) -> -229496.05 | AN25: =_xlfn.XLOOKUP($B25,'IS & BS Projections'!$B:$B,'IS & BS Projections'!AO:AO) -> -258184.93 | AO25: =_xlfn.XLOOKUP($B25,'IS & BS Projections'!$B:$B,'IS & BS Projections'!AP:AP) -> -310125.82 | AP25: =_xlfn.XLOOKUP($B25,'IS & BS Projections'!$B:$B,'IS & BS Projections'!AQ:AQ) -> -390441.7 | AQ25: =_xlfn.XLOOKUP($B25,'IS & BS Projections'!$B:$B,'IS & BS Projections'!AR:AR) -> -259169.83 | AR25: =_xlfn.XLOOKUP($B25,'IS & BS Projections'!$B:$B,'IS & BS Projections'!AS:AS) -> -281050.65 | AS25: =_xlfn.XLOOKUP($B25,'IS & BS Projections'!$B:$B,'IS & BS Projections'!AT:AT) -> -354884.3 | AT25: =_xlfn.XLOOKUP($B25,'IS & BS Projections'!$B:$B,'IS & BS Projections'!AU:AU) -> -439978.54 | AU25: =_xlfn.XLOOKUP($B25,'IS & BS Projections'!$B:$B,'IS & BS Projections'!AV:AV) -> -290116.24 | AV25: =_xlfn.XLOOKUP($B25,'IS & BS Projections'!$B:$B,'IS & BS Projections'!AW:AW) -> -310314.72 | AW25: =_xlfn.XLOOKUP($B25,'IS & BS Projections'!$B:$B,'IS & BS Projections'!AX:AX) -> -422069.8 | AX25: =_xlfn.XLOOKUP($B25,'IS & BS Projections'!$B:$B,'IS & BS Projections'!AY:AY) -> -516966.32 | AY25: =_xlfn.XLOOKUP($B25,'IS & BS Projections'!$B:$B,'IS & BS Projections'!AZ:AZ) -> -338849.5 | AZ25: =_xlfn.XLOOKUP($B25,'IS & BS Projections'!$B:$B,'IS & BS Projections'!BA:BA) -> -356531.68 | BA25: =_xlfn.XLOOKUP($B25,'IS & BS Projections'!$B:$B,'IS & BS Projections'!BB:BB) -> -530759.49 | BB25: =_xlfn.XLOOKUP($B25,'IS & BS Projections'!$B:$B,'IS & BS Projections'!BC:BC) -> -644181.04 | BC25: =_xlfn.XLOOKUP($B25,'IS & BS Projections'!$B:$B,'IS & BS Projections'!BD:BD) -> -417281.27
B26: Sales and Marketing | D26: USD '000s | E26: =SUMIF($P$1:$AI$1,E$1,$P26:$AI26) -> -663690 | F26: =SUMIF($P$1:$AI$1,F$1,$P26:$AI26) -> -510089 | G26: =SUMIF($P$1:$AI$1,G$1,$P26:$AI26) -> -332312 | H26: =SUMIF($P$1:$AI$1,H$1,$P26:$AI26) -> -654444 | I26: =SUMIF($P$1:$AI$1,I$1,$P26:$AI26) -> -1058577 | J26: =SUMIFS($AJ26:$BC26,$AJ$1:$BC$1,J$1) -> -787027.43 | K26: =SUMIFS($AJ26:$BC26,$AJ$1:$BC$1,K$1) -> -877038.44 | L26: =SUMIFS($AJ26:$BC26,$AJ$1:$BC$1,L$1) -> -975567.07 | M26: =SUMIFS($AJ26:$BC26,$AJ$1:$BC$1,M$1) -> -1126367.8 | N26: =SUMIFS($AJ26:$BC26,$AJ$1:$BC$1,N$1) -> -1373485.3 | P26: -117990 | Q26: -195733 | R26: -105395 | S26: -244572 | T26: -200204 | U26: -140894 | V26: -75888 | W26: -93103 | X26: -63976 | Y26: -83853 | Z26: -78178 | AA26: -106305 | AB26: -98585 | AC26: -165262 | AD26: -164770 | AE26: -225827 | AF26: -247283 | AG26: -236245 | AH26: -260272 | AI26: -314777 | AJ26: =_xlfn.XLOOKUP($B26,'IS & BS Projections'!$B:$B,'IS & BS Projections'!AK:AK) -> -135690.42 | AK26: =_xlfn.XLOOKUP($B26,'IS & BS Projections'!$B:$B,'IS & BS Projections'!AL:AL) -> -193421.07 | AL26: =_xlfn.XLOOKUP($B26,'IS & BS Projections'!$B:$B,'IS & BS Projections'!AM:AM) -> -281417.08 | AM26: =_xlfn.XLOOKUP($B26,'IS & BS Projections'!$B:$B,'IS & BS Projections'!AN:AN) -> -176498.85 | AN26: =_xlfn.XLOOKUP($B26,'IS & BS Projections'!$B:$B,'IS & BS Projections'!AO:AO) -> -139657.63 | AO26: =_xlfn.XLOOKUP($B26,'IS & BS Projections'!$B:$B,'IS & BS Projections'!AP:AP) -> -218022.4 | AP26: =_xlfn.XLOOKUP($B26,'IS & BS Projections'!$B:$B,'IS & BS Projections'!AQ:AQ) -> -322002.92 | AQ26: =_xlfn.XLOOKUP($B26,'IS & BS Projections'!$B:$B,'IS & BS Projections'!AR:AR) -> -197355.48 | AR26: =_xlfn.XLOOKUP($B26,'IS & BS Projections'!$B:$B,'IS & BS Projections'!AS:AS) -> -149909.22 | AS26: =_xlfn.XLOOKUP($B26,'IS & BS Projections'!$B:$B,'IS & BS Projections'!AT:AT) -> -247166.31 | AT26: =_xlfn.XLOOKUP($B26,'IS & BS Projections'!$B:$B,'IS & BS Projections'!AU:AU) -> -359769.84 | AU26: =_xlfn.XLOOKUP($B26,'IS & BS Projections'!$B:$B,'IS & BS Projections'!AV:AV) -> -218721.69 | AV26: =_xlfn.XLOOKUP($B26,'IS & BS Projections'!$B:$B,'IS & BS Projections'!AW:AW) -> -163180.97 | AW26: =_xlfn.XLOOKUP($B26,'IS & BS Projections'!$B:$B,'IS & BS Projections'!AX:AX) -> -291197.57 | AX26: =_xlfn.XLOOKUP($B26,'IS & BS Projections'!$B:$B,'IS & BS Projections'!AY:AY) -> -419095.67 | AY26: =_xlfn.XLOOKUP($B26,'IS & BS Projections'!$B:$B,'IS & BS Projections'!AZ:AZ) -> -252893.59 | AZ26: =_xlfn.XLOOKUP($B26,'IS & BS Projections'!$B:$B,'IS & BS Projections'!BA:BA) -> -184798.95 | BA26: =_xlfn.XLOOKUP($B26,'IS & BS Projections'!$B:$B,'IS & BS Projections'!BB:BB) -> -362713.02 | BB26: =_xlfn.XLOOKUP($B26,'IS & BS Projections'!$B:$B,'IS & BS Projections'!BC:BC) -> -517706.96 | BC26: =_xlfn.XLOOKUP($B26,'IS & BS Projections'!$B:$B,'IS & BS Projections'!BD:BD) -> -308266.4
B27: General and Administrative | D27: USD '000s | E27: =SUMIF($P$1:$AI$1,E$1,$P27:$AI27) -> -909392 | F27: =SUMIF($P$1:$AI$1,F$1,$P27:$AI27) -> -1600586 | G27: =SUMIF($P$1:$AI$1,G$1,$P27:$AI27) -> -1074308 | H27: =SUMIF($P$1:$AI$1,H$1,$P27:$AI27) -> -1300257 | I27: =SUMIF($P$1:$AI$1,I$1,$P27:$AI27) -> -1619642 | J27: =SUMIFS($AJ27:$BC27,$AJ$1:$BC$1,J$1) -> -1875931 | K27: =SUMIFS($AJ27:$BC27,$AJ$1:$BC$1,K$1) -> -2107093.6 | L27: =SUMIFS($AJ27:$BC27,$AJ$1:$BC$1,L$1) -> -2364618.1 | M27: =SUMIFS($AJ27:$BC27,$AJ$1:$BC$1,M$1) -> -2753249.1 | N27: =SUMIFS($AJ27:$BC27,$AJ$1:$BC$1,N$1) -> -3384661.7 | P27: -121231 | Q27: -248195 | R27: -242642 | S27: -297324 | T27: -413578 | U27: -470169 | V27: -339157 | W27: -377682 | X27: -248761 | Y27: -258988 | Z27: -252630 | AA27: -313929 | AB27: -287236 | AC27: -320115 | AD27: -330387 | AE27: -362519 | AF27: -394346 | AG27: -353707 | AH27: -418446 | AI27: -453143 | AJ27: =_xlfn.XLOOKUP($B27,'IS & BS Projections'!$B:$B,'IS & BS Projections'!AK:AK) -> -361243.02 | AK27: =_xlfn.XLOOKUP($B27,'IS & BS Projections'!$B:$B,'IS & BS Projections'!AL:AL) -> -421337.8 | AL27: =_xlfn.XLOOKUP($B27,'IS & BS Projections'!$B:$B,'IS & BS Projections'!AM:AM) -> -650752.34 | AM27: =_xlfn.XLOOKUP($B27,'IS & BS Projections'!$B:$B,'IS & BS Projections'!AN:AN) -> -442597.88 | AN27: =_xlfn.XLOOKUP($B27,'IS & BS Projections'!$B:$B,'IS & BS Projections'!AO:AO) -> -376982.12 | AO27: =_xlfn.XLOOKUP($B27,'IS & BS Projections'!$B:$B,'IS & BS Projections'!AP:AP) -> -479347.91 | AP27: =_xlfn.XLOOKUP($B27,'IS & BS Projections'!$B:$B,'IS & BS Projections'!AQ:AQ) -> -750937.9 | AQ27: =_xlfn.XLOOKUP($B27,'IS & BS Projections'!$B:$B,'IS & BS Projections'!AR:AR) -> -499825.66 | AR27: =_xlfn.XLOOKUP($B27,'IS & BS Projections'!$B:$B,'IS & BS Projections'!AS:AS) -> -410368.92 | AS27: =_xlfn.XLOOKUP($B27,'IS & BS Projections'!$B:$B,'IS & BS Projections'!AT:AT) -> -548529.14 | AT27: =_xlfn.XLOOKUP($B27,'IS & BS Projections'!$B:$B,'IS & BS Projections'!AU:AU) -> -846212.27 | AU27: =_xlfn.XLOOKUP($B27,'IS & BS Projections'!$B:$B,'IS & BS Projections'!AV:AV) -> -559507.81 | AV27: =_xlfn.XLOOKUP($B27,'IS & BS Projections'!$B:$B,'IS & BS Projections'!AW:AW) -> -453098.09 | AW27: =_xlfn.XLOOKUP($B27,'IS & BS Projections'!$B:$B,'IS & BS Projections'!AX:AX) -> -652374.83 | AX27: =_xlfn.XLOOKUP($B27,'IS & BS Projections'!$B:$B,'IS & BS Projections'!AY:AY) -> -994283.13 | AY27: =_xlfn.XLOOKUP($B27,'IS & BS Projections'!$B:$B,'IS & BS Projections'!AZ:AZ) -> -653493.04 | AZ27: =_xlfn.XLOOKUP($B27,'IS & BS Projections'!$B:$B,'IS & BS Projections'!BA:BA) -> -520580.6 | BA27: =_xlfn.XLOOKUP($B27,'IS & BS Projections'!$B:$B,'IS & BS Projections'!BB:BB) -> -820371.73 | BB27: =_xlfn.XLOOKUP($B27,'IS & BS Projections'!$B:$B,'IS & BS Projections'!BC:BC) -> -1238955.7 | BC27: =_xlfn.XLOOKUP($B27,'IS & BS Projections'!$B:$B,'IS & BS Projections'!BD:BD) -> -804753.74
B28: Technology Development | D28: USD '000s | E28: =SUMIF($P$1:$AI$1,E$1,$P28:$AI28) -> -1291561 | F28: =SUMIF($P$1:$AI$1,F$1,$P28:$AI28) -> -2326354 | G28: =SUMIF($P$1:$AI$1,G$1,$P28:$AI28) -> -1324541 | H28: =SUMIF($P$1:$AI$1,H$1,$P28:$AI28) -> -1468252 | I28: =SUMIF($P$1:$AI$1,I$1,$P28:$AI28) -> -1670605 | J28: =SUMIFS($AJ28:$BC28,$AJ$1:$BC$1,J$1) -> -1515771.2 | K28: =SUMIFS($AJ28:$BC28,$AJ$1:$BC$1,K$1) -> -1683819.7 | L28: =SUMIFS($AJ28:$BC28,$AJ$1:$BC$1,L$1) -> -1866088.7 | M28: =SUMIFS($AJ28:$BC28,$AJ$1:$BC$1,M$1) -> -2146482.3 | N28: =SUMIFS($AJ28:$BC28,$AJ$1:$BC$1,N$1) -> -2607377.5 | P28: -184225 | Q28: -291461 | R28: -356264 | S28: -459611 | T28: -570664 | U28: -609249 | V28: -556338 | W28: -590103 | X28: -358031 | Y28: -320667 | Z28: -322756 | AA28: -323087 | AB28: -357863 | AC28: -364258 | AD28: -377440 | AE28: -368691 | AF28: -355368 | AG28: -387322 | AH28: -430585 | AI28: -497330 | AJ28: =_xlfn.XLOOKUP($B28,'IS & BS Projections'!$B:$B,'IS & BS Projections'!AK:AK) -> -267477.69 | AK28: =_xlfn.XLOOKUP($B28,'IS & BS Projections'!$B:$B,'IS & BS Projections'!AL:AL) -> -327618.97 | AL28: =_xlfn.XLOOKUP($B28,'IS & BS Projections'!$B:$B,'IS & BS Projections'!AM:AM) -> -565393.92 | AM28: =_xlfn.XLOOKUP($B28,'IS & BS Projections'!$B:$B,'IS & BS Projections'!AN:AN) -> -355280.59 | AN28: =_xlfn.XLOOKUP($B28,'IS & BS Projections'!$B:$B,'IS & BS Projections'!AO:AO) -> -274269.7 | AO28: =_xlfn.XLOOKUP($B28,'IS & BS Projections'!$B:$B,'IS & BS Projections'!AP:AP) -> -367653.22 | AP28: =_xlfn.XLOOKUP($B28,'IS & BS Projections'!$B:$B,'IS & BS Projections'!AQ:AQ) -> -645590.04 | AQ28: =_xlfn.XLOOKUP($B28,'IS & BS Projections'!$B:$B,'IS & BS Projections'!AR:AR) -> -396306.71 | AR28: =_xlfn.XLOOKUP($B28,'IS & BS Projections'!$B:$B,'IS & BS Projections'!AS:AS) -> -293267.56 | AS28: =_xlfn.XLOOKUP($B28,'IS & BS Projections'!$B:$B,'IS & BS Projections'!AT:AT) -> -414909.59 | AT28: =_xlfn.XLOOKUP($B28,'IS & BS Projections'!$B:$B,'IS & BS Projections'!AU:AU) -> -719781.44 | AU28: =_xlfn.XLOOKUP($B28,'IS & BS Projections'!$B:$B,'IS & BS Projections'!AV:AV) -> -438130.07 | AV28: =_xlfn.XLOOKUP($B28,'IS & BS Projections'!$B:$B,'IS & BS Projections'!AW:AW) -> -317960.25 | AW28: =_xlfn.XLOOKUP($B28,'IS & BS Projections'!$B:$B,'IS & BS Projections'!AX:AX) -> -486555.27 | AX28: =_xlfn.XLOOKUP($B28,'IS & BS Projections'!$B:$B,'IS & BS Projections'!AY:AY) -> -836661.92 | AY28: =_xlfn.XLOOKUP($B28,'IS & BS Projections'!$B:$B,'IS & BS Projections'!AZ:AZ) -> -505304.89 | AZ28: =_xlfn.XLOOKUP($B28,'IS & BS Projections'!$B:$B,'IS & BS Projections'!BA:BA) -> -358602.17 | BA28: =_xlfn.XLOOKUP($B28,'IS & BS Projections'!$B:$B,'IS & BS Projections'!BB:BB) -> -603169.61 | BB28: =_xlfn.XLOOKUP($B28,'IS & BS Projections'!$B:$B,'IS & BS Projections'!BC:BC) -> -1031248.4 | BC28: =_xlfn.XLOOKUP($B28,'IS & BS Projections'!$B:$B,'IS & BS Projections'!BD:BD) -> -614357.29
B29: Other Operating (Expenses)/income | D29: USD '000s | E29: =SUMIF($P$1:$AI$1,E$1,$P29:$AI29) -> 0 | F29: =SUMIF($P$1:$AI$1,F$1,$P29:$AI29) -> 0 | G29: =SUMIF($P$1:$AI$1,G$1,$P29:$AI29) -> 34675 | H29: =SUMIF($P$1:$AI$1,H$1,$P29:$AI29) -> 0 | I29: =SUMIF($P$1:$AI$1,I$1,$P29:$AI29) -> 0 | J29: =SUMIFS($AJ29:$BC29,$AJ$1:$BC$1,J$1) -> 0 | K29: =SUMIFS($AJ29:$BC29,$AJ$1:$BC$1,K$1) -> 0 | L29: =SUMIFS($AJ29:$BC29,$AJ$1:$BC$1,L$1) -> 0 | M29: =SUMIFS($AJ29:$BC29,$AJ$1:$BC$1,M$1) -> 0 | N29: =SUMIFS($AJ29:$BC29,$AJ$1:$BC$1,N$1) -> 0 | P29: 0 | Q29: 0 | R29: 0 | S29: 0 | T29: 0 | U29: 0 | V29: 0 | W29: 0 | X29: -17962 | Y29: 8053 | Z29: -7180 | AA29: 51764 | AB29: 0 | AC29: 0 | AD29: 0 | AE29: 0 | AF29: 0 | AG29: 0 | AH29: 0 | AI29: 0 | AJ29: =_xlfn.XLOOKUP($B29,'IS & BS Projections'!$B:$B,'IS & BS Projections'!AK:AK) -> 0 | AK29: =_xlfn.XLOOKUP($B29,'IS & BS Projections'!$B:$B,'IS & BS Projections'!AL:AL) -> 0 | AL29: =_xlfn.XLOOKUP($B29,'IS & BS Projections'!$B:$B,'IS & BS Projections'!AM:AM) -> 0 | AM29: =_xlfn.XLOOKUP($B29,'IS & BS Projections'!$B:$B,'IS & BS Projections'!AN:AN) -> 0 | AN29: =_xlfn.XLOOKUP($B29,'IS & BS Projections'!$B:$B,'IS & BS Projections'!AO:AO) -> 0 | AO29: =_xlfn.XLOOKUP($B29,'IS & BS Projections'!$B:$B,'IS & BS Projections'!AP:AP) -> 0 | AP29: =_xlfn.XLOOKUP($B29,'IS & BS Projections'!$B:$B,'IS & BS Projections'!AQ:AQ) -> 0 | AQ29: =_xlfn.XLOOKUP($B29,'IS & BS Projections'!$B:$B,'IS & BS Projections'!AR:AR) -> 0 | AR29: =_xlfn.XLOOKUP($B29,'IS & BS Projections'!$B:$B,'IS & BS Projections'!AS:AS) -> 0 | AS29: =_xlfn.XLOOKUP($B29,'IS & BS Projections'!$B:$B,'IS & BS Projections'!AT:AT) -> 0 | AT29: =_xlfn.XLOOKUP($B29,'IS & BS Projections'!$B:$B,'IS & BS Projections'!AU:AU) -> 0 | AU29: =_xlfn.XLOOKUP($B29,'IS & BS Projections'!$B:$B,'IS & BS Projections'!AV:AV) -> 0 | AV29: =_xlfn.XLOOKUP($B29,'IS & BS Projections'!$B:$B,'IS & BS Projections'!AW:AW) -> 0 | AW29: =_xlfn.XLOOKUP($B29,'IS & BS Projections'!$B:$B,'IS & BS Projections'!AX:AX) -> 0 | AX29: =_xlfn.XLOOKUP($B29,'IS & BS Projections'!$B:$B,'IS & BS Projections'!AY:AY) -> 0 | AY29: =_xlfn.XLOOKUP($B29,'IS & BS Projections'!$B:$B,'IS & BS Projections'!AZ:AZ) -> 0 | AZ29: =_xlfn.XLOOKUP($B29,'IS & BS Projections'!$B:$B,'IS & BS Projections'!BA:BA) -> 0 | BA29: =_xlfn.XLOOKUP($B29,'IS & BS Projections'!$B:$B,'IS & BS Projections'!BB:BB) -> 0 | BB29: =_xlfn.XLOOKUP($B29,'IS & BS Projections'!$B:$B,'IS & BS Projections'!BC:BC) -> 0 | BC29: =_xlfn.XLOOKUP($B29,'IS & BS Projections'!$B:$B,'IS & BS Projections'!BD:BD) -> 0
B30: Other Operating Income/expense, Net | D30: USD '000s | E30: =SUMIF($P$1:$AI$1,E$1,$P30:$AI30) -> -630308 | F30: =SUMIF($P$1:$AI$1,F$1,$P30:$AI30) -> -717405 | G30: =SUMIF($P$1:$AI$1,G$1,$P30:$AI30) -> -10260 | H30: =SUMIF($P$1:$AI$1,H$1,$P30:$AI30) -> -28203 | I30: =SUMIF($P$1:$AI$1,I$1,$P30:$AI30) -> -363406 | J30: =SUMIFS($AJ30:$BC30,$AJ$1:$BC$1,J$1) -> -306627.45 | K30: =SUMIFS($AJ30:$BC30,$AJ$1:$BC$1,K$1) -> -349856.44 | L30: =SUMIFS($AJ30:$BC30,$AJ$1:$BC$1,L$1) -> -398624.15 | M30: =SUMIFS($AJ30:$BC30,$AJ$1:$BC$1,M$1) -> -472377.49 | N30: =SUMIFS($AJ30:$BC30,$AJ$1:$BC$1,N$1) -> -592293.71 | P30: -155887 | Q30: -282422 | R30: -118548 | S30: -73451 | T30: -258627 | U30: -422762 | V30: -62646 | W30: 26630 | X30: 33184 | Y30: -18866 | Z30: -3512 | AA30: -21066 | AB30: -2376 | AC30: -34383 | AD30: 8556 | AE30: 0 | AF30: 5899 | AG30: -308025 | AH30: -61280 | AI30: 0 | AJ30: =_xlfn.XLOOKUP($B30,'IS & BS Projections'!$B:$B,'IS & BS Projections'!AK:AK) -> -2703.8495 | AK30: =_xlfn.XLOOKUP($B30,'IS & BS Projections'!$B:$B,'IS & BS Projections'!AL:AL) -> -226078.7 | AL30: =_xlfn.XLOOKUP($B30,'IS & BS Projections'!$B:$B,'IS & BS Projections'!AM:AM) -> -77844.904 | AM30: =_xlfn.XLOOKUP($B30,'IS & BS Projections'!$B:$B,'IS & BS Projections'!AN:AN) -> 0 | AN30: =_xlfn.XLOOKUP($B30,'IS & BS Projections'!$B:$B,'IS & BS Projections'!AO:AO) -> -2821.6543 | AO30: =_xlfn.XLOOKUP($B30,'IS & BS Projections'!$B:$B,'IS & BS Projections'!AP:AP) -> -257205.39 | AP30: =_xlfn.XLOOKUP($B30,'IS & BS Projections'!$B:$B,'IS & BS Projections'!AQ:AQ) -> -89829.394 | AQ30: =_xlfn.XLOOKUP($B30,'IS & BS Projections'!$B:$B,'IS & BS Projections'!AR:AR) -> 0 | AR30: =_xlfn.XLOOKUP($B30,'IS & BS Projections'!$B:$B,'IS & BS Projections'!AS:AS) -> -3071.5494 | AS30: =_xlfn.XLOOKUP($B30,'IS & BS Projections'!$B:$B,'IS & BS Projections'!AT:AT) -> -294326.2 | AT30: =_xlfn.XLOOKUP($B30,'IS & BS Projections'!$B:$B,'IS & BS Projections'!AU:AU) -> -101226.39 | AU30: =_xlfn.XLOOKUP($B30,'IS & BS Projections'!$B:$B,'IS & BS Projections'!AV:AV) -> 0 | AV30: =_xlfn.XLOOKUP($B30,'IS & BS Projections'!$B:$B,'IS & BS Projections'!AW:AW) -> -3391.3709 | AW30: =_xlfn.XLOOKUP($B30,'IS & BS Projections'!$B:$B,'IS & BS Projections'!AX:AX) -> -350047.05 | AX30: =_xlfn.XLOOKUP($B30,'IS & BS Projections'!$B:$B,'IS & BS Projections'!AY:AY) -> -118939.06 | AY30: =_xlfn.XLOOKUP($B30,'IS & BS Projections'!$B:$B,'IS & BS Projections'!AZ:AZ) -> 0 | AZ30: =_xlfn.XLOOKUP($B30,'IS & BS Projections'!$B:$B,'IS & BS Projections'!BA:BA) -> -3896.4673 | BA30: =_xlfn.XLOOKUP($B30,'IS & BS Projections'!$B:$B,'IS & BS Projections'!BB:BB) -> -440189.74 | BB30: =_xlfn.XLOOKUP($B30,'IS & BS Projections'!$B:$B,'IS & BS Projections'!BC:BC) -> -148207.51 | BC30: =_xlfn.XLOOKUP($B30,'IS & BS Projections'!$B:$B,'IS & BS Projections'!BD:BD) -> 0
B31: Ther Operating Income and Expenses, Net | D31: USD '000s | E31: =SUMIF($P$1:$AI$1,E$1,$P31:$AI31) -> 0 | F31: =SUMIF($P$1:$AI$1,F$1,$P31:$AI31) -> 0 | G31: =SUMIF($P$1:$AI$1,G$1,$P31:$AI31) -> 0 | H31: =SUMIF($P$1:$AI$1,H$1,$P31:$AI31) -> 20270 | I31: =SUMIF($P$1:$AI$1,I$1,$P31:$AI31) -> 7280 | J31: =SUMIFS($AJ31:$BC31,$AJ$1:$BC$1,J$1) -> 0 | K31: =SUMIFS($AJ31:$BC31,$AJ$1:$BC$1,K$1) -> 0 | L31: =SUMIFS($AJ31:$BC31,$AJ$1:$BC$1,L$1) -> 0 | M31: =SUMIFS($AJ31:$BC31,$AJ$1:$BC$1,M$1) -> 0 | N31: =SUMIFS($AJ31:$BC31,$AJ$1:$BC$1,N$1) -> 0 | P31: 0 | Q31: 0 | R31: 0 | S31: 0 | T31: 0 | U31: 0 | V31: 0 | W31: 0 | X31: 0 | Y31: 0 | Z31: 0 | AA31: 0 | AB31: 0 | AC31: 0 | AD31: 0 | AE31: 20270 | AF31: 0 | AG31: 0 | AH31: 0 | AI31: 7280 | AJ31: =_xlfn.XLOOKUP($B31,'IS & BS Projections'!$B:$B,'IS & BS Projections'!AK:AK) -> 0 | AK31: =_xlfn.XLOOKUP($B31,'IS & BS Projections'!$B:$B,'IS & BS Projections'!AL:AL) -> 0 | AL31: =_xlfn.XLOOKUP($B31,'IS & BS Projections'!$B:$B,'IS & BS Projections'!AM:AM) -> 0 | AM31: =_xlfn.XLOOKUP($B31,'IS & BS Projections'!$B:$B,'IS & BS Projections'!AN:AN) -> 0 | AN31: =_xlfn.XLOOKUP($B31,'IS & BS Projections'!$B:$B,'IS & BS Projections'!AO:AO) -> 0 | AO31: =_xlfn.XLOOKUP($B31,'IS & BS Projections'!$B:$B,'IS & BS Projections'!AP:AP) -> 0 | AP31: =_xlfn.XLOOKUP($B31,'IS & BS Projections'!$B:$B,'IS & BS Projections'!AQ:AQ) -> 0 | AQ31: =_xlfn.XLOOKUP($B31,'IS & BS Projections'!$B:$B,'IS & BS Projections'!AR:AR) -> 0 | AR31: =_xlfn.XLOOKUP($B31,'IS & BS Projections'!$B:$B,'IS & BS Projections'!AS:AS) -> 0 | AS31: =_xlfn.XLOOKUP($B31,'IS & BS Projections'!$B:$B,'IS & BS Projections'!AT:AT) -> 0 | AT31: =_xlfn.XLOOKUP($B31,'IS & BS Projections'!$B:$B,'IS & BS Projections'!AU:AU) -> 0 | AU31: =_xlfn.XLOOKUP($B31,'IS & BS Projections'!$B:$B,'IS & BS Projections'!AV:AV) -> 0 | AV31: =_xlfn.XLOOKUP($B31,'IS & BS Projections'!$B:$B,'IS & BS Projections'!AW:AW) -> 0 | AW31: =_xlfn.XLOOKUP($B31,'IS & BS Projections'!$B:$B,'IS & BS Projections'!AX:AX) -> 0 | AX31: =_xlfn.XLOOKUP($B31,'IS & BS Projections'!$B:$B,'IS & BS Projections'!AY:AY) -> 0 | AY31: =_xlfn.XLOOKUP($B31,'IS & BS Projections'!$B:$B,'IS & BS Projections'!AZ:AZ) -> 0 | AZ31: =_xlfn.XLOOKUP($B31,'IS & BS Projections'!$B:$B,'IS & BS Projections'!BA:BA) -> 0 | BA31: =_xlfn.XLOOKUP($B31,'IS & BS Projections'!$B:$B,'IS & BS Projections'!BB:BB) -> 0 | BB31: =_xlfn.XLOOKUP($B31,'IS & BS Projections'!$B:$B,'IS & BS Projections'!BC:BC) -> 0 | BC31: =_xlfn.XLOOKUP($B31,'IS & BS Projections'!$B:$B,'IS & BS Projections'!BD:BD) -> 0
B32: Total OPEX | D32: USD '000s | E32: =SUM(E25:E31) -> -4762875 | F32: =SUM(F25:F31) -> -5784314 | G32: =SUM(G25:G31) -> -3001892 | H32: =SUM(H25:H31) -> -4328593 | I32: =SUM(I25:I31) -> -5725180 | J32: =SUM(J25:J31) -> -5573204.9 | K32: =SUM(K25:K31) -> -6235730.4 | L32: =SUM(L25:L31) -> -6970927.8 | ... N32: =SUM(N25:N31) -> -9906571.7 | P32: =SUM(P25:P31) -> -813399 | Q32: =SUM(Q25:Q31) -> -1353237 | R32: =SUM(R25:R31) -> -1020100 | S32: =SUM(S25:S31) -> -1576139 | T32: =SUM(T25:T31) -> -1720899 | U32: =SUM(U25:U31) -> -1810261 | V32: =SUM(V25:V31) -> -1135905 | W32: =SUM(W25:W31) -> -1117249 | ... BC32: =SUM(BC25:BC31) -> -2144658.7
B34: Asset Write-downs | D34: USD '000s | E34: =SUMIF($P$1:$AI$1,E$1,$P34:$AI34) -> 0 | F34: =SUMIF($P$1:$AI$1,F$1,$P34:$AI34) -> -79399 | G34: =SUMIF($P$1:$AI$1,G$1,$P34:$AI34) -> 0 | H34: =SUMIF($P$1:$AI$1,H$1,$P34:$AI34) -> 0 | I34: =SUMIF($P$1:$AI$1,I$1,$P34:$AI34) -> 0 | J34: =SUMIFS($AJ34:$BC34,$AJ$1:$BC$1,J$1) -> 0 | K34: =SUMIFS($AJ34:$BC34,$AJ$1:$BC$1,K$1) -> 0 | L34: =SUMIFS($AJ34:$BC34,$AJ$1:$BC$1,L$1) -> 0 | M34: =SUMIFS($AJ34:$BC34,$AJ$1:$BC$1,M$1) -> 0 | N34: =SUMIFS($AJ34:$BC34,$AJ$1:$BC$1,N$1) -> 0 | P34: 0 | Q34: 0 | R34: 0 | S34: 0 | T34: 0 | U34: 0 | V34: -12150 | W34: -67249 | X34: 0 | Y34: 0 | Z34: 0 | AA34: 0 | AB34: 0 | AC34: 0 | AD34: 0 | AE34: 0 | AF34: 0 | AG34: 0 | AH34: 0 | AI34: 0 | AJ34: =_xlfn.XLOOKUP($B34,'IS & BS Projections'!$B:$B,'IS & BS Projections'!AK:AK) -> 0 | AK34: =_xlfn.XLOOKUP($B34,'IS & BS Projections'!$B:$B,'IS & BS Projections'!AL:AL) -> 0 | AL34: =_xlfn.XLOOKUP($B34,'IS & BS Projections'!$B:$B,'IS & BS Projections'!AM:AM) -> 0 | AM34: =_xlfn.XLOOKUP($B34,'IS & BS Projections'!$B:$B,'IS & BS Projections'!AN:AN) -> 0 | AN34: =_xlfn.XLOOKUP($B34,'IS & BS Projections'!$B:$B,'IS & BS Projections'!AO:AO) -> 0 | AO34: =_xlfn.XLOOKUP($B34,'IS & BS Projections'!$B:$B,'IS & BS Projections'!AP:AP) -> 0 | AP34: =_xlfn.XLOOKUP($B34,'IS & BS Projections'!$B:$B,'IS & BS Projections'!AQ:AQ) -> 0 | AQ34: =_xlfn.XLOOKUP($B34,'IS & BS Projections'!$B:$B,'IS & BS Projections'!AR:AR) -> 0 | AR34: =_xlfn.XLOOKUP($B34,'IS & BS Projections'!$B:$B,'IS & BS Projections'!AS:AS) -> 0 | AS34: =_xlfn.XLOOKUP($B34,'IS & BS Projections'!$B:$B,'IS & BS Projections'!AT:AT) -> 0 | AT34: =_xlfn.XLOOKUP($B34,'IS & BS Projections'!$B:$B,'IS & BS Projections'!AU:AU) -> 0 | AU34: =_xlfn.XLOOKUP($B34,'IS & BS Projections'!$B:$B,'IS & BS Projections'!AV:AV) -> 0 | AV34: =_xlfn.XLOOKUP($B34,'IS & BS Projections'!$B:$B,'IS & BS Projections'!AW:AW) -> 0 | AW34: =_xlfn.XLOOKUP($B34,'IS & BS Projections'!$B:$B,'IS & BS Projections'!AX:AX) -> 0 | AX34: =_xlfn.XLOOKUP($B34,'IS & BS Projections'!$B:$B,'IS & BS Projections'!AY:AY) -> 0 | AY34: =_xlfn.XLOOKUP($B34,'IS & BS Projections'!$B:$B,'IS & BS Projections'!AZ:AZ) -> 0 | AZ34: =_xlfn.XLOOKUP($B34,'IS & BS Projections'!$B:$B,'IS & BS Projections'!BA:BA) -> 0 | BA34: =_xlfn.XLOOKUP($B34,'IS & BS Projections'!$B:$B,'IS & BS Projections'!BB:BB) -> 0 | BB34: =_xlfn.XLOOKUP($B34,'IS & BS Projections'!$B:$B,'IS & BS Projections'!BC:BC) -> 0 | BC34: =_xlfn.XLOOKUP($B34,'IS & BS Projections'!$B:$B,'IS & BS Projections'!BD:BD) -> 0
B35: Restructurings | D35: USD '000s | E35: =SUMIF($P$1:$AI$1,E$1,$P35:$AI35) -> 0 | F35: =SUMIF($P$1:$AI$1,F$1,$P35:$AI35) -> -40703 | G35: =SUMIF($P$1:$AI$1,G$1,$P35:$AI35) -> -142594 | H35: =SUMIF($P$1:$AI$1,H$1,$P35:$AI35) -> 0 | I35: =SUMIF($P$1:$AI$1,I$1,$P35:$AI35) -> 0 | J35: =SUMIFS($AJ35:$BC35,$AJ$1:$BC$1,J$1) -> 0 | K35: =SUMIFS($AJ35:$BC35,$AJ$1:$BC$1,K$1) -> 0 | L35: =SUMIFS($AJ35:$BC35,$AJ$1:$BC$1,L$1) -> 0 | M35: =SUMIFS($AJ35:$BC35,$AJ$1:$BC$1,M$1) -> 0 | N35: =SUMIFS($AJ35:$BC35,$AJ$1:$BC$1,N$1) -> 0 | P35: 0 | Q35: 0 | R35: 0 | S35: 0 | T35: 0 | U35: -42453 | V35: 1232 | W35: 518 | X35: -144489 | Y35: 1035 | Z35: 860 | AA35: 0 | AB35: 0 | AC35: 0 | AD35: 0 | AE35: 0 | AF35: 0 | AG35: 0 | AH35: 0 | AI35: 0 | AJ35: =_xlfn.XLOOKUP($B35,'IS & BS Projections'!$B:$B,'IS & BS Projections'!AK:AK) -> 0 | AK35: =_xlfn.XLOOKUP($B35,'IS & BS Projections'!$B:$B,'IS & BS Projections'!AL:AL) -> 0 | AL35: =_xlfn.XLOOKUP($B35,'IS & BS Projections'!$B:$B,'IS & BS Projections'!AM:AM) -> 0 | AM35: =_xlfn.XLOOKUP($B35,'IS & BS Projections'!$B:$B,'IS & BS Projections'!AN:AN) -> 0 | AN35: =_xlfn.XLOOKUP($B35,'IS & BS Projections'!$B:$B,'IS & BS Projections'!AO:AO) -> 0 | AO35: =_xlfn.XLOOKUP($B35,'IS & BS Projections'!$B:$B,'IS & BS Projections'!AP:AP) -> 0 | AP35: =_xlfn.XLOOKUP($B35,'IS & BS Projections'!$B:$B,'IS & BS Projections'!AQ:AQ) -> 0 | AQ35: =_xlfn.XLOOKUP($B35,'IS & BS Projections'!$B:$B,'IS & BS Projections'!AR:AR) -> 0 | AR35: =_xlfn.XLOOKUP($B35,'IS & BS Projections'!$B:$B,'IS & BS Projections'!AS:AS) -> 0 | AS35: =_xlfn.XLOOKUP($B35,'IS & BS Projections'!$B:$B,'IS & BS Projections'!AT:AT) -> 0 | AT35: =_xlfn.XLOOKUP($B35,'IS & BS Projections'!$B:$B,'IS & BS Projections'!AU:AU) -> 0 | AU35: =_xlfn.XLOOKUP($B35,'IS & BS Projections'!$B:$B,'IS & BS Projections'!AV:AV) -> 0 | AV35: =_xlfn.XLOOKUP($B35,'IS & BS Projections'!$B:$B,'IS & BS Projections'!AW:AW) -> 0 | AW35: =_xlfn.XLOOKUP($B35,'IS & BS Projections'!$B:$B,'IS & BS Projections'!AX:AX) -> 0 | AX35: =_xlfn.XLOOKUP($B35,'IS & BS Projections'!$B:$B,'IS & BS Projections'!AY:AY) -> 0 | AY35: =_xlfn.XLOOKUP($B35,'IS & BS Projections'!$B:$B,'IS & BS Projections'!AZ:AZ) -> 0 | AZ35: =_xlfn.XLOOKUP($B35,'IS & BS Projections'!$B:$B,'IS & BS Projections'!BA:BA) -> 0 | BA35: =_xlfn.XLOOKUP($B35,'IS & BS Projections'!$B:$B,'IS & BS Projections'!BB:BB) -> 0 | BB35: =_xlfn.XLOOKUP($B35,'IS & BS Projections'!$B:$B,'IS & BS Projections'!BC:BC) -> 0 | BC35: =_xlfn.XLOOKUP($B35,'IS & BS Projections'!$B:$B,'IS & BS Projections'!BD:BD) -> 0
B36: Interest Expense | D36: USD '000s | E36: =SUMIF($P$1:$AI$1,E$1,$P36:$AI36) -> -29160 | F36: =SUMIF($P$1:$AI$1,F$1,$P36:$AI36) -> -88901 | G36: =SUMIF($P$1:$AI$1,G$1,$P36:$AI36) -> -82766 | H36: =SUMIF($P$1:$AI$1,H$1,$P36:$AI36) -> -80645 | I36: =SUMIF($P$1:$AI$1,I$1,$P36:$AI36) -> -85413 | J36: =SUMIFS($AJ36:$BC36,$AJ$1:$BC$1,J$1) -> -84947.393 | K36: =SUMIFS($AJ36:$BC36,$AJ$1:$BC$1,K$1) -> -78709.629 | L36: =SUMIFS($AJ36:$BC36,$AJ$1:$BC$1,L$1) -> -78709.629 | M36: =SUMIFS($AJ36:$BC36,$AJ$1:$BC$1,M$1) -> -43009.629 | N36: =SUMIFS($AJ36:$BC36,$AJ$1:$BC$1,N$1) -> -34280.879 | P36: 0 | Q36: -748 | R36: -6972 | S36: -21440 | T36: -22138 | U36: -23656 | V36: -21507 | W36: -21600 | X36: -21536 | Y36: -21672 | Z36: -20821 | AA36: -18737 | AB36: -19071 | AC36: -20507 | AD36: -20530 | AE36: -20537 | AF36: -20511 | AG36: -20535 | AH36: -21774 | AI36: -22593 | AJ36: ='D&E Schedule'!AC109 -> -22796.289 | AK36: ='D&E Schedule'!AD109 -> -22796.289 | AL36: ='D&E Schedule'!AE109 -> -19677.407 | AM36: ='D&E Schedule'!AF109 -> -19677.407 | AN36: ='D&E Schedule'!AG109 -> -19677.407 | AO36: ='D&E Schedule'!AH109 -> -19677.407 | AP36: ='D&E Schedule'!AI109 -> -19677.407 | AQ36: ='D&E Schedule'!AJ109 -> -19677.407 | ... BC36: ='D&E Schedule'!AV109 -> -7700.5322
B37: Other Income/expense-net | D37: USD '000s | E37: =SUMIF($P$1:$AI$1,E$1,$P37:$AI37) -> -20463 | F37: =SUMIF($P$1:$AI$1,F$1,$P37:$AI37) -> -265473 | G37: =SUMIF($P$1:$AI$1,G$1,$P37:$AI37) -> 167583 | H37: =SUMIF($P$1:$AI$1,H$1,$P37:$AI37) -> 29074 | I37: =SUMIF($P$1:$AI$1,I$1,$P37:$AI37) -> 700894 | J37: =SUMIFS($AJ37:$BC37,$AJ$1:$BC$1,J$1) -> -29529.68 | K37: =SUMIFS($AJ37:$BC37,$AJ$1:$BC$1,K$1) -> -33519.545 | L37: =SUMIFS($AJ37:$BC37,$AJ$1:$BC$1,L$1) -> -37673.1 | M37: =SUMIFS($AJ37:$BC37,$AJ$1:$BC$1,M$1) -> -43933.772 | N37: =SUMIFS($AJ37:$BC37,$AJ$1:$BC$1,N$1) -> -54245.35 | P37: 8953 | Q37: -5096 | R37: -13976 | S37: -10344 | T37: -32844 | U37: -172524 | V37: -65699 | W37: 5594 | X37: -20265 | Y37: 16564 | Z37: 135307 | AA37: 35977 | AB37: 45605 | AC37: -63827 | AD37: 40105 | AE37: 7191 | AF37: -6188 | AG37: 1506905 | AH37: -380518 | AI37: -419305 | AJ37: =_xlfn.XLOOKUP($B37,'IS & BS Projections'!$B:$B,'IS & BS Projections'!AK:AK) -> -5668.5546 | AK37: =_xlfn.XLOOKUP($B37,'IS & BS Projections'!$B:$B,'IS & BS Projections'!AL:AL) -> -4079.346 | AL37: =_xlfn.XLOOKUP($B37,'IS & BS Projections'!$B:$B,'IS & BS Projections'!AM:AM) -> -25288.839 | AM37: =_xlfn.XLOOKUP($B37,'IS & BS Projections'!$B:$B,'IS & BS Projections'!AN:AN) -> 5507.0597 | AN37: =_xlfn.XLOOKUP($B37,'IS & BS Projections'!$B:$B,'IS & BS Projections'!AO:AO) -> -5915.5295 | AO37: =_xlfn.XLOOKUP($B37,'IS & BS Projections'!$B:$B,'IS & BS Projections'!AP:AP) -> -4640.9935 | AP37: =_xlfn.XLOOKUP($B37,'IS & BS Projections'!$B:$B,'IS & BS Projections'!AQ:AQ) -> -29182.143 | AQ37: =_xlfn.XLOOKUP($B37,'IS & BS Projections'!$B:$B,'IS & BS Projections'!AR:AR) -> 6219.1209 | AR37: =_xlfn.XLOOKUP($B37,'IS & BS Projections'!$B:$B,'IS & BS Projections'!AS:AS) -> -6439.4284 | AS37: =_xlfn.XLOOKUP($B37,'IS & BS Projections'!$B:$B,'IS & BS Projections'!AT:AT) -> -5310.7985 | AT37: =_xlfn.XLOOKUP($B37,'IS & BS Projections'!$B:$B,'IS & BS Projections'!AU:AU) -> -32884.594 | AU37: =_xlfn.XLOOKUP($B37,'IS & BS Projections'!$B:$B,'IS & BS Projections'!AV:AV) -> 6961.7209 | AV37: =_xlfn.XLOOKUP($B37,'IS & BS Projections'!$B:$B,'IS & BS Projections'!AW:AW) -> -7109.9263 | AW37: =_xlfn.XLOOKUP($B37,'IS & BS Projections'!$B:$B,'IS & BS Projections'!AX:AX) -> -6316.221 | AX37: =_xlfn.XLOOKUP($B37,'IS & BS Projections'!$B:$B,'IS & BS Projections'!AY:AY) -> -38638.765 | AY37: =_xlfn.XLOOKUP($B37,'IS & BS Projections'!$B:$B,'IS & BS Projections'!AZ:AZ) -> 8131.1396 | AZ37: =_xlfn.XLOOKUP($B37,'IS & BS Projections'!$B:$B,'IS & BS Projections'!BA:BA) -> -8168.8486 | BA37: =_xlfn.XLOOKUP($B37,'IS & BS Projections'!$B:$B,'IS & BS Projections'!BB:BB) -> -7942.7484 | BB37: =_xlfn.XLOOKUP($B37,'IS & BS Projections'!$B:$B,'IS & BS Projections'!BC:BC) -> -48146.966 | BC37: =_xlfn.XLOOKUP($B37,'IS & BS Projections'!$B:$B,'IS & BS Projections'!BD:BD) -> 10013.213
B38: Gain/Loss on Crypto assets held for investment, net | D38: USD '000s | E38: =SUMIF($P$1:$AI$1,E$1,$P38:$AI38) -> 0 | F38: =SUMIF($P$1:$AI$1,F$1,$P38:$AI38) -> 0 | G38: =SUMIF($P$1:$AI$1,G$1,$P38:$AI38) -> 0 | H38: =SUMIF($P$1:$AI$1,H$1,$P38:$AI38) -> 687055 | I38: =SUMIF($P$1:$AI$1,I$1,$P38:$AI38) -> -528857 | J38: =SUMIFS($AJ38:$BC38,$AJ$1:$BC$1,J$1) -> 0 | K38: =SUMIFS($AJ38:$BC38,$AJ$1:$BC$1,K$1) -> 0 | L38: =SUMIFS($AJ38:$BC38,$AJ$1:$BC$1,L$1) -> 0 | M38: =SUMIFS($AJ38:$BC38,$AJ$1:$BC$1,M$1) -> 0 | N38: =SUMIFS($AJ38:$BC38,$AJ$1:$BC$1,N$1) -> 0 | P38: 0 | Q38: 0 | R38: 0 | S38: 0 | T38: 0 | U38: 0 | V38: 0 | W38: 0 | X38: 0 | Y38: 0 | Z38: 0 | AA38: 0 | AB38: 650429 | AC38: -319020 | AD38: -120507 | AE38: 476153 | AF38: -596651 | AG38: 362053 | AH38: 423903 | AI38: -718162 | AJ38: =_xlfn.XLOOKUP($B38,'IS & BS Projections'!$B:$B,'IS & BS Projections'!AK:AK) -> 0 | AK38: =_xlfn.XLOOKUP($B38,'IS & BS Projections'!$B:$B,'IS & BS Projections'!AL:AL) -> 0 | AL38: =_xlfn.XLOOKUP($B38,'IS & BS Projections'!$B:$B,'IS & BS Projections'!AM:AM) -> 0 | AM38: =_xlfn.XLOOKUP($B38,'IS & BS Projections'!$B:$B,'IS & BS Projections'!AN:AN) -> 0 | AN38: =_xlfn.XLOOKUP($B38,'IS & BS Projections'!$B:$B,'IS & BS Projections'!AO:AO) -> 0 | AO38: =_xlfn.XLOOKUP($B38,'IS & BS Projections'!$B:$B,'IS & BS Projections'!AP:AP) -> 0 | AP38: =_xlfn.XLOOKUP($B38,'IS & BS Projections'!$B:$B,'IS & BS Projections'!AQ:AQ) -> 0 | AQ38: =_xlfn.XLOOKUP($B38,'IS & BS Projections'!$B:$B,'IS & BS Projections'!AR:AR) -> 0 | AR38: =_xlfn.XLOOKUP($B38,'IS & BS Projections'!$B:$B,'IS & BS Projections'!AS:AS) -> 0 | AS38: =_xlfn.XLOOKUP($B38,'IS & BS Projections'!$B:$B,'IS & BS Projections'!AT:AT) -> 0 | AT38: =_xlfn.XLOOKUP($B38,'IS & BS Projections'!$B:$B,'IS & BS Projections'!AU:AU) -> 0 | AU38: =_xlfn.XLOOKUP($B38,'IS & BS Projections'!$B:$B,'IS & BS Projections'!AV:AV) -> 0 | AV38: =_xlfn.XLOOKUP($B38,'IS & BS Projections'!$B:$B,'IS & BS Projections'!AW:AW) -> 0 | AW38: =_xlfn.XLOOKUP($B38,'IS & BS Projections'!$B:$B,'IS & BS Projections'!AX:AX) -> 0 | AX38: =_xlfn.XLOOKUP($B38,'IS & BS Projections'!$B:$B,'IS & BS Projections'!AY:AY) -> 0 | AY38: =_xlfn.XLOOKUP($B38,'IS & BS Projections'!$B:$B,'IS & BS Projections'!AZ:AZ) -> 0 | AZ38: =_xlfn.XLOOKUP($B38,'IS & BS Projections'!$B:$B,'IS & BS Projections'!BA:BA) -> 0 | BA38: =_xlfn.XLOOKUP($B38,'IS & BS Projections'!$B:$B,'IS & BS Projections'!BB:BB) -> 0 | BB38: =_xlfn.XLOOKUP($B38,'IS & BS Projections'!$B:$B,'IS & BS Projections'!BC:BC) -> 0 | BC38: =_xlfn.XLOOKUP($B38,'IS & BS Projections'!$B:$B,'IS & BS Projections'!BD:BD) -> 0
B40: Earnings Before Taxes (EBT) | D40: USD '000s | E40: =SUM(E32,E34:E38,E22) -> 3026947 | F40: =SUM(F32,F34:F38,F22) -> -3064582 | G40: =SUM(G32,G34:G38,G22) -> -76845 | H40: =SUM(H32,H34:H38,H22) -> 2870919 | I40: =SUM(I32,I34:I38,I22) -> 1542769 | J40: =SUM(J32,J34:J38,J22) -> 2072837.9 | K40: =SUM(K32,K34:K38,K22) -> 2329703.4 | L40: =SUM(L32,L34:L38,L22) -> 2637552.3 | ... N40: =SUM(N32,N34:N38,N22) -> 3845617.1 | P40: =SUM(P32,P34:P38,P22) -> 996666 | Q40: =SUM(Q32,Q34:Q38,Q22) -> 868881 | R40: =SUM(R32,R34:R38,R22) -> 270860 | S40: =SUM(S32,S34:S38,S22) -> 890540 | T40: =SUM(T32,T34:T38,T22) -> -609445 | U40: =SUM(U32,U34:U38,U22) -> -1240569 | V40: =SUM(V32,V34:V38,V22) -> -643690 | W40: =SUM(W32,W34:W38,W22) -> -570878 | ... BC40: =SUM(BC32,BC34:BC38,BC22) -> 1020828.1
B41: EBT Margin | D41: % | E41: =E40/E$22 -> 0.38611751 | F41: =F40/F$22 -> -0.95941842 | G41: =G40/G$22 -> -0.025762499 | H41: =H40/H$22 -> 0.43737153 | I41: =I40/I$22 -> 0.21483069 | J41: =J40/J$22 -> 0.26710039 | K41: =K40/K$22 -> 0.26847129 | L41: =L40/L$22 -> 0.27121743 | ... N41: =N40/N$22 -> 0.27784815 | P41: =P40/P$22 -> 0.55336148 | Q41: =Q40/Q$22 -> 0.38998915 | R41: =R40/R$22 -> 0.20646265 | S41: =S40/S$22 -> 0.35643514 | T41: =T40/T$22 -> -0.52248473 | U41: =U40/U$22 -> -1.5347404 | V41: =V40/V$22 -> -1.0903735 | W41: =W40/W$22 -> -0.90744038 | ... BC41: =BC40/BC$22 -> 0.32272271
B43: Earnings Before Interest & Taxes (EBIT) | D43: USD '000s | E43: =E40-E36 -> 3056107 | F43: =F40-F36 -> -2975681 | G43: =G40-G36 -> 5921 | H43: =H40-H36 -> 2951564 | I43: =I40-I36 -> 1628182 | J43: =J40-J36 -> 2157785.3 | K43: =K40-K36 -> 2408413 | L43: =L40-L36 -> 2716261.9 | ... N43: =N40-N36 -> 3879897.9 | P43: =SUM(P35,P37:P41,P25) -> 771553.55 | Q43: =SUM(Q35,Q37:Q41,Q25) -> 528359.39 | R43: =SUM(R35,R37:R41,R25) -> 59633.206 | S43: =SUM(S35,S37:S41,S25) -> 379015.36 | T43: =SUM(T35,T37:T41,T25) -> -920115.52 | U43: =SUM(U35,U37:U41,U25) -> -1622734.5 | V43: =SUM(V35,V37:V41,V25) -> -810034.09 | W43: =SUM(W35,W37:W41,W25) -> -647757.91 | ... BC43: =SUM(BC35,BC37:BC41,BC25) -> 613560.38
B44: EBIT Margin | D44: % | E44: =E43/E$22 -> 0.38983716 | F44: =F43/F$22 -> -0.93158648 | G44: =G43/G$22 -> 0.0019850316 | H44: =H43/H$22 -> 0.44965744 | I44: =I43/I$22 -> 0.22672446 | J44: =J43/J$22 -> 0.27804649 | K44: =K43/K$22 -> 0.27754166 | L44: =L43/L$22 -> 0.27931108 | ... N44: =N43/N$22 -> 0.28032496 | P44: =P43/P$22 -> 0.42837622 | Q44: =Q43/Q$22 -> 0.23714919 | R44: =R43/R$22 -> 0.045455326 | S44: =S43/S$22 -> 0.15169941 | T44: =T43/T$22 -> -0.78882641 | U44: =U43/U$22 -> -2.0075273 | V44: =V43/V$22 -> -1.3721507 | W44: =W43/W$22 -> -1.029645 | ... BC44: =BC43/BC$22 -> 0.19396984
B46: Earnings Before Interest, Taxes, Depreciation & Amortization (EBITDA) | D46: USD '000s | E46: =E43+SUM(E142:E143) -> 3119758 | F46: =F43+SUM(F142:F143) -> -2821612 | G46: =G43+SUM(G142:G143) -> 145563 | H46: =H43+SUM(H142:H143) -> 3079082 | I46: =I43+SUM(I142:I143) -> 1816610 | J46: =J43+SUM(J142:J143) -> 2422168.6 | K46: =K43+SUM(K142:K143) -> 2709341.9 | L46: =L43+SUM(L142:L143) -> 3058146.7 | ... N46: =N43+SUM(N142:N143) -> 4327638.2 | P46: =P43+SUM(P142:P143) -> 782475.55 | Q46: =Q43+SUM(Q142:Q143) -> 540971.39 | R46: =R43+SUM(R142:R143) -> 76732.206 | S46: =S43+SUM(S142:S143) -> 402033.36 | T46: =T43+SUM(T142:T143) -> -888535.52 | U46: =U43+SUM(U142:U143) -> -1580707.5 | V46: =V43+SUM(V142:V143) -> -769920.09 | W46: =W43+SUM(W142:W143) -> -607409.91 | ... BC46: =BC43+SUM(BC142:BC143) -> 725495.46
B47: EBITDA Margin | D47: % | E47: =E46/E$22 -> 0.39795649 | F47: =F46/F$22 -> -0.88335262 | G47: =G46/G$22 -> 0.048800399 | H47: =H46/H$22 -> 0.46908423 | I47: =I46/I$22 -> 0.25296307 | J47: =J46/J$22 -> 0.31211421 | K47: =K46/K$22 -> 0.31222023 | L47: =L46/L$22 -> 0.31446682 | ... N47: =N46/N$22 -> 0.31267447 | P47: =P46/P$22 -> 0.43444025 | Q47: =Q46/Q$22 -> 0.24280997 | R47: =R46/R$22 -> 0.058489015 | S47: =S46/S$22 -> 0.16091227 | T47: =T46/T$22 -> -0.76175249 | U47: =U46/U$22 -> -1.9555346 | V47: =V46/V$22 -> -1.3041999 | W47: =W46/W$22 -> -0.96550975 | ... BC47: =BC46/BC$22 -> 0.22935679
B49: Provision For Income Tax | D49: USD '000s | E49: =SUMIF($P$1:$AI$1,E$1,$P49:$AI49) -> 597173 | F49: =SUMIF($P$1:$AI$1,F$1,$P49:$AI49) -> 439633 | G49: =SUMIF($P$1:$AI$1,G$1,$P49:$AI49) -> 171716 | H49: =SUMIF($P$1:$AI$1,H$1,$P49:$AI49) -> -363578 | I49: =SUMIF($P$1:$AI$1,I$1,$P49:$AI49) -> -261738 | J49: =SUMIFS($AJ49:$BC49,$AJ$1:$BC$1,J$1) -> 155144.09 | K49: =SUMIFS($AJ49:$BC49,$AJ$1:$BC$1,K$1) -> 177856.93 | L49: =SUMIFS($AJ49:$BC49,$AJ$1:$BC$1,L$1) -> 203069.91 | M49: =SUMIFS($AJ49:$BC49,$AJ$1:$BC$1,M$1) -> 241719.07 | N49: =SUMIFS($AJ49:$BC49,$AJ$1:$BC$1,N$1) -> 304353.49 | P49: -225203 | Q49: 737468 | R49: 135240 | S49: -50332 | T49: 179786 | U49: 146915 | V49: 99055 | W49: 13877 | X49: 86780 | Y49: -18722 | Z49: -36926 | AA49: 140584 | AB49: -261179 | AC49: 96387 | AD49: 6914 | AE49: -205700 | AF49: -16848 | AG49: -394873 | AH49: -69591 | AI49: 219574 | AJ49: =_xlfn.XLOOKUP($B49,'IS & BS Projections'!$B:$B,'IS & BS Projections'!AK:AK) -> -15433.712 | AK49: =_xlfn.XLOOKUP($B49,'IS & BS Projections'!$B:$B,'IS & BS Projections'!AL:AL) -> 118585.28 | AL49: =_xlfn.XLOOKUP($B49,'IS & BS Projections'!$B:$B,'IS & BS Projections'!AM:AM) -> 13618.277 | AM49: =_xlfn.XLOOKUP($B49,'IS & BS Projections'!$B:$B,'IS & BS Projections'!AN:AN) -> 38374.242 | AN49: =_xlfn.XLOOKUP($B49,'IS & BS Projections'!$B:$B,'IS & BS Projections'!AO:AO) -> -16106.147 | AO49: =_xlfn.XLOOKUP($B49,'IS & BS Projections'!$B:$B,'IS & BS Projections'!AP:AP) -> 134912.2 | AP49: =_xlfn.XLOOKUP($B49,'IS & BS Projections'!$B:$B,'IS & BS Projections'!AQ:AQ) -> 15714.858 | AQ49: =_xlfn.XLOOKUP($B49,'IS & BS Projections'!$B:$B,'IS & BS Projections'!AR:AR) -> 43336.02 | AR49: =_xlfn.XLOOKUP($B49,'IS & BS Projections'!$B:$B,'IS & BS Projections'!AS:AS) -> -17532.561 | AS49: =_xlfn.XLOOKUP($B49,'IS & BS Projections'!$B:$B,'IS & BS Projections'!AT:AT) -> 154383.21 | AT49: =_xlfn.XLOOKUP($B49,'IS & BS Projections'!$B:$B,'IS & BS Projections'!AU:AU) -> 17708.662 | AU49: =_xlfn.XLOOKUP($B49,'IS & BS Projections'!$B:$B,'IS & BS Projections'!AV:AV) -> 48510.599 | AV49: =_xlfn.XLOOKUP($B49,'IS & BS Projections'!$B:$B,'IS & BS Projections'!AW:AW) -> -19358.119 | AW49: =_xlfn.XLOOKUP($B49,'IS & BS Projections'!$B:$B,'IS & BS Projections'!AX:AX) -> 183610.53 | AX49: =_xlfn.XLOOKUP($B49,'IS & BS Projections'!$B:$B,'IS & BS Projections'!AY:AY) -> 20807.337 | AY49: =_xlfn.XLOOKUP($B49,'IS & BS Projections'!$B:$B,'IS & BS Projections'!AZ:AZ) -> 56659.331 | AZ49: =_xlfn.XLOOKUP($B49,'IS & BS Projections'!$B:$B,'IS & BS Projections'!BA:BA) -> -22241.235 | BA49: =_xlfn.XLOOKUP($B49,'IS & BS Projections'!$B:$B,'IS & BS Projections'!BB:BB) -> 230893.16 | BB49: =_xlfn.XLOOKUP($B49,'IS & BS Projections'!$B:$B,'IS & BS Projections'!BC:BC) -> 25927.592 | BC49: =_xlfn.XLOOKUP($B49,'IS & BS Projections'!$B:$B,'IS & BS Projections'!BD:BD) -> 69773.978
B51: Net Income | D51: USD '000s | E51: =SUM(E40,E49) -> 3624120 | F51: =SUM(F40,F49) -> -2624949 | G51: =SUM(G40,G49) -> 94871 | H51: =SUM(H40,H49) -> 2507341 | I51: =SUM(I40,I49) -> 1281031 | J51: =SUM(J40,J49) -> 2227982 | K51: =SUM(K40,K49) -> 2507560.3 | L51: =SUM(L40,L49) -> 2840622.2 | ... N51: =SUM(N40,N49) -> 4149970.6 | P51: =SUM(P40,P49) -> 771463 | Q51: =SUM(Q40,Q49) -> 1606349 | R51: =SUM(R40,R49) -> 406100 | S51: =SUM(S40,S49) -> 840208 | T51: =SUM(T40,T49) -> -429659 | U51: =SUM(U40,U49) -> -1093654 | V51: =SUM(V40,V49) -> -544635 | W51: =SUM(W40,W49) -> -557001 | ... BC51: =SUM(BC40,BC49) -> 1090602.1
B52: Net Income Margin | D52: % | E52: =E51/E$22 -> 0.46229293 | F52: =F51/F$22 -> -0.82178399 | G52: =G51/G$22 -> 0.031805765 | H52: =H51/H$22 -> 0.38198207 | I52: =I51/I$22 -> 0.17838365 | J52: =J51/J$22 -> 0.28709185 | K52: =K51/K$22 -> 0.28896724 | L52: =L51/L$22 -> 0.29209895 | ... N52: =N51/N$22 -> 0.29983787 | P52: =P51/P$22 -> 0.42832595 | Q52: =Q51/Q$22 -> 0.72099479 | R52: =R51/R$22 -> 0.30954915 | S52: =S51/S$22 -> 0.33628995 | T52: =T51/T$22 -> -0.36835197 | U52: =U51/U$22 -> -1.352988 | V52: =V51/V$22 -> -0.92258008 | W52: =W51/W$22 -> -0.88538216 | ... BC52: =BC51/BC$22 -> 0.34478092
A54: x | B54: Balance Sheet | D54: Units | E54: 21 | F54: =E54+1 -> 22 | G54: =F54+1 -> 23 | H54: =G54+1 -> 24 | I54: =H54+1 -> 25 | J54: =I54+1 -> 26 | K54: =J54+1 -> 27 | L54: =K54+1 -> 28 | M54: =L54+1 -> 29 | N54: =M54+1 -> 30 | P54: 44286 | Q54: 44377 | R54: 44469 | S54: 44561 | T54: 44651 | U54: 44742 | V54: 44834 | W54: 44926 | X54: 45016 | Y54: 45107 | Z54: 45199 | AA54: 45291 | AB54: 45382 | AC54: 45473 | AD54: 45565 | AE54: 45657 | AF54: 45747 | AG54: 45838 | AH54: 45930 | AI54: 46022 | AJ54: 46112 | AK54: 46203 | AL54: 46295 | AM54: 46387 | AN54: 46477 | AO54: 46568 | AP54: 46660 | AQ54: 46752 | AR54: 46843 | AS54: 46934 | AT54: 47026 | AU54: 47118 | AV54: 47208 | AW54: 47299 | AX54: 47391 | AY54: 47483 | AZ54: 47573 | BA54: 47664 | BB54: 47756 | BC54: 47848
...

Sheet Debt
A1: ='Cover Page'!$C$3 -> Coinbase Global Inc., (NASDAQ: COIN) | F1: 2021 | G1: =F1+1 -> 2022 | H1: =G1+1 -> 2023 | I1: =H1+1 -> 2024 | J1: =I1+1 -> 2025 | K1: =J1+1 -> 2026 | L1: =K1+1 -> 2027 | M1: =L1+1 -> 2028 | N1: =M1+1 -> 2029 | O1: =N1+1 -> 2030
A2: Property, Plant & Equipment Projections | F2: Q4 | G2: Q4 | H2: Q4 | I2: Q4 | J2: Q4 | K2: Q4 | L2: Q4 | M2: Q4 | N2: Q4 | O2: Q4
F3: 12 | G3: 12 | H3: 12 | I3: 12 | J3: 12 | K3: 12 | L3: 12 | M3: 12 | N3: 12 | O3: 12
F4: 365 | G4: 365 | H4: 365 | I4: 366 | J4: 365 | K4: 365 | L4: 365 | M4: 366 | N4: 365 | O4: 365
F5: Actuals | G5: Actuals | H5: Actuals | I5: Actuals | J5: Actuals | K5: Forecasted | L5: Forecasted | M5: Forecasted | N5: Forecasted | O5: Forecasted
A6: In USD '000s, Unless Stated Otherwise | F6: 44561 | G6: =EOMONTH(F6,12) -> 44926 | H6: =EOMONTH(G6,12) -> 45291 | I6: =EOMONTH(H6,12) -> 45657 | J6: =EOMONTH(I6,12) -> 46022 | K6: =EOMONTH(J6,12) -> 46387 | L6: =EOMONTH(K6,12) -> 46752 | M6: =EOMONTH(L6,12) -> 47118 | N6: =EOMONTH(M6,12) -> 47483 | O6: =EOMONTH(N6,12) -> 47848
A8: x | B8: Cash Available for Debt Service | E8: Units | F8: 21 | G8: =F8+1 -> 22 | H8: =G8+1 -> 23 | I8: =H8+1 -> 24 | J8: =I8+1 -> 25 | K8: =J8+1 -> 26 | L8: =K8+1 -> 27 | M8: =L8+1 -> 28 | N8: =M8+1 -> 29 | O8: =N8+1 -> 30
B10: Beginning Cash Balance | E10: USD '000s | K10: ='3FS'!J207 -> 11285452 | L10: ='3FS'!K207 -> 16507513 | M10: ='3FS'!L207 -> 18457012 | N10: ='3FS'!M207 -> 19725501 | O10: ='3FS'!N207 -> 20646417
B11: Cash Flow Available for Debt Service | E11: USD '000s | K11: ='3FS'!J183+'3FS'!J187+'3FS'!J188 -> 5384029.1 | L11: ='3FS'!K183+'3FS'!K187+'3FS'!K188 -> 2086390.2 | M11: ='3FS'!L183+'3FS'!L187+'3FS'!L188 -> 2411250.1 | N11: ='3FS'!M183+'3FS'!M187+'3FS'!M188 -> 2645730.8 | O11: ='3FS'!N183+'3FS'!N187+'3FS'!N188 -> 2934180.9
B12: Cash Available for Debt Service | E12: USD '000s | K12: =SUM(K10:K11) -> 16669481 | L12: =SUM(L10:L11) -> 18593903 | M12: =SUM(M10:M11) -> 20868262 | N12: =SUM(N10:N11) -> 22371232 | O12: =SUM(O10:O11) -> 23580597
A14: x | B14: Mandated Repayments | E14: Units | F14: 21 | G14: =F14+1 -> 22 | H14: =G14+1 -> 23 | I14: =H14+1 -> 24 | J14: =I14+1 -> 25 | K14: =J14+1 -> 26 | L14: =K14+1 -> 27 | M14: =L14+1 -> 28 | N14: =M14+1 -> 29 | O14: =N14+1 -> 30
B16: Mandated Repayments Amount - Term Loan A | E16: USD '000s
B17: Mandated Repayments Amount - Term Loan B | E17: USD '000s

Sheet WACC
A1: ='Cover Page'!$C$3 -> Coinbase Global Inc., (NASDAQ: COIN) | F1: 2021 | G1: =F1+1 -> 2022 | H1: =G1+1 -> 2023 | I1: =H1+1 -> 2024 | J1: =I1+1 -> 2025 | K1: =J1+1 -> 2026 | L1: =K1+1 -> 2027 | M1: =L1+1 -> 2028 | N1: =M1+1 -> 2029 | O1: =N1+1 -> 2030
A2: Property, Plant & Equipment Projections | F2: Q4 | G2: Q4 | H2: Q4 | I2: Q4 | J2: Q4 | K2: Q4 | L2: Q4 | M2: Q4 | N2: Q4 | O2: Q4
F3: 12 | G3: 12 | H3: 12 | I3: 12 | J3: 12 | K3: 12 | L3: 12 | M3: 12 | N3: 12 | O3: 12
F4: 365 | G4: 365 | H4: 365 | I4: 366 | J4: 365 | K4: 365 | L4: 365 | M4: 366 | N4: 365 | O4: 365
F5: Actuals | G5: Actuals | H5: Actuals | I5: Actuals | J5: Actuals | K5: Forecasted | L5: Forecasted | M5: Forecasted | N5: Forecasted | O5: Forecasted
A6: In USD '000s, Unless Stated Otherwise | F6: 44561 | G6: =EOMONTH(F6,12) -> 44926 | H6: =EOMONTH(G6,12) -> 45291 | I6: =EOMONTH(H6,12) -> 45657 | J6: =EOMONTH(I6,12) -> 46022 | K6: =EOMONTH(J6,12) -> 46387 | L6: =EOMONTH(K6,12) -> 46752 | M6: =EOMONTH(L6,12) -> 47118 | N6: =EOMONTH(M6,12) -> 47483 | O6: =EOMONTH(N6,12) -> 47848
A8: x | B8: Cost of Equity
B10: Capital Asset Pricing Model (CAPM)
B11: Risk Free Rate | D11: 0.0435
B12: Levered Beta | D12: =O39 -> 2.7506394
B13: Equity Risk Premium | D13: =O47 -> 0.055134434
B14: Country Risk Premium | D14: =O55 -> 0.013034434
B15: Cost of Equity | D15: =D11+D12*D13+D14 -> 0.20818938
B17: Levered Beta
B18: 2 | C18: 6 | F18: 161 | G18: 155 | L18: 16 | M18: 8 | N18: 9 | O18: 9
B19: Identified Peer Group
F21: Levered | G21: BV | H21: Cost of | I21: Debt | J21: Interest | K21: MV | L21: Market | M21: D/E | N21: Tax | O21: Unlevered
B22: Country | C22: Name | E22: Ticker | F22: Beta | G22: Debt | H22: Debt | I22: Maturity | J22: Expense | K22: Debt | L22: Capitalisation | M22: Ratio | N22: Rate | O22: Beta
B23: =_xlfn.XLOOKUP($E23,'Trading Comps_Raw'!$B$20:$B$26,'Trading Comps_Raw'!$I$20:$I$26) -> United States | C23: =_xlfn.XLOOKUP($E23,'Trading Comps_Raw'!$B$20:$B$26,'Trading Comps_Raw'!$E$20:$E$26) -> Gemini Space Station, Inc. | E23: NASDAQ:GEMI | F23: 0.80987929 | G23: =_xlfn.XLOOKUP($E23,'Trading Comps_Raw'!$B$20:$B$26,'Trading Comps_Raw'!$EC$20:$EC$26) -> 654.026 | L23: =_xlfn.XLOOKUP($E23,'Trading Comps_Raw'!$B$20:$B$26,'Trading Comps_Raw'!$S$20:$S$26) -> 519.15457 | M23: =G23/L23 -> 1.2597905 | N23: =Damodaran!$H$59 -> 0.25 | O23: =F23/(1+M23*(1-N23)) -> 0.41642402
B24: =_xlfn.XLOOKUP($E24,'Trading Comps_Raw'!$B$20:$B$26,'Trading Comps_Raw'!$I$20:$I$26) -> Cayman Islands | C24: =_xlfn.XLOOKUP($E24,'Trading Comps_Raw'!$B$20:$B$26,'Trading Comps_Raw'!$E$20:$E$26) -> Bullish | E24: NYSE:BLSH | F24: -2.4793146 | G24: =_xlfn.XLOOKUP($E24,'Trading Comps_Raw'!$B$20:$B$26,'Trading Comps_Raw'!$EC$20:$EC$26) -> 581.085 | L24: =_xlfn.XLOOKUP($E24,'Trading Comps_Raw'!$B$20:$B$26,'Trading Comps_Raw'!$S$20:$S$26) -> 5370.2979 | M24: =G24/L24 -> 0.10820349 | N24: =Damodaran!$H$59 -> 0.25 | O24: =F24/(1+M24*(1-N24)) -> -2.2932143
