Workbook
Name IQ_CH: 110000
Name IQ_CQ: 5000
Name IQ_CY: 10000
Name IQ_DAILY: 500000
Name IQ_FH: 100000
Name IQ_FQ: 500
Name IQ_FY: 1000
Name IQ_LTM: 2000
Name IQ_MONTH: 15000
Name IQ_NTM: 6000
Name IQ_WEEK: 50000
Name IQ_YTD: 3000

Sheet Cover
B2: EOS Energy Enterprise
B4: Last Updated: | C4: =TODAY() -> 45990
B5: COMPANY INFORMATION
B7: Company Name: | C7: EOS Energy Enterprise
B8: Exchange: | C8: NASDAQ
B9: Ticker: | C9: EOSE
B10: Applied Currency: | C10: USD Mn
B11: Scenario: | C11: Base Case
B13: BUSINESS DESCRIPTION
B14: Eos Energy Enterprises is a U.S.-based clean energy company that designs, manufactures, and markets zinc-based battery energy storage systems (BESS) for utility-scale, microgrid, and commercial/industrial applications. Their flagship product, the Eos Znyth™ DC system, is a safe, non-flammable, and scalable alternative to lithium-ion technology for long-duration energy storage, typically from 4 to 16+ hours. The company, founded in 2008 and headquartered in Edison, New Jersey, also provides services like project management and long-term maintenance.
B20: STYLE GUIDE
B22: Number Format | F22: General Format | G22: Colour Format
B23: _(0.0%_);(0.0%);- | C23: 0.105 | F23: Hardcoded Numbers | G23: #0000FF
B24: _(* #,##0.0_);_(* (#,##0.0);_(* "-"??_);_(@_) | C24: -100000 | F24: Assumptions | G24: #FFFFCC
B25: #,##0.0);(#,##0.0) | C25: 10 | F25: From Another Sheet | G25: #00B050
B26: #,##0.0;(#,##0.0);- | C26: -20334.1 | F26: Formula | G26: #000000
C117: Adjustments:

Sheet DuPont Analysis
C1: EOS Energy Enterprises, Inc. (NASDAQ: EOSE)
C3: 12M Target Price
C4: Scenario | D4: =Cover!C11 -> Base Case
F5: Historical | K5: Forecasted
C6: In USD Mns, unless stated otherwise | F6: 20 | G6: =F6+1 -> 21 | H6: =G6+1 -> 22 | I6: =H6+1 -> 23 | J6: =I6+1 -> 24 | K6: =J6+1 -> 25 | L6: =K6+1 -> 26 | M6: =L6+1 -> 27 | N6: =M6+1 -> 28 | O6: =N6+1 -> 29
C8: Days
C10: Income Statement
C11: Total Revenue | F11: ='3FS'!E13 -> 0.219 | G11: ='3FS'!F13 -> 4.598 | H11: ='3FS'!G13 -> 17.924 | I11: ='3FS'!H13 -> 16.378 | J11: ='3FS'!I13 -> 15.606 | K11: ='3FS'!J13 -> 174.94326 | L11: ='3FS'!K13 -> 769.7381 | M11: ='3FS'!L13 -> 1641.2176 | ... O11: ='3FS'!N13 -> 2543.7125
C12: Capex | F12: =PPE!H29 -> 3.605 | G12: =PPE!I29 -> 15.589 | H12: =PPE!J29 -> 20.072 | I12: =PPE!K29 -> 29.323 | J12: =PPE!L29 -> 33.152 | K12: =PPE!M29 -> 46.628408 | L12: =PPE!N29 -> 91.642169 | M12: =PPE!O29 -> 180.71687 | ... O12: =PPE!Q29 -> 621.58758
F13: =F12/F11 -> 16.461187 | G13: =G12/G11 -> 3.3903871 | H13: =H12/H11 -> 1.1198393 | I13: =I12/I11 -> 1.7903895 | J13: =J12/J11 -> 2.1243112 | K13: =K12/K11 -> 0.26653446 | L13: =L12/L11 -> 0.1190563 | M13: =M12/M11 -> 0.11011146 | ... O13: =O12/O11 -> 0.24436236
C14: EBITDA | F14: ='3FS'!E29 -> 0 | G14: ='3FS'!F29 -> -101.693 | H14: ='3FS'!G29 -> -207.598 | I14: ='3FS'!H29 -> -136.07 | J14: ='3FS'!I29 -> -158.217 | K14: ='3FS'!J29 -> -0.43026561 | L14: ='3FS'!K29 -> 64.326751 | M14: ='3FS'!L29 -> 361.55404 | ... O14: ='3FS'!N29 -> 1397.583
C15: EBT | F15: ='3FS'!E37 -> -70.643 | G15: ='3FS'!F37 -> -124.266 | H15: ='3FS'!G37 -> -229.716 | I15: ='3FS'!H37 -> -229.516 | J15: ='3FS'!I37 -> -685.816 | K15: ='3FS'!J37 -> -39.45218 | L15: ='3FS'!K37 -> 9.1605309 | M15: ='3FS'!L37 -> 290.05615 | ... O15: ='3FS'!N37 -> 1153.564
C16: Operating Income | F16: ='3FS'!E26 -> -37.417 | G16: ='3FS'!F26 -> -104.306 | H16: ='3FS'!G26 -> -214.412 | I16: ='3FS'!H26 -> -145.778 | J16: ='3FS'!I26 -> -166.066 | K16: ='3FS'!J26 -> -17.494326 | L16: ='3FS'!K26 -> 30.789524 | M16: ='3FS'!L26 -> 295.41917 | ... O16: ='3FS'!N26 -> 1170.1077
C18: Net Income/(Loss) | F18: ='3FS'!E40 -> -70.643 | G18: ='3FS'!F40 -> -124.266 | H18: ='3FS'!G40 -> -229.767 | I18: ='3FS'!H40 -> -229.547 | J18: ='3FS'!I40 -> -685.837 | K18: ='3FS'!J40 -> -39.453388 | L18: ='3FS'!K40 -> 9.1608114 | M18: ='3FS'!L40 -> 290.06504 | ... O18: ='3FS'!N40 -> 1153.5993
C21: Balance Sheet
C22: Total Asset (EOP) | F22: ='3FS'!E67 -> 138.264 | G22: ='3FS'!F67 -> 169.175 | H22: ='3FS'!G67 -> 106.788 | I22: ='3FS'!H67 -> 186.492 | J22: ='3FS'!I67 -> 260.318 | K22: ='3FS'!J67 -> 340.72589 | L22: ='3FS'!K67 -> 1980.9592 | M22: ='3FS'!L67 -> 5643.7823 | ... O22: ='3FS'!N67 -> 13436.195
C23: Average Asset | G23: =AVERAGE(F22:G22) -> 153.7195 | H23: =AVERAGE(G22:H22) -> 137.9815 | I23: =AVERAGE(H22:I22) -> 146.64 | J23: =AVERAGE(I22:J22) -> 223.405 | K23: =AVERAGE(J22:K22) -> 300.52194 | L23: =AVERAGE(K22:L22) -> 1160.8425 | M23: =AVERAGE(L22:M22) -> 3812.3707 | N23: =AVERAGE(M22:N22) -> 7621.1824 | O23: =AVERAGE(N22:O22) -> 11517.389
C25: Total Equity (EOP) | F25: ='3FS'!E95 -> 120.785 | G25: ='3FS'!F95 -> 32.447 | H25: ='3FS'!G95 -> -132.711 | I25: ='3FS'!H95 -> -110.8 | J25: ='3FS'!I95 -> -581.767 | K25: ='3FS'!J95 -> -486.61008 | L25: ='3FS'!K95 -> 114.92784 | M25: ='3FS'!L95 -> 1668.0455 | ... O25: ='3FS'!N95 -> 7230.6631
C26: Average Equity | G26: =AVERAGE(F25:G25) -> 76.616 | H26: =AVERAGE(G25:H25) -> -50.132 | I26: =AVERAGE(H25:I25) -> -121.7555 | J26: =AVERAGE(I25:J25) -> -346.2835 | K26: =AVERAGE(J25:K25) -> -534.18854 | L26: =AVERAGE(K25:L25) -> -185.84112 | M26: =AVERAGE(L25:M25) -> 891.48669 | N26: =AVERAGE(M25:N25) -> 2893.7561 | O26: =AVERAGE(N25:O25) -> 5675.0649
C30: Extended DuPont ROE
C31: Interest Burden Ratio | F31: =F15/F16 -> 1.8879921 | G31: =G15/G16 -> 1.19136 | H31: =H15/H16 -> 1.0713766 | I31: =I15/I16 -> 1.5744214 | J31: =J15/J16 -> 4.1297797 | K31: =K15/K16 -> 2.2551414 | L31: =L15/L16 -> 0.29752103 | M31: =M15/M16 -> 0.98184607 | ... O31: =O15/O16 -> 0.98586132
C32: Tax Burden Ratio | F32: =F18/F15 -> 1 | G32: =G18/G15 -> 1 | H32: =H18/H15 -> 1.000222 | I32: =I18/I15 -> 1.0001351 | J32: =J18/J15 -> 1.0000306 | K32: =K18/K15 -> 1.0000306 | L32: =L18/L15 -> 1.0000306 | M32: =M18/M15 -> 1.0000306 | ... O32: =O18/O15 -> 1.0000306
C33: Operating Profit Margin | F33: =F16/F11 -> -170.85388 | G33: =G16/G11 -> -22.68508 | H33: =H16/H11 -> -11.962285 | I33: =I16/I11 -> -8.9008426 | J33: =J16/J11 -> -10.641164 | K33: =K16/K11 -> -0.1 | L33: =L16/L11 -> 0.04 | M33: =M16/M11 -> 0.18 | ... O33: =O16/O11 -> 0.46
C34: Asset Turnover | G34: =G11/G23 -> 0.029911625 | H34: =H11/H23 -> 0.12990147 | I34: =I11/I23 -> 0.11168849 | J34: =J11/J23 -> 0.069855196 | K34: =K11/K23 -> 0.5821314 | L34: =L11/L23 -> 0.66308571 | M34: =M11/M23 -> 0.43049791 | N34: =N11/N23 -> 0.29653942 | O34: =O11/O23 -> 0.22085843
C35: Financial Leverage | G35: =G23/G26 -> 2.0063629 | H35: =H23/H26 -> -2.7523638 | I35: =I23/I26 -> -1.2043809 | J35: =J23/J26 -> -0.64515058 | K35: =K23/K26 -> -0.56257655 | L35: =L23/L26 -> -6.2464244 | M35: =M23/M26 -> 4.2764192 | N35: =N23/N26 -> 2.6336644 | O35: =O23/O26 -> 2.0294726
C37: ROE | G37: =G31*G32*G33*G35*G34 -> -1.6219328 | H37: =H31*H32*H33*H35*H34 -> 4.5832402 | I37: =I31*I32*I33*I35*I34 -> 1.8853111 | J37: =J31*J32*J33*J35*J34 -> 1.9805651 | K37: =K31*K32*K33*K35*K34 -> 0.073856672 | L37: =L31*L32*L33*L35*L34 -> -0.04929378 | M37: =M31*M32*M33*M35*M34 -> 0.32537226 | N37: =N31*N32*N33*N35*N34 -> 0.24610883 | O37: =O31*O32*O33*O35*O34 -> 0.20327508

Sheet Valuation>

Sheet DCF
D2: EOS Energy Enterprises, Inc. (NASDAQ: EOSE)
D4: EOS Energy Enterprises, Inc. (NASDAQ: EOSE)
D6: 12M Target Price
D7: Scenario | F7: =Cover!C11 -> Base Case
H8: Historical | M8: Forecasted
D9: In USD, unless stated otherwise | E9: Units | H9: 20 | I9: =H9+1 -> 21 | J9: =I9+1 -> 22 | K9: =J9+1 -> 23 | L9: =K9+1 -> 24 | M9: =L9+1 -> 25 | N9: =M9+1 -> 26 | O9: =N9+1 -> 27 | P9: =O9+1 -> 28 | Q9: =P9+1 -> 29 | S9: Notes:
B11: 1 | D11: Assumptions | R11: Notes:
D13: Tax Rate | E13: % | F13: 0.21 | G13: US Marginal Tax Rate
D14: Weighted ERP | E14: % | F14: 0.09 | G14: US Market ERP 5% (Kroll) + Size Premium 4% (Damodaran)
D15: Relevered Beta | E15: x | F15: =Comps!I23 -> 2.1920846 | G15: Relevered the Unlevered beta taken from the average of competitors
D17: US 10Y Treasury Yield | E17: % | F17: 0.041
D19: Unit | E19: USD | F19: 1000000
D21: LTM Total Interest Expense (Average of Forecasted) | F21: =AVERAGE('3FS'!J33:N33) -> -15.306086
D22: Interest Coverage Ratio | F22: =-F21/(AVERAGE(M42:Q42)) -> 0.034754711
D23: Credit Rating | F23: ='Synthetic Rating'!C19 -> D2/D | G23: Average of Forecasted Interest Expense / Average of Forecasted EBIT
D24: Synthetic Credit Spread | E24: % | F24: ='Synthetic Rating'!D19 -> 0.19
D26: Total Cash | F26: =$F$19*'3FS'!I48 -> 74292000
D27: Total Debt | E27: USD | F27: =$F$19*('3FS'!I80+'3FS'!I73+'3FS'!I81+'3FS'!I74+'3FS'!I94) -> 809187000
D28: NOSH | E28: x | F28: 279200000
D29: Last Closed Share Price | E29: USD | F29: 15.29
D30: Shareholder's Equity | E30: USD | F30: =F28*F29 -> 4268968000 | G30: Share Price as of 7th Nov, 2025
D31: Debt + Equity | F31: =F30+F27 -> 5078155000
D33: Cost of Debt | E33: % | F33: =F17+F24*(1-F13) -> 0.1911
D34: Cost of Equity | E34: % | F34: =F15*F14+F17 -> 0.23828761
D35: WACC | E35: % | F35: =F27/F31*F33+F30/F31*F34 -> 0.23076842
D36: Valuation Date | F36: =TODAY() -> 45990
B38: 2 | D38: 3FS
D40: Depreciation & Amortization | H40: ='3FS'!E107 -> 1.558 | I40: ='3FS'!F107 -> 3.537 | J40: ='3FS'!G107 -> 7.679 | K40: ='3FS'!H107 -> 10.731 | L40: ='3FS'!I107 -> 9.082 | M40: ='3FS'!J107 -> 17.06406 | N40: ='3FS'!K107 -> 33.537227 | O40: ='3FS'!L107 -> 66.134868 | ... Q40: ='3FS'!N107 -> 227.47523
D42: EBIT | H42: ='3FS'!E26 -> -37.417 | I42: ='3FS'!F26 -> -104.306 | J42: ='3FS'!G26 -> -214.412 | K42: ='3FS'!H26 -> -145.778 | L42: ='3FS'!I26 -> -166.066 | M42: ='3FS'!J26 -> -17.494326 | N42: ='3FS'!K26 -> 30.789524 | O42: ='3FS'!L26 -> 295.41917 | ... Q42: ='3FS'!N26 -> 1170.1077
D44: CapEx | H44: =-PPE!H29 -> -3.605 | I44: =-PPE!I29 -> -15.589 | J44: =-PPE!J29 -> -20.072 | K44: =-PPE!K29 -> -29.323 | L44: =-PPE!L29 -> -33.152 | M44: =-PPE!M29 -> -46.628408 | N44: =-PPE!N29 -> -91.642169 | O44: =-PPE!O29 -> -180.71687 | ... Q44: =-PPE!Q29 -> -621.58758
D46: Net Change in Working Capital | I46: =I48-H48 -> -1.127 | J46: =J48-I48 -> -118.084 | K46: =K48-J48 -> 66.89 | L46: =L48-K48 -> 53.476 | M46: =M48-L48 -> -703.28892 | N46: =N48-M48 -> 434.29871 | O46: =O48-N48 -> 1279.0199 | P46: =P48-O48 -> 2131.1568 | Q46: =Q48-P48 -> 2936.1048
D48: Net Working Capital | H48: ='3FS'!E56-'3FS'!E77 -> 113.782 | I48: ='3FS'!F56-'3FS'!F77 -> 112.655 | J48: ='3FS'!G56-'3FS'!G77 -> -5.429 | K48: ='3FS'!H56-'3FS'!H77 -> 61.461 | L48: ='3FS'!I56-'3FS'!I77 -> 114.937 | M48: ='3FS'!J56-'3FS'!J77 -> -588.35192 | N48: ='3FS'!K56-'3FS'!K77 -> -154.05322 | O48: ='3FS'!L56-'3FS'!L77 -> 1124.9666 | ... Q48: ='3FS'!N56-'3FS'!N77 -> 6192.2282
B50: 3 | D50: DCF
D52: NOPAT | H52: =H42*(1-$F$13) -> -29.55943 | I52: =I42*(1-$F$13) -> -82.40174 | J52: =J42*(1-$F$13) -> -169.38548 | K52: =K42*(1-$F$13) -> -115.16462 | L52: =L42*(1-$F$13) -> -131.19214 | M52: =M42*(1-$F$13) -> -13.820518 | N52: =N42*(1-$F$13) -> 24.323724 | O52: =O42*(1-$F$13) -> 233.38115 | ... Q52: =Q42*(1-$F$13) -> 924.38511
D53: (+) D&A | H53: =H40 -> 1.558 | I53: =I40 -> 3.537 | J53: =J40 -> 7.679 | K53: =K40 -> 10.731 | L53: =L40 -> 9.082 | M53: =M40 -> 17.06406 | N53: =N40 -> 33.537227 | O53: =O40 -> 66.134868 | ... Q53: =Q40 -> 227.47523
D54: (-) CapEx | H54: =H44 -> -3.605 | I54: =I44 -> -15.589 | J54: =J44 -> -20.072 | K54: =K44 -> -29.323 | L54: =L44 -> -33.152 | M54: =M44 -> -46.628408 | N54: =N44 -> -91.642169 | O54: =O44 -> -180.71687 | ... Q54: =Q44 -> -621.58758
D55: (-) Net Change in Working Capital | H55: =H46 -> 0 | I55: =I46 -> -1.127 | J55: =J46 -> -118.084 | K55: =K46 -> 66.89 | L55: =L46 -> 53.476 | M55: =M46 -> -703.28892 | N55: =N46 -> 434.29871 | O55: =O46 -> 1279.0199 | ... Q55: =Q46 -> 2936.1048
D56: Unlevered Free Cash Flow (FCFF) | H56: =SUM(H52:H55) -> -31.60643 | I56: =SUM(I52:I55) -> -95.58074 | J56: =SUM(J52:J55) -> -299.86248 | K56: =SUM(K52:K55) -> -66.86662 | L56: =SUM(L52:L55) -> -101.78614 | M56: =SUM(M52:M55) -> -746.67379 | N56: =SUM(N52:N55) -> 400.51749 | O56: =SUM(O52:O55) -> 1397.819 | ... Q56: =SUM(Q52:Q55) -> 3466.3776
D58: Discount Factor | M58: =(1+$F$35)^(M9-$L$9) -> 1.2307684 | N58: =(1+$F$35)^(N9-$L$9) -> 1.5147909 | O58: =(1+$F$35)^(O9-$L$9) -> 1.8643568 | P58: =(1+$F$35)^(P9-$L$9) -> 2.2945915 | Q58: =(1+$F$35)^(Q9-$L$9) -> 2.8241108
D59: Present Value of FCFE | M59: =M56/M58 -> -606.67285 | N59: =N56/N58 -> 264.40447 | O59: =O56/O58 -> 749.75937 | P59: =P56/P58 -> 1085.3176 | Q59: =Q56/Q58 -> 1227.4227
...

Sheet Comps
D2: EOS Energy Enterprises, Inc. (NASDAQ: EOSE)
D4: 12M Target Price
D5: Scenario | G5: =[1]Cover!C11 -> Base Case
D7: In USD Mns, unless stated otherwise | S7: Notes:
B9: 1 | D9: Peer Companies - Unlevered Beta Calculation
D11: Peer Companies | E11: Ticker | F11: Industry | G11: Location | H11: EV/Sales | I11: Levered Beta | J11: Debt | K11: % Debt | L11: Preferred Stock | M11: % Preferred | N11: Equity Value | O11: % Equity | P11: Tax Rate | Q11: Unlevered Beta
D12: Fluence Energy, Inc. | E12: FLNC | F12: Utilities | G12: USA | H12: 0.2 | I12: 2.8 | J12: =390356/10^3 -> 390.356 | K12: =J12/(J12+L12+N12) -> 0.4283996 | L12: 0 | M12: =L12/(J12+L12+N12) -> 0 | N12: 520.84 | O12: =N12/(N12+L12+J12) -> 0.5716004 | P12: 0.21 | Q12: =I12/(1+(1-P12)*(J12+L12)/N12) -> 1.7587007
D13: Solid Power | E13: SLDP | F13: Industrials | G13: USA | H13: 16.1 | I13: 1.85 | J13: 8.8 | K13: =J13/(J13+L13+N13) -> 0.023184129 | L13: 0 | M13: =L13/(J13+L13+N13) -> 0 | N13: 370.77 | O13: =N13/(N13+L13+J13) -> 0.97681587 | P13: 0.21 | Q13: =I13/(1+(1-P13)*(J13+L13)/N13) -> 1.8159506
D14: Plug Power | E14: PLUG | F14: Industrials | G14: USA | H14: 3.4 | I14: 2.24 | J14: =655.56 -> 655.56 | K14: =J14/(J14+L14+N14) -> 0.27139049 | L14: 0 | M14: =L14/(J14+L14+N14) -> 0 | N14: 1760 | O14: =N14/(N14+L14+J14) -> 0.72860951 | P14: 0.21 | Q14: =I14/(1+(1-P14)*(J14+L14)/N14) -> 1.7307227
D15: Microvast | E15: MVST | F15: Industrials | G15: USA | H15: 4.85 | I15: 3.36 | J15: 403.28 | K15: =J15/(J15+L15+N15) -> 0.53434386 | L15: 0 | M15: =L15/(J15+L15+N15) -> 0 | N15: 351.44 | O15: =N15/(N15+L15+J15) -> 0.46565614 | P15: 0.21 | Q15: =I15/(1+(1-P15)*(J15+L15)/N15) -> 1.7623633
D16: FuelCell Energy | E16: FCEL | F16: Industrials | G16: USA | H16: 1.2 | I16: 4.27 | J16: 135 | K16: =J16/(J16+L16+N16) -> 0.17974668 | L16: 59.857 | M16: =L16/(J16+L16+N16) -> 0.079697014 | N16: 556.2 | O16: =N16/(N16+L16+J16) -> 0.74055631 | P16: 0.21 | Q16: =I16/(1+(1-P16)*(J16+L16)/N16) -> 3.3443883
D19: Average | H19: =AVERAGE(H12,H13:H16) -> 5.15 | I19: =AVERAGE(I12:I16) -> 2.904 | J19: =AVERAGE(J12:J16) -> 318.5992 | K19: =AVERAGE(K12:K16) -> 0.28741295 | L19: =AVERAGE(L12:L16) -> 11.9714 | M19: =AVERAGE(M12:M16) -> 0.015939403 | N19: =AVERAGE(N12:N16) -> 711.85 | O19: =AVERAGE(O12:O16) -> 0.69664765 | P19: =AVERAGE(P12:P16) -> 0.21 | Q19: =AVERAGE(Q12:Q16) -> 2.0824251
D20: Median | H20: =MEDIAN(H12:H16) -> 3.4 | I20: =MEDIAN(I12:I16) -> 2.8 | J20: =MEDIAN(J12:J16) -> 390.356 | K20: =MEDIAN(K12:K16) -> 0.27139049 | L20: =MEDIAN(L12:L16) -> 0 | M20: =MEDIAN(M12:M16) -> 0 | N20: =MEDIAN(N12:N16) -> 520.84 | O20: =MEDIAN(O12:O16) -> 0.72860951 | ... Q20: =MEDIAN(Q12:Q16) -> 1.7623633
D22: EOSE Energy Enterprise, Inc - Levered Beta Calculation
D23: EOS Energy Enterprise, Inc | E23: EOSE | F23: Industrials | G23: USA | I23: =Q23*(1+(1-P23)*((J23+L23)/N23)) -> 2.1920846 | J23: =AVERAGE('[1]Debt & Equity'!M13:Q13) -> 22736.573 | K23: =J23/(J23+L23+N23) -> 0.062492018 | M23: =L23/(J23+L23+N23) -> 0 | N23: =AVERAGE('[1]3FS'!J95:N95) -> 341095.06 | O23: =N23/(N23+L23+J23) -> 0.93750798 | P23: 0.21 | Q23: =Q19 -> 2.0824251
G24: DON’T USE Forecasted | I24: =Q24*(1+(1-P24)*((J24+L24)/N24)) -> 1.863524 | J24: =[1]DCF!G24 -> 316.896 | K24: =J24/(J24+L24+N24) -> 0.067737246 | L24: 0 | M24: =L24/(J24+L24+N24) -> 0 | N24: =[1]DCF!G27 -> 4361.4164 | O24: =N24/(N24+L24+J24) -> 0.93226275 | P24: 0.21 | Q24: =Q20 -> 1.7623633 | R24: not sure if we should use forecasted year average total debt and equity or the last actual year

Sheet Balance>

Sheet 3FS
C1: EOS Energy Enterprises, Inc. (NASDAQ: EOSE)
C3: 12M Target Price
C4: Scenario | D4: =[2]Cover!C11 -> Base Case
E5: Historical | J5: Forecasted
C6: In USD Mns, unless stated otherwise | E6: 20 | F6: =E6+1 -> 21 | G6: =F6+1 -> 22 | H6: =G6+1 -> 23 | I6: =H6+1 -> 24 | J6: =I6+1 -> 25 | K6: =J6+1 -> 26 | L6: =K6+1 -> 27 | M6: =L6+1 -> 28 | N6: =M6+1 -> 29
B8: x
C9: Income Statement | E9: FY20A | F9: FY21A | G9: FY22A | H9: FY23A | I9: FY24A | J9: FY25E | K9: FY26E | L9: FY27E | M9: FY28E | N9: FY29E
C11: Product Revenue | E11: 0.184 | F11: 4.562 | G11: 17.429 | H11: 16.151 | I11: 14.503 | J11: ='Revenue Build'!L12 -> 162.57863 | K11: ='Revenue Build'!M12 -> 715.33459 | L11: ='Revenue Build'!N12 -> 1525.2197 | M11: ='Revenue Build'!O12 -> 2100.2502 | N11: ='Revenue Build'!P12 -> 2363.9281
C12: Service Revenue | E12: 0.035 | F12: 0.036 | G12: 0.495 | H12: 0.227 | I12: 1.103 | J12: ='Revenue Build'!L13 -> 12.36463 | K12: ='Revenue Build'!M13 -> 54.403506 | L12: ='Revenue Build'!N13 -> 115.99789 | M12: ='Revenue Build'!O13 -> 159.73081 | N12: ='Revenue Build'!P13 -> 179.78437
C13: Total Revenue | E13: =SUM(E11:E12) -> 0.219 | F13: =SUM(F11:F12) -> 4.598 | G13: =SUM(G11:G12) -> 17.924 | H13: =SUM(H11:H12) -> 16.378 | I13: =SUM(I11:I12) -> 15.606 | J13: =SUM(J11:J12) -> 174.94326 | K13: =SUM(K11:K12) -> 769.7381 | L13: =SUM(L11:L12) -> 1641.2176 | ... N13: =SUM(N11:N12) -> 2543.7125
C14: %yoy | F14: =(F13-E13)/E13 -> 19.995434 | G14: =(G13-F13)/F13 -> 2.8982166 | H14: =(H13-G13)/G13 -> -0.086253069 | I14: =(I13-H13)/H13 -> -0.047136402 | J14: =(J13-I13)/I13 -> 10.21 | K14: =(K13-J13)/J13 -> 3.39993 | L14: =(L13-K13)/K13 -> 1.1321767 | M14: =(M13-L13)/L13 -> 0.37701484 | N14: =(N13-M13)/M13 -> 0.12554594
C16: Cost of Goods Sold | E16: -5.509 | F16: -46.483 | G16: -153.26 | H16: -89.798 | I16: -98.867 | J16: =Projections!K17 -> -104.96596 | K16: =Projections!L17 -> -442.59941 | L16: =Projections!M17 -> -902.6697 | M16: =Projections!N17 -> -1186.49 | N16: =Projections!O17 -> -1271.8562
C17: Gross Profit | E17: =SUM(E13,E16) -> -5.29 | F17: =SUM(F13,F16) -> -41.885 | G17: =SUM(G13,G16) -> -135.336 | H17: =SUM(H13,H16) -> -73.42 | I17: =SUM(I13,I16) -> -83.261 | J17: =SUM(J13,J16) -> 69.977304 | K17: =SUM(K13,K16) -> 327.13869 | L17: =SUM(L13,L16) -> 738.54793 | ... N17: =SUM(N13,N16) -> 1271.8562
C18: %revenue | E18: =E16/E13 -> -25.155251 | F18: =F16/F13 -> -10.109395 | G18: =G16/G13 -> -8.5505468 | H18: =H16/H13 -> -5.4828428 | I18: =I16/I13 -> -6.3351916 | J18: =J16/J13 -> -0.6 | K18: =K16/K13 -> -0.575 | L18: =L16/L13 -> -0.55 | ... N18: =N16/N13 -> -0.5
C19: Gross Profit Margin | E19: =E17/E13 -> -24.155251 | F19: =F17/F13 -> -9.1093954 | G19: =G17/G13 -> -7.5505468 | H19: =H17/H13 -> -4.4828428 | I19: =I17/I13 -> -5.3351916 | J19: =J17/J13 -> 0.4 | K19: =K17/K13 -> 0.425 | L19: =L17/L13 -> 0.45 | ... N19: =N17/N13 -> 0.5
B21: x | C21: OPERATING ITEMS:
C22: SG&A | E22: -17.621 | F22: -42.998 | G22: -60.623 | H22: -53.65 | I22: -60.047 | J22: =Projections!K27 -> -69.977304 | K22: =Projections!L27 -> -238.61881 | L22: =Projections!M27 -> -361.06788 | M22: =Projections!N27 -> -293.79753 | N22: =Projections!O27 -> -101.7485
C23: R&D | E23: -13.593 | F23: -19.154 | G23: -18.469 | H23: -18.708 | I23: -22.758 | J23: =Projections!K33 -> -17.494326 | K23: =Projections!L33 -> -57.730357 | L23: =Projections!M33 -> -82.060881 | M23: =Projections!N33 -> -56.499526 | N23: =Projections!O33 -> 0 | S23: 477 | T23: 785 | U23: 924 | V23: 843 | W23: 836
C24: Other Operating Expenses | E24: -0.913 | F24: -0.269 | G24: =--0.016 -> 0.016 | H24: 0 | I24: 0 | J24: =Projections!K39 -> 0 | K24: =Projections!L39 -> 0 | L24: =Projections!M39 -> 0 | M24: =Projections!N39 -> 0 | N24: =Projections!O39 -> 0 | S24: - | T24: - | U24: 20 | V24: 26 | W24: 31
C25: Total Operating Expenses | E25: =SUM(E22:E24) -> -32.127 | F25: =SUM(F22:F24) -> -62.421 | G25: =SUM(G22:G24) -> -79.076 | H25: =SUM(H22:H24) -> -72.358 | I25: =SUM(I22:I24) -> -82.805 | J25: =SUM(J22:J24) -> -87.47163 | K25: =SUM(K22:K24) -> -296.34917 | L25: =SUM(L22:L24) -> -443.12876 | ... N25: =SUM(N22:N24) -> -101.7485 | S25: 257 | T25: 356 | U25: 465 | V25: 421 | W25: 410
C26: Operating Income (EBIT) | E26: =E17+E25 -> -37.417 | F26: =F17+F25 -> -104.306 | G26: =G17+G25 -> -214.412 | H26: =H17+H25 -> -145.778 | I26: =I17+I25 -> -166.066 | J26: =J17+J25 -> -17.494326 | K26: =K17+K25 -> 30.789524 | L26: =L17+L25 -> 295.41917 | ... N26: =N17+N25 -> 1170.1077
C27: %revenue | E27: =E26/E13 -> -170.85388 | F27: =F26/F13 -> -22.68508 | G27: =G26/G13 -> -11.962285 | H27: =H26/H13 -> -8.9008426 | I27: =I26/I13 -> -10.641164 | J27: =J26/J13 -> -0.1 | K27: =K26/K13 -> 0.04 | L27: =L26/L13 -> 0.18 | ... N27: =N26/N13 -> 0.46
C29: EBITDA | F29: -101.693 | G29: -207.598 | H29: -136.07 | I29: -158.217 | J29: =J26+J105+J106 -> -0.43026561 | K29: =K26+K105+K106 -> 64.326751 | L29: =L26+L105+L106 -> 361.55404 | M29: =M26+M105+M106 -> 845.6258 | N29: =N26+N105+N106 -> 1397.583
C30: %revenue | E30: =E29/E13 -> 0 | F30: =F29/F13 -> -22.11679 | G30: =G29/G13 -> -11.582125 | H30: =H29/H13 -> -8.3080962 | I30: =I29/I13 -> -10.138216 | J30: =J29/J13 -> -0.0024594581 | K30: =K29/K13 -> 0.08356966 | L30: =L29/L13 -> 0.22029622 | ... N30: =N29/N13 -> 0.54942647
B32: x | C32: NON-OPERATING ITEMS
C33: Net Interest Exp. | E33: -23.821 | F33: -5.201 | G33: -18.813 | H33: -56.236 | I33: -28.217 | J33: ='Debt & Equity'!M64+Projections!K131 -> -21.957854 | K33: ='Debt & Equity'!N64+Projections!L131 -> -21.628993 | L33: ='Debt & Equity'!O64+Projections!M131 -> -5.3630191 | M33: ='Debt & Equity'!P64+Projections!N131 -> -11.036791 | N33: ='Debt & Equity'!Q64+Projections!O131 -> -16.543775
C34: Income/(Loss) from Affiliates | E34: 0.077 | F34: 14.436 | G34: 11.251 | H34: -16.792 | I34: -584.734 | J34: =Projections!K52 -> 0 | K34: =Projections!L52 -> 0 | L34: =Projections!M52 -> 0 | M34: =Projections!N52 -> 0 | N34: =Projections!O52 -> 0
C35: Asset Writedown | E35: - | F35: -0.1 | G35: -6.8 | H35: -7.2 | I35: -9.1 | J35: =Projections!K55 -> 0 | K35: =Projections!L55 -> 0 | L35: =Projections!M55 -> 0 | M35: =Projections!N55 -> 0 | N35: =Projections!O55 -> 0
C36: Other Unusual Items | E36: -9.482 | F36: -29.095 | G36: -0.942 | H36: -3.51 | I36: 102.301 | J36: =Projections!K58 -> 0 | K36: =Projections!L58 -> 0 | L36: =Projections!M58 -> 0 | M36: =Projections!N58 -> 0 | N36: =Projections!O58 -> 0
C37: Earnings Before Taxes | E37: =SUM(E26,E33:E36) -> -70.643 | F37: =SUM(F26,F33:F36) -> -124.266 | G37: =SUM(G26,G33:G36) -> -229.716 | H37: =SUM(H26,H33:H36) -> -229.516 | I37: =SUM(I26,I33:I36) -> -685.816 | J37: =SUM(J26,J33:J36) -> -39.45218 | K37: =SUM(K26,K33:K36) -> 9.1605309 | L37: =SUM(L26,L33:L36) -> 290.05615 | ... N37: =SUM(N26,N33:N36) -> 1153.564
C38: Income Tax Expense | E38: 0 | F38: 0 | G38: 0.051 | H38: 0.031 | I38: 0.021 | J38: =Projections!K65 -> 0.0012080438 | K38: =Projections!L65 -> -0.00028049965 | L38: =Projections!M65 -> -0.0088816523 | M38: =Projections!N65 -> -0.021806578 | N38: =Projections!O65 -> -0.035322657
C39: Minority Interest in Earnings | J39: =Projections!K68 -> 0 | K39: =Projections!L68 -> 0 | L39: =Projections!M68 -> 0 | M39: =Projections!N68 -> 0 | N39: =Projections!O68 -> 0
C40: Net Income/(Loss) | E40: =E37-E38+E39 -> -70.643 | F40: =F37-F38+F39 -> -124.266 | G40: =G37-G38+G39 -> -229.767 | H40: =H37-H38+H39 -> -229.547 | I40: =I37-I38+I39 -> -685.837 | J40: =J37-J38+J39 -> -39.453388 | K40: =K37-K38+K39 -> 9.1608114 | L40: =L37-L38+L39 -> 290.06504 | ... N40: =N37-N38+N39 -> 1153.5993
C41: %revenue
B43: x
C44: Balance Sheet | E44: FY20A | F44: FY21A | G44: FY22A | H44: FY23A | I44: FY24A | J44: FY25E | K44: FY26E | L44: FY27E | M44: FY28E | N44: FY29E
C46: ASSETS:
C47: Current Assets
C48: Cash And Equivalents | E48: 121.853 | F48: 104.831 | G48: 17.076 | H48: 69.473 | I48: 74.292 | J48: =J147 -> 32.036765 | K48: =K147 -> 813.55452 | L48: =L147 -> 3188.699 | M48: =M147 -> 6100.6289 | N48: =N147 -> 9155.6914
C49: Restricted Cash | E49: 0 | F49: 0.861 | G49: 2.725 | H49: 3.439 | I49: 14.07 | J49: =Projections!K190 -> 0 | K49: =Projections!L190 -> 0 | L49: =Projections!M190 -> 0 | M49: =Projections!N190 -> 0 | N49: =Projections!O190 -> 0
...

Sheet Projections
C1: EOS Energy Enterprises, Inc. (NASDAQ: EOSE)
C3: 12M Target Price
C4: Scenario | D4: =Cover!C11 -> Base Case
F5: Historical | K5: Forecasted
C6: In USD Mns, unless stated otherwise | F6: 20 | G6: =F6+1 -> 21 | H6: =G6+1 -> 22 | I6: =H6+1 -> 23 | J6: =I6+1 -> 24 | K6: =J6+1 -> 25 | L6: =K6+1 -> 26 | M6: =L6+1 -> 27 | N6: =M6+1 -> 28 | O6: =N6+1 -> 29
C7: Fiscal Year End Date
C8: Days | F8: 366 | G8: 365 | H8: 365 | I8: 365 | J8: 366 | K8: 365 | L8: 365 | M8: 365 | N8: 366 | O8: 365
C10: Revenue Build
C12: Total Revenue | F12: ='3FS'!E13 -> 0.219 | G12: ='3FS'!F13 -> 4.598 | H12: ='3FS'!G13 -> 17.924 | I12: ='3FS'!H13 -> 16.378 | J12: ='3FS'!I13 -> 15.606 | K12: ='3FS'!J13 -> 174.94326 | L12: ='3FS'!K13 -> 769.7381 | M12: ='3FS'!L13 -> 1641.2176 | ... O12: ='3FS'!N13 -> 2543.7125
C13: %yoy | G13: =G12/F12-1 -> 19.995434 | H13: =H12/G12-1 -> 2.8982166 | I13: =I12/H12-1 -> -0.086253069 | J13: =J12/I12-1 -> -0.047136402 | K13: =K12/J12-1 -> 10.21 | L13: =L12/K12-1 -> 3.39993 | M13: =M12/L12-1 -> 1.1321767 | N13: =N12/M12-1 -> 0.37701484 | O13: =O12/N12-1 -> 0.12554594
C15: COGS
C17: Cost of Sales | F17: ='3FS'!E16 -> -5.509 | G17: ='3FS'!F16 -> -46.483 | H17: ='3FS'!G16 -> -153.26 | I17: ='3FS'!H16 -> -89.798 | J17: ='3FS'!I16 -> -98.867 | K17: =K18*K$12 -> -104.96596 | L17: =L18*L$12 -> -442.59941 | M17: =M18*M$12 -> -902.6697 | N17: =N18*N$12 -> -1186.49 | O17: =O18*O$12 -> -1271.8562
C18: %Revenue | F18: =F17/F12 -> -25.155251 | G18: =G17/G12 -> -10.109395 | H18: =H17/H12 -> -8.5505468 | I18: =I17/I12 -> -5.4828428 | J18: =J17/J12 -> -6.3351916 | K18: =_xlfn.XLOOKUP($D$4,$C19:$C21,K19:K21) -> -0.6 | L18: =_xlfn.XLOOKUP($D$4,$C19:$C21,L19:L21) -> -0.575 | M18: =_xlfn.XLOOKUP($D$4,$C19:$C21,M19:M21) -> -0.55 | N18: =_xlfn.XLOOKUP($D$4,$C19:$C21,N19:N21) -> -0.525 | O18: =_xlfn.XLOOKUP($D$4,$C19:$C21,O19:O21) -> -0.5
C19: Bull Case | E19: 0.02 | K19: =K20+$E19 -> -0.58 | L19: =L20+$E19 -> -0.555 | M19: =M20+$E19 -> -0.53 | N19: =N20+$E19 -> -0.505 | O19: =O20+$E19 -> -0.48
C20: Base Case | E20: 0.025 | K20: -0.6 | L20: =K18+$E20 -> -0.575 | M20: =L18+$E20 -> -0.55 | N20: =M18+$E20 -> -0.525 | O20: =N18+$E20 -> -0.5
C21: Bear Case | E21: -0.02 | K21: =K20+$E21 -> -0.62 | L21: =L20+$E21 -> -0.595 | M21: =M20+$E21 -> -0.57 | N21: =N20+$E21 -> -0.545 | O21: =O20+$E21 -> -0.52
C23: Operating Expenses
C25: Total Operating Expenses | F25: ='3FS'!E25 -> -32.127 | G25: ='3FS'!F25 -> -62.421 | H25: ='3FS'!G25 -> -79.076 | I25: ='3FS'!H25 -> -72.358 | J25: ='3FS'!I25 -> -82.805 | K25: =SUM(K27,K39,K33) -> -87.47163 | L25: =SUM(L27,L39,L33) -> -296.34917 | M25: =SUM(M27,M39,M33) -> -443.12876 | N25: =SUM(N27,N39,N33) -> -350.29706 | O25: =SUM(O27,O39,O33) -> -101.7485
C27: SG&A | F27: ='3FS'!E22 -> -17.621 | G27: ='3FS'!F22 -> -42.998 | H27: ='3FS'!G22 -> -60.623 | I27: ='3FS'!H22 -> -53.65 | J27: ='3FS'!I22 -> -60.047 | K27: =K28*K$12 -> -69.977304 | L27: =L28*L$12 -> -238.61881 | M27: =M28*M$12 -> -361.06788 | N27: =N28*N$12 -> -293.79753 | O27: =O28*O$12 -> -101.7485
C28: %Revenue | F28: =F27/F12 -> -80.461187 | G28: =G27/G12 -> -9.3514572 | H28: =H27/H12 -> -3.3822249 | I28: =I27/I12 -> -3.2757357 | J28: =J27/J12 -> -3.8476868 | K28: =_xlfn.XLOOKUP($D$4,$C29:$C31,K29:K31) -> -0.4 | L28: =_xlfn.XLOOKUP($D$4,$C29:$C31,L29:L31) -> -0.31 | M28: =_xlfn.XLOOKUP($D$4,$C29:$C31,M29:M31) -> -0.22 | N28: =_xlfn.XLOOKUP($D$4,$C29:$C31,N29:N31) -> -0.13 | O28: =_xlfn.XLOOKUP($D$4,$C29:$C31,O29:O31) -> -0.04
C29: Bull Case | E29: 0.01 | K29: =K30+$E29 -> -0.39 | L29: =L30+$E29 -> -0.3 | M29: =M30+$E29 -> -0.21 | N29: =N30+$E29 -> -0.12 | O29: =O30+$E29 -> -0.03
C30: Base Case | E30: 0.09 | K30: -0.4 | L30: =K28+$E30 -> -0.31 | M30: =L28+$E30 -> -0.22 | N30: =M28+$E30 -> -0.13 | O30: =N28+$E30 -> -0.04
C31: Bear Case | E31: -0.01 | K31: =K30+$E31 -> -0.41 | L31: =L30+$E31 -> -0.32 | M31: =M30+$E31 -> -0.23 | N31: =N30+$E31 -> -0.14 | O31: =O30+$E31 -> -0.05
C33: R&D | F33: ='3FS'!E23 -> -13.593 | G33: ='3FS'!F23 -> -19.154 | H33: ='3FS'!G23 -> -18.469 | I33: ='3FS'!H23 -> -18.708 | J33: ='3FS'!I23 -> -22.758 | K33: =K34*K$12 -> -17.494326 | L33: =L34*L$12 -> -57.730357 | M33: =M34*M$12 -> -82.060881 | N33: =N34*N$12 -> -56.499526 | O33: =O34*O$12 -> 0
C34: %Revenue | F34: =F33/F12 -> -62.068493 | G34: =G33/G12 -> -4.1657242 | H34: =H33/H12 -> -1.0304062 | I34: =I33/I12 -> -1.142264 | J34: =J33/J12 -> -1.4582853 | K34: =_xlfn.XLOOKUP($D$4,$C35:$C37,K35:K37) -> -0.1 | L34: =_xlfn.XLOOKUP($D$4,$C35:$C37,L35:L37) -> -0.075 | M34: =_xlfn.XLOOKUP($D$4,$C35:$C37,M35:M37) -> -0.05 | N34: =_xlfn.XLOOKUP($D$4,$C35:$C37,N35:N37) -> -0.025 | O34: =_xlfn.XLOOKUP($D$4,$C35:$C37,O35:O37) -> 0
C35: Bull Case | E35: 0.005 | K35: =K36+$E35 -> -0.095 | L35: =L36+$E35 -> -0.07 | M35: =M36+$E35 -> -0.045 | N35: =N36+$E35 -> -0.02 | O35: =O36+$E35 -> 0.005
C36: Base Case | E36: 0.025 | K36: -0.1 | L36: =K34+$E36 -> -0.075 | M36: =L34+$E36 -> -0.05 | N36: =M34+$E36 -> -0.025 | O36: =N34+$E36 -> 0
C37: Bear Case | E37: -0.005 | K37: =K36+$E37 -> -0.105 | L37: =L36+$E37 -> -0.08 | M37: =M36+$E37 -> -0.055 | N37: =N36+$E37 -> -0.03 | O37: =O36+$E37 -> -0.005
C39: Other Operating Expenses/(Income) | F39: ='3FS'!E24 -> -0.913 | G39: ='3FS'!F24 -> -0.269 | H39: ='3FS'!G24 -> 0.016 | I39: ='3FS'!H24 -> 0 | J39: ='3FS'!I24 -> 0 | K39: =K40*K$12 -> 0 | L39: =L40*L$12 -> 0 | M39: =M40*M$12 -> 0 | N39: =N40*N$12 -> 0 | O39: =O40*O$12 -> 0
C40: %Revenue | F40: =F39/F12 -> -4.1689498 | G40: =G39/G12 -> -0.058503697 | H40: =H39/H12 -> 0.00089265789 | I40: 0 | J40: 0 | K40: =_xlfn.XLOOKUP($D$4,$C41:$C43,K41:K43) -> 0 | L40: =_xlfn.XLOOKUP($D$4,$C41:$C43,L41:L43) -> 0 | M40: =_xlfn.XLOOKUP($D$4,$C41:$C43,M41:M43) -> 0 | N40: =_xlfn.XLOOKUP($D$4,$C41:$C43,N41:N43) -> 0 | O40: =_xlfn.XLOOKUP($D$4,$C41:$C43,O41:O43) -> 0
C41: Bull Case | E41: 0.01 | K41: =K42+$E$41 -> 0.01 | L41: =L42+$E$41 -> 0.01 | M41: =M42+$E$41 -> 0.01 | N41: =N42+$E$41 -> 0.01 | O41: =O42+$E$41 -> 0.01
C42: Base Case | E42: 0 | K42: =MEDIAN($F$40:$J$40) -> 0 | L42: =K42 -> 0 | M42: =L42 -> 0 | N42: =M42 -> 0 | O42: =N42 -> 0
C43: Bear Case | E43: -0.01 | K43: =K42+$E$43 -> -0.01 | L43: =L42+$E$43 -> -0.01 | M43: =M42+$E$43 -> -0.01 | N43: =N42+$E$43 -> -0.01 | O43: =O42+$E$43 -> -0.01
C45: Non-Operating Expenses
C47: Before Tax Items
C49: Net Interest Expense | F49: ='3FS'!E33 -> -23.821 | G49: ='3FS'!F33 -> -5.201 | H49: ='3FS'!G33 -> -18.813 | I49: ='3FS'!H33 -> -56.236 | J49: ='3FS'!I33 -> -28.217 | K49: =K50*K12 -> -316.31257 | L49: =L50*L12 -> -1391.7532 | M49: =M50*M12 -> -2967.4637 | N49: =N50*N12 -> -4086.2415 | O49: =O50*O12 -> -4599.2525
C50: %Revenue | F50: =F49/F12 -> -108.77169 | G50: =G49/G12 -> -1.131144 | H50: =H49/H12 -> -1.0495983 | I50: =I49/I12 -> -3.4336305 | J50: =J49/J12 -> -1.8080866 | K50: =MEDIAN(F50:J50) -> -1.8080866 | L50: =MEDIAN(G50:K50) -> -1.8080866 | M50: =MEDIAN(H50:L50) -> -1.8080866 | N50: =MEDIAN(I50:M50) -> -1.8080866 | O50: =MEDIAN(J50:N50) -> -1.8080866
C52: Income/(Loss) from Affiliates | F52: ='3FS'!E34 -> 0.077 | G52: ='3FS'!F34 -> 14.436 | H52: ='3FS'!G34 -> 11.251 | I52: ='3FS'!H34 -> -16.792 | J52: ='3FS'!I34 -> -584.734 | K52: =K53*K12 -> 0 | L52: =L53*L12 -> 0 | M52: =M53*M12 -> 0 | N52: =N53*N12 -> 0 | O52: =O53*O12 -> 0
C53: %Revenue | F53: =F52/F12 -> 0.35159817 | G53: =G52/G12 -> 3.1396259 | H53: =H52/H12 -> 0.62770587 | I53: =I52/I12 -> -1.0252778 | J53: =J52/J12 -> -37.468538 | K53: 0 | L53: =K53 -> 0 | M53: =L53 -> 0 | N53: =M53 -> 0 | O53: =N53 -> 0
C55: Asset Writedown | F55: ='3FS'!E35 -> - | G55: ='3FS'!F35 -> -0.1 | H55: ='3FS'!G35 -> -6.8 | I55: ='3FS'!H35 -> -7.2 | J55: ='3FS'!I35 -> -9.1 | K55: =K56*K18 -> 0 | L55: =L56*L18 -> 0 | M55: =M56*M18 -> 0 | N55: =N56*N18 -> 0 | O55: =O56*O18 -> 0
...

Sheet Drivers>
C118: Adjustments:

Sheet Debt & Equity
C1: EOS Energy Enterprises, Inc. (NASDAQ: EOSE)
C3: 12M Target Price
C4: Scenario | G4: =Cover!C11 -> Base Case
H5: Historical (31 Jan) | M5: Forecast (31 Jan)
C6: In USD Mns, unless stated otherwise | H6: 20 | I6: 21 | J6: 22 | K6: 23 | L6: 24 | M6: 25 | N6: 26 | O6: 27 | P6: 28 | Q6: 29
C7: Fiscal year end date | H7: 44227 | I7: 44592 | J7: 44957 | K7: 45322 | L7: 45688 | M7: 46053 | N7: 46418 | O7: 46783 | P7: 47149 | Q7: 47514
A9: 1 | C9: Debt Schedule | H9: 20 | I9: 21 | J9: 22 | K9: 23 | L9: 24 | M9: 25 | N9: 26 | O9: 27 | P9: 28 | Q9: 29
C11: Financial Debt, Current | H11: ='3FS'!E73 -> 0.924 | I11: ='3FS'!F73 -> 6.57 | J11: ='3FS'!G73 -> 5.56 | K11: ='3FS'!H73 -> 3.332 | L11: ='3FS'!I73 -> 2.014 | M11: =-N17 -> 416.87314 | N11: =-O17 -> 76.97381 | O11: =-P17 -> 164.12176 | P11: =-Q17 -> 225.9981 | Q11: =-R17 -> 0
C12: Financial Debt, Non-Current | H12: ='3FS'!E80 -> 0.427 | I12: ='3FS'!F80 -> 102.644 | J12: ='3FS'!G80 -> 170.271 | K12: ='3FS'!H80 -> 200.527 | L12: ='3FS'!I80 -> 314.882 | M12: =M18-M11 -> 0 | N12: =N18-N11 -> 0 | O12: =O18-O11 -> 0 | P12: =P18-P11 -> 0 | Q12: =Q18-Q11 -> 254.37125
C13: Total Debt | H13: =H11+H12 -> 1.351 | I13: =I11+I12 -> 109.214 | J13: =J11+J12 -> 175.831 | K13: =K11+K12 -> 203.859 | L13: =L11+L12 -> 316.896 | M13: =M11+M12 -> 416.87314 | N13: =N11+N12 -> 76.97381 | O13: =O11+O12 -> 164.12176 | ... Q13: =Q11+Q12 -> 254.37125
C15: Total Debt, BOP | M15: =L13 -> 316.896 | N15: =M13 -> 416.87314 | O15: =N13 -> 76.97381 | P15: =O13 -> 164.12176 | Q15: =P13 -> 225.9981 | R15: =Q13 -> 254.37125
C16: (+) Borrowings | M16: =M38+M40 -> 416.87314 | N16: =N38+N40 -> 76.97381 | O16: =O38+O40 -> 164.12176 | P16: =P38+P40 -> 225.9981 | Q16: =Q38+Q40 -> 254.37125 | R16: =R38+R40 -> 0
C17: (-) Repayments | M17: =M39+M50 -> -316.896 | N17: =N39+N50 -> -416.87314 | O17: =O39+O50 -> -76.97381 | P17: =P39+P50 -> -164.12176 | Q17: =Q39+Q50 -> -225.9981 | R17: =R39+R50 -> 0
C18: Total Debt, EOP | M18: =SUM(M15:M17) -> 416.87314 | N18: =SUM(N15:N17) -> 76.97381 | O18: =SUM(O15:O17) -> 164.12176 | P18: =SUM(P15:P17) -> 225.9981 | Q18: =SUM(Q15:Q17) -> 254.37125 | R18: =SUM(R15:R17) -> 254.37125
C20: Revolver Needs Analysis | H20: 20 | I20: 21 | J20: 22 | K20: 23 | L20: 24 | M20: 25 | N20: 26 | O20: 27 | P20: 28 | Q20: 29
C22: CIRCULARITY | F22: off
C24: Revenue | H24: ='3FS'!E13 -> 0.219 | I24: ='3FS'!F13 -> 4.598 | J24: ='3FS'!G13 -> 17.924 | K24: ='3FS'!H13 -> 16.378 | L24: ='3FS'!I13 -> 15.606 | M24: ='3FS'!J13 -> 174.94326 | N24: ='3FS'!K13 -> 769.7381 | O24: ='3FS'!L13 -> 1641.2176 | ... Q24: ='3FS'!N13 -> 2543.7125 | R24: =Q24 -> 2543.7125
C26: Beginning Cash and Equivalents | M26: ='3FS'!I48 -> 74.292 | N26: ='3FS'!J48 -> 32.036765 | O26: ='3FS'!K48 -> 813.55452 | P26: ='3FS'!L48 -> 3188.699 | Q26: ='3FS'!M48 -> 6100.6289 | R26: =Q26 -> 6100.6289
C27: (+) Cash Flow from Operations + Investing | M27: ='3FS'!J125+'3FS'!J132 -> -154.88579 | N27: ='3FS'!K125+'3FS'!K132 -> 1115.5932 | O27: ='3FS'!L125+'3FS'!L132 -> 2276.7908 | P27: ='3FS'!M125+'3FS'!M132 -> 2830.0055 | Q27: ='3FS'!N125+'3FS'!N132 -> 2990.1257 | R27: =Q27 -> 2990.1257
C28: (-) Debt Principal Repayment | M28: =M50 -> -316.896 | N28: =N50 -> 0 | O28: =O50 -> 0 | P28: =P50 -> 0 | Q28: =Q50 -> 0 | R28: =Q28 -> 0
C29: (-) Mandatory Lease Repayments | M29: =Projections!K133 -> -1.8890306 | N29: =Projections!L133 -> -3.9697231 | O29: =Projections!M133 -> -8.0728151 | P29: =Projections!N133 -> -15.668645 | Q29: =Projections!O133 -> -29.7815 | R29: =Q29 -> -29.7815
C30: (-) Dividends | M30: =-M76 -> 0 | N30: =-N76 -> 0 | O30: =-O76 -> 0 | P30: =-P76 -> 0 | Q30: =-Q76 -> 0 | R30: =Q30 -> 0
C31: (-) Minimum Cash Balance | F31: 0.1 | M31: =-$F$31*'Debt & Equity'!M24 -> -17.494326 | N31: =-$F$31*'Debt & Equity'!N24 -> -76.97381 | O31: =-$F$31*'Debt & Equity'!O24 -> -164.12176 | P31: =-$F$31*'Debt & Equity'!P24 -> -225.9981 | Q31: =-$F$31*'Debt & Equity'!Q24 -> -254.37125 | R31: =Q31 -> -254.37125
C32: Cash Surplus/(Required Fundraise) | M32: =IF($F$22="OFF",SUM(M26:M31),0) -> -416.87314 | N32: =IF($F$22="OFF",SUM(N26:N31),0) -> 1066.6864 | O32: =IF($F$22="OFF",SUM(O26:O31),0) -> 2918.1507 | P32: =IF($F$22="OFF",SUM(P26:P31),0) -> 5777.0378 | Q32: =IF($F$22="OFF",SUM(Q26:Q31),0) -> 8806.6018 | R32: =IF($F$22="OFF",SUM(R26:R31),0) -> 8806.6018
C34: Assumptions:
C35: Discretionary Borrowing as % revenue | G35: 0.1
C37: Credit Revolver, BOP | M37: 0 | N37: =M41 -> 416.87314 | O37: =N41 -> 76.97381 | P37: =O41 -> 164.12176 | Q37: =P41 -> 225.9981
C38: (+) Draw | M38: =-MIN(M32,0) -> 416.87314 | N38: =-MIN(N32,0) -> 0 | O38: =-MIN(O32,0) -> 0 | P38: =-MIN(P32,0) -> 0 | Q38: =-MIN(Q32,0) -> 0
C39: (-) Paydown | M39: =IF(M32>0,-MIN(M37,M32),0) -> 0 | N39: =IF(N32>0,-MIN(N37,N32),0) -> -416.87314 | O39: =IF(O32>0,-MIN(O37,O32),0) -> -76.97381 | P39: =IF(P32>0,-MIN(P37,P32),0) -> -164.12176 | Q39: =IF(Q32>0,-MIN(Q37,Q32),0) -> -225.9981
C40: (+) Discretionary Borrowing | M40: =IF($G$35*M$24<SUM(M37:M39),0,$G$35*M$24-SUM(M37:M39)) -> 0 | N40: =IF($G$35*N$24<SUM(N37:N39),0,$G$35*N$24-SUM(N37:N39)) -> 76.97381 | O40: =IF($G$35*O$24<SUM(O37:O39),0,$G$35*O$24-SUM(O37:O39)) -> 164.12176 | P40: =IF($G$35*P$24<SUM(P37:P39),0,$G$35*P$24-SUM(P37:P39)) -> 225.9981 | Q40: =IF($G$35*Q$24<SUM(Q37:Q39),0,$G$35*Q$24-SUM(Q37:Q39)) -> 254.37125
C41: Credit Revolver, EOP | M41: =SUM(M37:M40) -> 416.87314 | N41: =SUM(N37:N40) -> 76.97381 | O41: =SUM(O37:O40) -> 164.12176 | P41: =SUM(P37:P40) -> 225.9981 | Q41: =SUM(Q37:Q40) -> 254.37125
C43: Repayment Schedule
C45: Principal Repayments
C47: Loans from banks | E47: Principal | F47: Effective Rate | G47: Maturity
C48: Financial Debt | E48: =L13 -> 316.896 | F48: 0.068 | G48: 25 | M48: =IF(M$6=$G$48,-E48,0) -> -316.896 | N48: =IF(N$6=$G$48,-F48,0) -> 0 | O48: =IF(O$6=$G$48,-G48,0) -> 0 | P48: =IF(P$6=$G$48,-H48,0) -> 0 | Q48: =IF(Q$6=$G$48,-I48,0) -> 0 | R48: =IF(R$6=$G$48,-J48,0) -> 0
C50: Total Principal Repayments | M50: =SUM(M48) -> -316.896 | N50: =SUM(N48) -> 0 | O50: =SUM(O48) -> 0 | P50: =SUM(P48) -> 0 | Q50: =SUM(Q48) -> 0 | R50: =SUM(R48) -> 0
C52: Interest Schedule
C54: Loans from banks | E54: Principal | F54: Effective Rate | G54: Maturity
C55: Financial Debt | E55: =L13 -> 316.896 | F55: 0.068 | G55: 25 | M55: =IF(M$6=$G$55,-$E$55*$F$55,0) -> -21.548928 | N55: =IF(N$6=$G$55,-$E$55*$F$55,0) -> 0 | O55: =IF(O$6=$G$55,-$E$55*$F$55,0) -> 0 | P55: =IF(P$6=$G$55,-$E$55*$F$55,0) -> 0 | Q55: =IF(Q$6=$G$55,-$E$55*$F$55,0) -> 0
C57: Credit Revolver | E57: Principal | F57: Interest Rate | G57: Maturity
...

Sheet PPE
D1: EOS Energy Enterprises, Inc. (NASDAQ: EOSE)
D3: 12M Target Price
D4: Scenario | E4: =Cover!C11 -> Base Case
H5: Historical | M5: Forecasted
D6: In USD Mns, unless stated otherwise | G6: Units | H6: 20 | I6: =H6+1 -> 21 | J6: =I6+1 -> 22 | K6: =J6+1 -> 23 | L6: =K6+1 -> 24 | M6: =L6+1 -> 25 | N6: =M6+1 -> 26 | O6: =N6+1 -> 27 | P6: =O6+1 -> 28 | Q6: =P6+1 -> 29
B8: 1 | D8: PPE
D10: Property, Plant & Equipment | G10: USD Mns | H10: ='3FS'!E59 -> 5.653 | I10: ='3FS'!F59 -> 16.358 | J10: ='3FS'!G59 -> 31.485 | K10: ='3FS'!H59 -> 41.888 | L10: ='3FS'!I59 -> 48.569 | M10: =SUM(M42,M69) -> 68.43575 | N10: =SUM(N42,N69) -> 127.50239 | O10: =SUM(O42,O69) -> 244.54776 | P10: =SUM(P42,P69) -> 460.98097 | Q10: =SUM(Q42,Q69) -> 861.03025
D11: %yoy | G11: % | I11: =I10/H10-1 -> 1.8936848 | J11: =J10/I10-1 -> 0.9247463 | K11: =K10/J10-1 -> 0.33041131 | L11: =L10/K10-1 -> 0.15949675 | M11: =M10/L10-1 -> 0.40904177 | N11: =N10/M10-1 -> 0.86309622 | O11: =O10/N10-1 -> 0.91798574 | P11: =P10/O10-1 -> 0.88503452 | Q11: =Q10/P10-1 -> 0.8678217
B13: x | D13: Assumptions
D15: Useful Life : | E15: Min | F15: Max | G15: Average
D16: ROU Asset | E16: 5 | F16: 5 | G16: =ROUNDUP(AVERAGE(E16:F16),0) -> 5
D17: Equipment | E17: 5 | F17: 10 | G17: =ROUNDUP(AVERAGE(E17:F17),0) -> 8
D18: Finance Lease | E18: 5 | F18: 5 | G18: =ROUNDUP(AVERAGE(E18:F18),0) -> 5
D19: Furniture | E19: 5 | F19: 10 | G19: =ROUNDUP(AVERAGE(E19:F19),0) -> 8
D20: Leasehold Improvements | E20: 0 | F20: 0 | G20: =ROUNDUP(AVERAGE(E20:F20),0) -> 0
D21: Tooling | E21: 2 | F21: 3 | G21: =ROUNDUP(AVERAGE(E21:F21),0) -> 3
D22: Construction In Progress | E22: 0 | F22: 0 | G22: =ROUNDUP(AVERAGE(E22:F22),0) -> 0
D24: Revenue | G24: USD Mns | H24: ='3FS'!E13 -> 0.219 | I24: ='3FS'!F13 -> 4.598 | J24: ='3FS'!G13 -> 17.924 | K24: ='3FS'!H13 -> 16.378 | L24: ='3FS'!I13 -> 15.606 | M24: ='3FS'!J13 -> 174.94326 | N24: ='3FS'!K13 -> 769.7381 | O24: ='3FS'!L13 -> 1641.2176 | ... Q24: ='3FS'!N13 -> 2543.7125
D25: %yoy | G25: % | I25: =I24/H24-1 -> 19.995434 | J25: =J24/I24-1 -> 2.8982166 | K25: =K24/J24-1 -> -0.086253069 | L25: =L24/K24-1 -> -0.047136402 | M25: =M24/L24-1 -> 10.21 | N25: =N24/M24-1 -> 3.39993 | O25: =O24/N24-1 -> 1.1321767 | P25: =P24/O24-1 -> 0.37701484 | Q25: =Q24/P24-1 -> 0.12554594
D27: Depreciation | G27: USD Mns | H27: ='3FS'!E107 -> 1.558 | I27: ='3FS'!F107 -> 3.537 | J27: ='3FS'!G107 -> 7.679 | K27: ='3FS'!H107 -> 10.731 | L27: ='3FS'!I107 -> 9.082 | M27: ='3FS'!J107 -> 17.06406 | N27: ='3FS'!K107 -> 33.537227 | O27: ='3FS'!L107 -> 66.134868 | ... Q27: ='3FS'!N107 -> 227.47523
D29: PPE CapEx | G29: USD Mns | H29: 3.605 | I29: 15.589 | J29: 20.072 | K29: 29.323 | L29: 33.152 | M29: =M27/M30 -> 46.628408 | N29: =N27/N30 -> 91.642169 | O29: =O27/O30 -> 180.71687 | P29: =P27/P30 -> 334.55128 | Q29: =Q27/Q30 -> 621.58758
D30: Depreciation/Capex Ratio | G30: % | H30: =H27/H29 -> 0.43217753 | I30: =I27/I29 -> 0.22689076 | J30: =J27/J29 -> 0.38257274 | K30: =K27/K29 -> 0.36595846 | L30: =L27/L29 -> 0.27395029 | M30: =MEDIAN($H$30:$L$30) -> 0.36595846 | N30: =M30 -> 0.36595846 | O30: =N30 -> 0.36595846 | P30: =O30 -> 0.36595846 | Q30: =P30 -> 0.36595846
B32: x | D32: Capex Schedule and Allocation
D34: COST ALLOCATION:
D35: ROU Asset | H35: 0 | I35: 3.468 | J35: 4.316 | K35: 4.033 | L35: 2.909 | M35: =L35+M45 -> 7.4925138 | N35: =M35+N45 -> 16.500824 | O35: =N35+O45 -> 34.265065 | P35: =O35+P45 -> 67.151035 | Q35: =P35+Q45 -> 128.25231
D36: Equipment | G36: USD Mns | H36: 7.055 | I36: 13.489 | J36: 23.653 | K36: 20.559 | L36: 51.874 | M36: =L36+M46 -> 91.903486 | N36: =M36+N46 -> 170.57632 | O36: =N36+O46 -> 325.71787 | P36: =O36+P46 -> 612.92296 | Q36: =P36+Q46 -> 1146.5425
D37: Finance Lease | G37: USD Mns | H37: 0.201 | I37: 0.226 | J37: 0.379 | K37: 0.504 | L37: 0.504 | M37: =L37+M47 -> 0.74391515 | N37: =M37+N47 -> 1.2154377 | O37: =N37+O47 -> 2.1452725 | P37: =O37+P47 -> 3.8666249 | Q37: =P37+Q47 -> 7.0648529
D38: Furniture | G38: USD Mns | H38: 0.211 | I38: 0.808 | J38: 1.868 | K38: 2.103 | L38: 2.369 | M38: =L38+M48 -> 4.4140125 | N38: =M38+N48 -> 8.4332229 | O38: =N38+O48 -> 16.359041 | P38: =O38+P48 -> 31.031675 | Q38: =P38+Q48 -> 58.293047
D39: Leasehold Improvements | G39: USD Mns | H39: 2.732 | I39: 2.933 | J39: 6.303 | K39: 7.718 | L39: 9.674 | M39: =L39+M50 -> 15.072066 | N39: =M39+N50 -> 25.681274 | O39: =N39+O50 -> 46.602459 | P39: =O39+P50 -> 85.332708 | Q39: =P39+Q50 -> 157.2925
D40: Tooling | H40: 2.732 | I40: 3.053 | J40: 6.926 | K40: 7.045 | L40: 9.955
D41: Construction In Progress | G41: USD Mns | H41: 2.732 | I41: 0 | J41: 0 | K41: 17.958 | L41: 0 | M41: =L41+M51 -> -5.6675857 | N41: =M41+N51 -> -16.8065 | O41: =N41+O51 -> -38.772259 | P41: =O41+P51 -> -79.436269 | Q41: =P41+Q51 -> -154.98894
D42: PPE, gross | G42: USD Mns | H42: =SUM(H35:H41) -> 15.663 | I42: =SUM(I35:I41) -> 23.977 | J42: =SUM(J35:J41) -> 43.445 | K42: =SUM(K35:K41) -> 59.92 | L42: =SUM(L35:L41) -> 77.285 | M42: =SUM(M35:M41) -> 113.95841 | N42: =SUM(N35:N41) -> 205.60058 | O42: =SUM(O35:O41) -> 386.31745 | ... Q42: =SUM(Q35:Q41) -> 1342.4563
D44: PPE NET ADDITIONS:
D45: ROU Asset | I45: =I35-H35 -> 3.468 | J45: =J35-I35 -> 0.848 | K45: =K35-J35 -> -0.283 | L45: =L35-K35 -> -1.124 | M45: =M55*$M$29 -> 4.5835138 | N45: =$N$29*N55 -> 9.0083099 | O45: =$O$29*O55 -> 17.764241 | P45: =P55*$P$29 -> 32.88597 | Q45: =$Q$29*Q55 -> 61.101277
D46: Equipment | G46: USD Mns | I46: =I36-H36 -> 6.434 | J46: =J36-I36 -> 10.164 | K46: =K36-J36 -> -3.094 | L46: =L36-K36 -> 31.315 | M46: =M56*$M$29 -> 40.029486 | N46: =$N$29*N56 -> 78.672833 | O46: =$O$29*O56 -> 155.14155 | P46: =P56*$P$29 -> 287.20509 | Q46: =$Q$29*Q56 -> 533.61958
D47: Finance Lease | G47: USD Mns | I47: =I37-H37 -> 0.025 | J47: =J37-I37 -> 0.153 | K47: =K37-J37 -> 0.125 | L47: =L37-K37 -> 0 | M47: =M57*$M$29 -> 0.23991515 | N47: =$N$29*N57 -> 0.47152253 | O47: =$O$29*O57 -> 0.92983478 | P47: =P57*$P$29 -> 1.7213524 | Q47: =$Q$29*Q57 -> 3.198228
D48: Furniture | G48: USD Mns | I48: =I38-H38 -> 0.597 | J48: =J38-I38 -> 1.06 | K48: =K38-J38 -> 0.235 | L48: =L38-K38 -> 0.266 | M48: =M59*$M$29 -> 2.0450125 | N48: =$N$29*N59 -> 4.0192104 | O48: =$O$29*O59 -> 7.9258177 | P48: =P59*$P$29 -> 14.672634 | Q48: =$Q$29*Q59 -> 27.261372
D49: Leasehold Improvements
D50: Tooling | G50: USD Mns | I50: =I39-H39 -> 0.201 | J50: =J39-I39 -> 3.37 | K50: =K39-J39 -> 1.415 | L50: =L39-K39 -> 1.956 | M50: =M60*$M$29 -> 5.3980658 | N50: =$N$29*N60 -> 10.609208 | O50: =$O$29*O60 -> 20.921185 | P50: =P60*$P$29 -> 38.730249 | Q50: =$Q$29*Q60 -> 71.959795
D51: Construction In Progress | G51: USD Mns | I51: =I41-H41 -> -2.732 | J51: =J41-I41 -> 0 | K51: =K41-J41 -> 17.958 | L51: =L41-K41 -> -17.958 | M51: =M29*M61 -> -5.6675857 | N51: =N29*N61 -> -11.138915 | O51: =O29*O61 -> -21.965759 | P51: =P29*P61 -> -40.664011 | Q51: =Q29*Q61 -> -75.552674
...

Sheet Intangibles
D1: EOS Energy Enterprises, Inc. (NASDAQ: EOSE)
D3: 12M Target Price
D4: Scenario | E4: =Cover!C11 -> Base Case
H5: Historical | M5: Forecasted
D6: In USD Mns, unless stated otherwise | G6: Units | H6: 20 | I6: =H6+1 -> 21 | J6: =I6+1 -> 22 | K6: =J6+1 -> 23 | L6: =K6+1 -> 24 | M6: =L6+1 -> 25 | N6: =M6+1 -> 26 | O6: =N6+1 -> 27 | P6: =O6+1 -> 28 | Q6: =P6+1 -> 29
B8: 1 | D8: Intangibles
B10: 1 | D10: Intangibles | G10: USD Mns | H10: ='3FS'!E62 -> 0.32 | I10: ='3FS'!F62 -> 0.28 | J10: ='3FS'!G62 -> 0.24 | K10: ='3FS'!H62 -> 0.295 | L10: ='3FS'!I62 -> 0.24 | M10: =M31+M48 -> 0.84480468 | N10: =N31+N48 -> 1.9959872 | O10: =O31+O48 -> 4.0376442 | P10: =P31+P48 -> 5.9273359 | Q10: =Q31+Q48 -> 6.9727053
D11: %yoy | G11: % | I11: =I10/H10-1 -> -0.125 | J11: =J10/I10-1 -> -0.14285714 | K11: =K10/J10-1 -> 0.22916667 | L11: =L10/K10-1 -> -0.18644068 | M11: =M10/L10-1 -> 2.5200195 | N11: =N10/M10-1 -> 1.3626611 | O11: =O10/N10-1 -> 1.0228808 | P11: =P10/O10-1 -> 0.46801837 | Q11: =Q10/P10-1 -> 0.17636413
B13: x | D13: Assumptions
D15: Useful Life : | E15: Min | F15: Max | G15: Average
D16: Patent | E16: 10 | F16: 10 | G16: 10
D17: Software | E17: 3 | F17: 3 | G17: 3
E18: 3 | F18: 3 | G18: =AVERAGE(E18:F18) -> 3
D20: Revenue | G20: USD Mns | H20: ='3FS'!E13 -> 0.219 | I20: ='3FS'!F13 -> 4.598 | J20: ='3FS'!G13 -> 17.924 | K20: ='3FS'!H13 -> 16.378 | L20: ='3FS'!I13 -> 15.606 | M20: ='3FS'!J13 -> 174.94326 | N20: ='3FS'!K13 -> 769.7381 | O20: ='3FS'!L13 -> 1641.2176 | ... Q20: ='3FS'!N13 -> 2543.7125
D21: %yoy | G21: % | I21: =I20/H20-1 -> 19.995434 | J21: =J20/I20-1 -> 2.8982166 | K21: =K20/J20-1 -> -0.086253069 | L21: =L20/K20-1 -> -0.047136402 | M21: =M20/L20-1 -> 10.21 | N21: =N20/M20-1 -> 3.39993 | O21: =O20/N20-1 -> 1.1321767 | P21: =P20/O20-1 -> 0.37701484 | Q21: =Q20/P20-1 -> 0.12554594
B23: 2 | D23: Addition to Intangible Assets | G23: USD Mns | I23: =I36 -> 0 | J23: =J36 -> 0 | K23: =K36 -> 0.0138 | L23: =L36 -> 0.1582 | M23: =M20*M24 -> 0.48020702 | N23: =N20*N24 -> 2.1128773 | O23: =O20*O24 -> 4.5050277 | P23: =P20*P24 -> 6.20349 | Q23: =Q20*Q24 -> 6.982313
D24: % Revenue | I24: =I23/I20 -> 0 | J24: =J23/J20 -> 0 | K24: =K23/K20 -> 0.00084259372 | L24: =L23/L20 -> 0.010137127 | M24: =AVERAGE(I24:L24) -> 0.0027449301 | N24: =M24 -> 0.0027449301 | O24: =N24 -> 0.0027449301 | P24: =O24 -> 0.0027449301 | Q24: =P24 -> 0.0027449301
D26: CAPEX Schedule and Allocation
D28: Cost Allocation
D29: Trademark | H29: 0.4 | I29: 0.4 | J29: 0.4 | K29: 0.4 | L29: 0.4 | M29: =L29+M34 -> 0.4 | N29: =M29+N34 -> 0.4 | O29: =N29+O34 -> 0.4 | P29: =O29+P34 -> 0.4 | Q29: =P29+Q34 -> 0.4
D30: Non-Compete Agreement | H30: 0 | I30: 0 | J30: 0 | K30: 0.0138 | L30: 0.172 | M30: =L30+M35 -> 0.65220702 | N30: =M30+N35 -> 2.7650843 | O30: =N30+O35 -> 7.270112 | P30: =O30+P35 -> 13.473602 | Q30: =P30+Q35 -> 20.455915
D31: Intangible Assets, Gross | H31: =SUM(H29:H30) -> 0.4 | I31: =SUM(I29:I30) -> 0.4 | J31: =SUM(J29:J30) -> 0.4 | K31: =SUM(K29:K30) -> 0.4138 | L31: =SUM(L29:L30) -> 0.572 | M31: =SUM(M29:M30) -> 1.052207 | N31: =SUM(N29:N30) -> 3.1650843 | O31: =SUM(O29:O30) -> 7.670112 | ... Q31: =SUM(Q29:Q30) -> 20.855915
D33: Net Addition
D34: Trademark | I34: =I29-H29 -> 0 | J34: =J29-I29 -> 0 | K34: =K29-J29 -> 0 | L34: =L29-K29 -> 0 | M34: =M$23*M39 -> 0 | N34: =N$23*N39 -> 0 | O34: =O$23*O39 -> 0 | P34: =P$23*P39 -> 0 | Q34: =Q$23*Q39 -> 0
D35: Non-Compete Agreement | I35: =I30-H30 -> 0 | J35: =J30-I30 -> 0 | K35: =K30-J30 -> 0.0138 | L35: =L30-K30 -> 0.1582 | M35: =M$23*M40 -> 0.48020702 | N35: =N$23*N40 -> 2.1128773 | O35: =O$23*O40 -> 4.5050277 | P35: =P$23*P40 -> 6.20349 | Q35: =Q$23*Q40 -> 6.982313
D36: Total Net Addition | I36: =SUM(I34:I35) -> 0 | J36: =SUM(J34:J35) -> 0 | K36: =SUM(K34:K35) -> 0.0138 | L36: =SUM(L34:L35) -> 0.1582 | M36: =SUM(M34:M35) -> 0.48020702 | N36: =SUM(N34:N35) -> 2.1128773 | O36: =SUM(O34:O35) -> 4.5050277 | P36: =SUM(P34:P35) -> 6.20349 | Q36: =SUM(Q34:Q35) -> 6.982313
D38: % of Addition
D39: Trademark | K39: =K34/K$36 -> 0 | L39: =L34/L$36 -> 0 | M39: =AVERAGE(I39:L39) -> 0 | N39: =M39 -> 0 | O39: =N39 -> 0 | P39: =O39 -> 0 | Q39: =P39 -> 0
D40: Non-Compete Agreement | K40: =K35/K$36 -> 1 | L40: =L35/L$36 -> 1 | M40: =AVERAGE(I40:L40) -> 1 | N40: =M40 -> 1 | O40: =N40 -> 1 | P40: =O40 -> 1 | Q40: =P40 -> 1
D41: Total (%) | I41: =SUM(I39:I40) -> 0 | J41: =SUM(J39:J40) -> 0 | K41: =SUM(K39:K40) -> 1 | L41: =SUM(L39:L40) -> 1 | M41: =SUM(M39:M40) -> 1 | N41: =SUM(N39:N40) -> 1 | O41: =SUM(O39:O40) -> 1 | P41: =SUM(P39:P40) -> 1 | Q41: =SUM(Q39:Q40) -> 1
D43: Depreciation Schedule
D45: Total Amortization
D46: Beginning Accumulated Amortization | M46: =L48 -> 0.05 | N46: =M48 -> -0.20740234 | O46: =N48 -> -1.1690971 | P46: =O48 -> -3.6324678 | Q46: =P48 -> -7.9462661
D47: (+) Amortization | M47: =SUM(M66,M84) -> -0.25740234 | N47: =SUM(N66,N84) -> -0.96169477 | O47: =SUM(O66,O84) -> -2.4633707 | P47: =SUM(P66,P84) -> -4.3137983 | Q47: =SUM(Q66,Q84) -> -5.9369436
D48: Ending Accumulated Amortization | L48: 0.05 | M48: =SUM(M46:M47) -> -0.20740234 | N48: =SUM(N46:N47) -> -1.1690971 | O48: =SUM(O46:O47) -> -3.6324678 | P48: =SUM(P46:P47) -> -7.9462661 | Q48: =SUM(Q46:Q47) -> -13.88321
D50: Patent
D52: Useful Life | G52: =G16 -> 10
D54: Beginning Balance | M54: =L29 -> 0.4 | N54: =M29 -> 0.4 | O54: =N29 -> 0.4 | P54: =O29 -> 0.4 | Q54: =P29 -> 0.4
D55: (+) Additions | M55: =M34 -> 0 | N55: =N34 -> 0 | O55: =O34 -> 0 | P55: =P34 -> 0 | Q55: =Q34 -> 0
D56: (-) Depreciation | M56: =M66 -> -0.04 | N56: =N66 -> -0.04 | O56: =O66 -> -0.04 | P56: =P66 -> -0.04 | Q56: =Q66 -> -0.04
...

Sheet Revenue Build
D2: EOS Energy Enterprises, Inc. (NASDAQ: EOSE)
D4: 12M Target Price
D5: Scenario | F5: =Cover!C11 -> Base Case
G6: Historical | L6: Forecasted
D7: In USD Mns, unless stated otherwise | F7: Units | G7: 20 | H7: =G7+1 -> 21 | I7: =H7+1 -> 22 | J7: =I7+1 -> 23 | K7: =J7+1 -> 24 | L7: =K7+1 -> 25 | M7: =L7+1 -> 26 | N7: =M7+1 -> 27 | O7: =N7+1 -> 28 | P7: =O7+1 -> 29
B9: 1 | D9: Live Case
D11: Revenue Segments
D12: Product | F12: USD Mns | G12: 0.184 | H12: 4.562 | I12: 17.429 | J12: 16.151 | K12: 14.503 | L12: =L24 -> 162.57863 | M12: =M24 -> 715.33459 | N12: =N24 -> 1525.2197 | O12: =O24 -> 2100.2502 | P12: =P24 -> 2363.9281
D13: Service | F13: USD Mns | G13: 0.035 | H13: 0.036 | I13: 0.495 | J13: 0.227 | K13: 1.103 | L13: =L31 -> 12.36463 | M13: =M31 -> 54.403506 | N13: =N31 -> 115.99789 | O13: =O31 -> 159.73081 | P13: =P31 -> 179.78437
D14: Total Revenue | F14: USD Mns | G14: =SUM(G12:G13) -> 0.219 | H14: =SUM(H12:H13) -> 4.598 | I14: =SUM(I12:I13) -> 17.924 | J14: =SUM(J12:J13) -> 16.378 | K14: =SUM(K12:K13) -> 15.606 | L14: =SUM(L12:L13) -> 174.94326 | M14: =SUM(M12:M13) -> 769.7381 | N14: =SUM(N12:N13) -> 1641.2176 | ... P14: =SUM(P12:P13) -> 2543.7125
D15: %yoy | F15: % | H15: =H14/G14-1 -> 19.995434 | I15: =I14/H14-1 -> 2.8982166 | J15: =J14/I14-1 -> -0.086253069 | K15: =K14/J14-1 -> -0.047136402 | L15: =L14/K14-1 -> 10.21 | M15: =M14/L14-1 -> 3.39993 | N15: =N14/M14-1 -> 1.1321767 | O15: =O14/N14-1 -> 0.37701484 | P15: =P14/O14-1 -> 0.12554594
B17: 2 | D17: Assumptions
D19: Revenue Per Segment Growth Rate
D20: Product | F20: % | H20: =(H12-G12)/G12 -> 23.793478 | I20: =(I12-H12)/H12 -> 2.8204735 | J20: =(J12-I12)/I12 -> -0.073326066 | K20: =(K12-J12)/J12 -> -0.10203703 | L20: =(L12-K12)/K12 -> 10.21 | M20: =(M12-L12)/L12 -> 3.39993 | N20: =(N12-M12)/M12 -> 1.1321767 | O20: =(O12-N12)/N12 -> 0.37701484 | P20: =(P12-O12)/O12 -> 0.12554594
D21: Service | F21: % | H21: =(H13-G13)/G13 -> 0.028571429 | I21: =(I13-H13)/H13 -> 12.75 | J21: =(J13-I13)/I13 -> -0.54141414 | K21: =(K13-J13)/J13 -> 3.8590308 | L21: =(L13-K13)/K13 -> 10.21 | M21: =(M13-L13)/L13 -> 3.39993 | N21: =(N13-M13)/M13 -> 1.1321767 | O21: =(O13-N13)/N13 -> 0.37701484 | P21: =(P13-O13)/O13 -> 0.12554594
B23: 3 | D23: Product Revenue Breakdown
D24: Revenue | F24: USD Mns | G24: =G12 -> 0.184 | H24: =H12 -> 4.562 | I24: =I12 -> 17.429 | J24: =J12 -> 16.151 | K24: =K12 -> 14.503 | L24: =(1+L25)*K24 -> 162.57863 | M24: =(1+M25)*L24 -> 715.33459 | N24: =(1+N25)*M24 -> 1525.2197 | O24: =(1+O25)*N24 -> 2100.2502 | P24: =(1+P25)*O24 -> 2363.9281
D25: %yoy | F25: % | H25: =(H24-G24)/G24 -> 23.793478 | I25: =(I24-H24)/H24 -> 2.8204735 | J25: =(J24-I24)/I24 -> -0.073326066 | K25: =(K24-J24)/J24 -> -0.10203703 | L25: =_xlfn.XLOOKUP($F$5, $D26:$D28, L26:L28) -> 10.21 | M25: =_xlfn.XLOOKUP($F$5, $D26:$D28, M26:M28) -> 3.39993 | N25: =_xlfn.XLOOKUP($F$5, $D26:$D28, N26:N28) -> 1.1321767 | O25: =_xlfn.XLOOKUP($F$5, $D26:$D28, O26:O28) -> 0.37701484 | P25: =_xlfn.XLOOKUP($F$5, $D26:$D28, P26:P28) -> 0.12554594
D26: Bull Case | E26: 0.143 | L26: =L27+$E$26 -> 10.353 | M26: =M27+$E$26 -> 3.54293 | N26: =N27+$E$26 -> 1.2751767 | O26: =O27+$E$26 -> 0.52001484 | P26: =P27+$E$26 -> 0.26854594
D27: Base Case | E27: 0.667 | L27: 10.21 | M27: =L27*(1-$E$27) -> 3.39993 | N27: =M27*(1-$E$27) -> 1.1321767 | O27: =N27*(1-$E$27) -> 0.37701484 | P27: =O27*(1-$E$27) -> 0.12554594
D28: Bear Case | E28: -0.143 | L28: =L27+$E$28 -> 10.067 | M28: =M27+$E$28 -> 3.25693 | N28: =N27+$E$28 -> 0.98917669 | O28: =O27+$E$28 -> 0.23401484 | P28: =P27+$E$28 -> -0.017454059
B30: 4 | D30: Service Revenue Breakdown
D31: Revenue | F31: USD Mns | G31: =G13 -> 0.035 | H31: =H13 -> 0.036 | I31: =I13 -> 0.495 | J31: =J13 -> 0.227 | K31: =K13 -> 1.103 | L31: =(1+L32)*K31 -> 12.36463 | M31: =(1+M32)*L31 -> 54.403506 | N31: =(1+N32)*M31 -> 115.99789 | O31: =(1+O32)*N31 -> 159.73081 | P31: =(1+P32)*O31 -> 179.78437
D32: %yoy | F32: % | H32: =(H31-G31)/G31 -> 0.028571429 | I32: =(I31-H31)/H31 -> 12.75 | J32: =(J31-I31)/I31 -> -0.54141414 | K32: =(K31-J31)/J31 -> 3.8590308 | L32: =_xlfn.XLOOKUP($F$5, $D33:$D35, L33:L35) -> 10.21 | M32: =_xlfn.XLOOKUP($F$5, $D33:$D35, M33:M35) -> 3.39993 | N32: =_xlfn.XLOOKUP($F$5, $D33:$D35, N33:N35) -> 1.1321767 | O32: =_xlfn.XLOOKUP($F$5, $D33:$D35, O33:O35) -> 0.37701484 | P32: =_xlfn.XLOOKUP($F$5, $D33:$D35, P33:P35) -> 0.12554594
D33: Bull Case | E33: 0.143 | L33: =L34+$E$33 -> 10.353 | M33: =M34+$E$26 -> 3.54293 | N33: =N34+$E$26 -> 1.2751767 | O33: =O34+$E$26 -> 0.52001484 | P33: =P34+$E$26 -> 0.26854594
D34: Base Case | E34: 0.667 | L34: 10.21 | M34: =L34*(1-$E$34) -> 3.39993 | N34: =M34*(1-$E$34) -> 1.1321767 | O34: =N34*(1-$E$34) -> 0.37701484 | P34: =O34*(1-$E$34) -> 0.12554594
D35: Bear Case | E35: -0.143 | L35: =L34+$E$35 -> 10.067 | M35: =M34+$E$35 -> 3.25693 | N35: =N34+$E$35 -> 0.98917669 | O35: =O34+$E$35 -> 0.23401484 | P35: =P34+$E$35 -> -0.017454059
C99: Adjustments:

Sheet References>

Sheet For Graphs
D2: EOS Energy Enterprises, Inc. (NASDAQ: EOSE) | S2: EOS Energy Enterprises, Inc. (NASDAQ: EOSE)
D4: 12M Target Price | S4: 12M Target Price
D5: Scenario | E5: =Cover!C11 -> Base Case | S5: Scenario | T5: =Cover!R11 -> 0
F6: Historical | K6: Forecasted | U6: Historical | Z6: Forecasted
E7: Units | F7: 20 | G7: =F7+1 -> 21 | H7: =G7+1 -> 22 | I7: =H7+1 -> 23 | J7: =I7+1 -> 24 | K7: =J7+1 -> 25 | L7: =K7+1 -> 26 | M7: =L7+1 -> 27 | N7: =M7+1 -> 28 | O7: =N7+1 -> 29 | T7: Units | U7: 20 | V7: =U7+1 -> 21 | W7: =V7+1 -> 22 | X7: =W7+1 -> 23 | Y7: =X7+1 -> 24 | Z7: =Y7+1 -> 25 | AA7: =Z7+1 -> 26 | AB7: =AA7+1 -> 27 | AC7: =AB7+1 -> 28 | AD7: =AC7+1 -> 29
B9: 1 | D9: Live Case | Q9: 1 | S9: Live Case
D11: Total Revenue | F11: ='3FS'!E13 -> 0.219 | G11: ='3FS'!F13 -> 4.598 | H11: ='3FS'!G13 -> 17.924 | I11: ='3FS'!H13 -> 16.378 | J11: ='3FS'!I13 -> 15.606 | K11: ='3FS'!J13 -> 174.94326 | L11: ='3FS'!K13 -> 769.7381 | M11: ='3FS'!L13 -> 1641.2176 | ... O11: ='3FS'!N13 -> 2543.7125 | S11: Total Revenue | U11: ='3FS'!E13 -> 0.219 | V11: ='3FS'!F13 -> 4.598 | W11: ='3FS'!G13 -> 17.924 | X11: ='3FS'!H13 -> 16.378 | Y11: ='3FS'!I13 -> 15.606 | Z11: ='3FS'!J13 -> 174.94326 | AA11: ='3FS'!K13 -> 769.7381 | AB11: ='3FS'!L13 -> 1641.2176 | ... AD11: ='3FS'!N13 -> 2543.7125
D12: %YoY | G12: =(G11-F11)/F11 -> 19.995434 | H12: =(H11-G11)/G11 -> 2.8982166 | I12: =(I11-H11)/H11 -> -0.086253069 | J12: =(J11-I11)/I11 -> -0.047136402 | K12: =(K11-J11)/J11 -> 10.21 | L12: =(L11-K11)/K11 -> 3.39993 | M12: =(M11-L11)/L11 -> 1.1321767 | N12: =(N11-M11)/M11 -> 0.37701484 | O12: =(O11-N11)/N11 -> 0.12554594 | S12: Gross Profit | U12: ='3FS'!E17 -> -5.29 | V12: ='3FS'!F17 -> -41.885 | W12: ='3FS'!G17 -> -135.336 | X12: ='3FS'!H17 -> -73.42 | Y12: ='3FS'!I17 -> -83.261 | Z12: ='3FS'!J17 -> 69.977304 | AA12: ='3FS'!K17 -> 327.13869 | AB12: ='3FS'!L17 -> 738.54793 | ... AD12: ='3FS'!N17 -> 1271.8562
D13: Gross Profit | F13: ='3FS'!E17 -> -5.29 | G13: ='3FS'!F17 -> -41.885 | H13: ='3FS'!G17 -> -135.336 | I13: ='3FS'!H17 -> -73.42 | J13: ='3FS'!I17 -> -83.261 | K13: ='3FS'!J17 -> 69.977304 | L13: ='3FS'!K17 -> 327.13869 | M13: ='3FS'!L17 -> 738.54793 | ... O13: ='3FS'!N17 -> 1271.8562 | S13: EBITDA | U13: ='3FS'!E29 -> 0 | V13: ='3FS'!F29 -> -101.693 | W13: ='3FS'!G29 -> -207.598 | X13: ='3FS'!H29 -> -136.07 | Y13: ='3FS'!I29 -> -158.217 | Z13: ='3FS'!J29 -> -0.43026561 | AA13: ='3FS'!K29 -> 64.326751 | AB13: ='3FS'!L29 -> 361.55404 | ... AD13: ='3FS'!N29 -> 1397.583
D14: %Revenue | F14: =F13/F$11 -> -24.155251 | G14: =G13/G$11 -> -9.1093954 | H14: =H13/H$11 -> -7.5505468 | I14: =I13/I$11 -> -4.4828428 | J14: =J13/J$11 -> -5.3351916 | K14: =K13/K$11 -> 0.4 | L14: =L13/L$11 -> 0.425 | M14: =M13/M$11 -> 0.45 | ... O14: =O13/O$11 -> 0.5 | S14: Operating Income (EBIT) | U14: ='3FS'!E26 -> -37.417 | V14: ='3FS'!F26 -> -104.306 | W14: ='3FS'!G26 -> -214.412 | X14: ='3FS'!H26 -> -145.778 | Y14: ='3FS'!I26 -> -166.066 | Z14: ='3FS'!J26 -> -17.494326 | AA14: ='3FS'!K26 -> 30.789524 | AB14: ='3FS'!L26 -> 295.41917 | ... AD14: ='3FS'!N26 -> 1170.1077
D15: EBITDA | F15: ='3FS'!E29 -> 0 | G15: ='3FS'!F29 -> -101.693 | H15: ='3FS'!G29 -> -207.598 | I15: ='3FS'!H29 -> -136.07 | J15: ='3FS'!I29 -> -158.217 | K15: ='3FS'!J29 -> -0.43026561 | L15: ='3FS'!K29 -> 64.326751 | M15: ='3FS'!L29 -> 361.55404 | ... O15: ='3FS'!N29 -> 1397.583 | S15: Net Income/(Loss) | U15: ='3FS'!E40 -> -70.643 | V15: ='3FS'!F40 -> -124.266 | W15: ='3FS'!G40 -> -229.767 | X15: ='3FS'!H40 -> -229.547 | Y15: ='3FS'!I40 -> -685.837 | Z15: ='3FS'!J40 -> -39.453388 | AA15: ='3FS'!K40 -> 9.1608114 | AB15: ='3FS'!L40 -> 290.06504 | ... AD15: ='3FS'!N40 -> 1153.5993
D16: %Revenue | F16: =F15/F$11 -> 0 | G16: =G15/G$11 -> -22.11679 | H16: =H15/H$11 -> -11.582125 | I16: =I15/I$11 -> -8.3080962 | J16: =J15/J$11 -> -10.138216 | K16: =K15/K$11 -> -0.0024594581 | L16: =L15/L$11 -> 0.08356966 | M16: =M15/M$11 -> 0.22029622 | ... O16: =O15/O$11 -> 0.54942647
