Workbook
Name BoxPlot: "BoxPlot"
Name Bubble: "Bubble"
Name Candlestick: "Candlestick"
Name Chart: "Chart"
Name ChartImage: "ChartImage"
Name ColumnRange: "ColumnRange"
Name DB: "WIREHKPROD"
Name Dumbbell: "Dumbbell"
Name Heatmap: "Heatmap"
Name Histogram: "Histogram"
Name LastActual: Summary!$C$7
Name Map: "Map"
Name OHLC: "OHLC"
Name PieChart: "PieChart"
Name Scatter: "Scatter"
Name Series: "Series"
Name Stripe: "Stripe"
Name Table: "Table"
Name Template.WIRE.DBAccess.CalcMode: "Async"
Name TreeMap: "TreeMap"
Name Waterfall: "Waterfall"

Sheet Legend
B2: Owner: | D2: Odyssey Capital - In Gyu Song
B4: Legend
B5: BLUE | D5: Hardcode / Historicals
B6: BLUE | D6: Assumptions
B7: RED | D7: Core assumptions
B8: GREEN | D8: Links to other sheet
B9: BLACK | D9: Formula
B10: PURPLE | D10: External data

Sheet Summary
B2: Name | C2: Nitto Boseki | D2: Recommendation
B3: Ticker | C3: TYO: 3110 | D3: SELL
B5: Valuation Date | C5: =TODAY() -> 46313 | D5: Stock Price | E5: 2989
B6: FY26 Ending | C6: 46112 | D6: Target Price | E6: =Valuation!Q17 -> 2391.6398
B7: Last quarter-end | C7: 46203 | D7: Upside | E7: =(E6-E5)/E5 -> -0.19985286
B8: Unit | C8: JPY M | D8: Time Horizon | E8: 1 year
B9: Case | C9: 2 | D9: IRR
B13: Thesis

Sheet 3FS
A1: =Summary!C2 -> Nitto Boseki
A2: =Summary!C3 -> TYO: 3110 | F2: Case | G2: =Summary!C9 -> 2
B4: FQ | H4: A | I4: A | J4: A | K4: A | L4: A | M4: A | N4: A | O4: A | P4: E | Q4: E | R4: E | S4: E | T4: E | Y4: 1 | Z4: 2 | AA4: 3 | AB4: 4 | AC4: =Y4 -> 1 | AD4: =Z4 -> 2 | AE4: =AA4 -> 3 | AF4: =AB4 -> 4 | AG4: =AC4 -> 1 | AH4: =AD4 -> 2 | AI4: =AE4 -> 3 | AJ4: =AF4 -> 4 | ... BX4: =BT4 -> 4
B5: FY | H5: 2019 | I5: =H5+1 -> 2020 | J5: =I5+1 -> 2021 | K5: =J5+1 -> 2022 | L5: =K5+1 -> 2023 | M5: =L5+1 -> 2024 | N5: =M5+1 -> 2025 | O5: =N5+1 -> 2026 | P5: =O5+1 -> 2027 | ... T5: =S5+1 -> 2031 | Y5: 2019 | Z5: 2019 | AA5: 2019 | AB5: 2019 | AC5: =Y5+1 -> 2020 | AD5: =Z5+1 -> 2020 | AE5: =AA5+1 -> 2020 | AF5: =AB5+1 -> 2020 | AG5: =AC5+1 -> 2021 | AH5: =AD5+1 -> 2021 | AI5: =AE5+1 -> 2021 | AJ5: =AF5+1 -> 2021 | ... BX5: =BT5+1 -> 2031
B6: FY End | G6: Units | H6: 43555 | I6: =EOMONTH(J6,-12) -> 43921 | J6: =EOMONTH(K6,-12) -> 44286 | K6: =EOMONTH(L6,-12) -> 44651 | L6: =EOMONTH(M6,-12) -> 45016 | M6: =EOMONTH(N6,-12) -> 45382 | N6: =EOMONTH(O6,-12) -> 45747 | O6: =Summary!$C$6 -> 46112 | P6: =EOMONTH(O6,12) -> 46477 | Q6: =EOMONTH(P6,12) -> 46843 | R6: =EOMONTH(Q6,12) -> 47208 | S6: =EOMONTH(R6,12) -> 47573 | T6: =EOMONTH(S6,12) -> 47938 | Y6: 43281 | Z6: 43373 | AA6: 43465 | AB6: 43555 | AC6: =EOMONTH(AD6,-3) -> 43646 | AD6: =EOMONTH(AE6,-3) -> 43738 | AE6: =EOMONTH(AF6,-3) -> 43830 | AF6: =EOMONTH(AG6,-3) -> 43921 | AG6: =EOMONTH(AH6,-3) -> 44012 | AH6: =EOMONTH(AI6,-3) -> 44104 | AI6: =EOMONTH(AJ6,-3) -> 44196 | AJ6: =EOMONTH(AK6,-3) -> 44286 | ... BC6: =EOMONTH(BD6,-3) -> 46022 | BD6: =Summary!C6 -> 46112 | BE6: =EOMONTH(BD6,3) -> 46203 | BF6: =EOMONTH(BE6,3) -> 46295 | BG6: =EOMONTH(BF6,3) -> 46387 | BH6: =EOMONTH(BG6,3) -> 46477 | BI6: =EOMONTH(BH6,3) -> 46568 | BJ6: =EOMONTH(BI6,3) -> 46660 | BK6: =EOMONTH(BJ6,3) -> 46752 | BL6: =EOMONTH(BK6,3) -> 46843 | ... BX6: =EOMONTH(BW6,3) -> 47938
A8: x | B8: SUMMARY
B10: Revenue | G10: =Summary!C8 -> JPY M | H10: =+SUMIF($X$5:$BY$5,H$5,$X10:$BY10) -> 82292 | I10: =+SUMIF($X$5:$BY$5,I$5,$X10:$BY10) -> 85722 | J10: =+SUMIF($X$5:$BY$5,J$5,$X10:$BY10) -> 78727 | K10: =+SUMIF($X$5:$BY$5,K$5,$X10:$BY10) -> 84051 | L10: =+SUMIF($X$5:$BY$5,L$5,$X10:$BY10) -> 87529 | M10: =+SUMIF($X$5:$BY$5,M$5,$X10:$BY10) -> 93253 | N10: =+SUMIF($X$5:$BY$5,N$5,$X10:$BY10) -> 109035 | O10: =+SUMIF($X$5:$BY$5,O$5,$X10:$BY10) -> 118229 | ... T10: =+SUMIF($X$5:$BY$5,T$5,$X10:$BY10) -> 193564.08 | Y10: =Y82 -> 20450 | Z10: =Z82 -> 21052 | AA10: =AA82 -> 21679 | AB10: =AB82 -> 19111 | AC10: =AC82 -> 20621 | AD10: =AD82 -> 22141 | AE10: =AE82 -> 21299 | AF10: =AF82 -> 21661 | ... BE10: =BE82 -> 34033 | BF10: =SUM(BF11:BF16) -> 34065.465 | BG10: =SUM(BG11:BG16) -> 34825.505 | BH10: =SUM(BH11:BH16) -> 35704.673 | BI10: =SUM(BI11:BI16) -> 37806.795 | BJ10: =SUM(BJ11:BJ16) -> 38507.806 | BK10: =SUM(BK11:BK16) -> 39750.777 | BL10: =SUM(BL11:BL16) -> 40940.616 | BM10: =SUM(BM11:BM16) -> 41906.919 | ... BX10: =SUM(BX11:BX16) -> 49018.055
B11: Electronic Materials | G11: =G$10 -> JPY M | H11: =+SUMIF($X$5:$BY$5,H$5,$X11:$BY11) -> 19786.95 | I11: =+SUMIF($X$5:$BY$5,I$5,$X11:$BY11) -> 23638.2 | J11: =+SUMIF($X$5:$BY$5,J$5,$X11:$BY11) -> 23371.65 | K11: =+SUMIF($X$5:$BY$5,K$5,$X11:$BY11) -> 25381.75 | L11: =+SUMIF($X$5:$BY$5,L$5,$X11:$BY11) -> 25538.3 | M11: =+SUMIF($X$5:$BY$5,M$5,$X11:$BY11) -> 29812.85 | N11: =+SUMIF($X$5:$BY$5,N$5,$X11:$BY11) -> 40911 | O11: =+SUMIF($X$5:$BY$5,O$5,$X11:$BY11) -> 49265 | ... T11: =+SUMIF($X$5:$BY$5,T$5,$X11:$BY11) -> 94669.213 | Y11: =0.35*Y20+0.75*Y21 -> 4915.4 | Z11: =0.35*Z20+0.75*Z21 -> 4969.3 | AA11: =0.35*AA20+0.75*AA21 -> 5242.25 | AB11: =0.35*AB20+0.75*AB21 -> 4660 | AC11: =0.35*AC20+0.75*AC21 -> 5033.1 | AD11: =0.35*AD20+0.75*AD21 -> 6130.35 | AE11: =0.35*AE20+0.75*AE21 -> 6084.75 | AF11: =0.35*AF20+0.75*AF21 -> 6390 | ... AV11: =0.35*AV20+0.75*AV21 -> 8598 | AW11: 9627 | AX11: 10004 | AY11: 10568 | AZ11: 10712 | BA11: 11265 | BB11: 12153 | BC11: 12669 | BD11: 13178 | BE11: 14589 | BF11: =Revenue!BF11 -> 15134.711 | BG11: =Revenue!BG11 -> 15438.299 | BH11: =Revenue!BH11 -> 16392.44 | BI11: =Revenue!BI11 -> 17139.195 | BJ11: =Revenue!BJ11 -> 18369.786 | BK11: =Revenue!BK11 -> 19144.496 | BL11: =Revenue!BL11 -> 20394.819 | BM11: =Revenue!BM11 -> 19946.043 | ... BX11: =Revenue!BX11 -> 24187.021
B12: Medical | G12: =G$10 -> JPY M | H12: =+SUMIF($X$5:$BY$5,H$5,$X12:$BY12) -> 12048.96 | I12: =+SUMIF($X$5:$BY$5,I$5,$X12:$BY12) -> 13245.76 | J12: =+SUMIF($X$5:$BY$5,J$5,$X12:$BY12) -> 11880 | K12: =+SUMIF($X$5:$BY$5,K$5,$X12:$BY12) -> 13983.2 | L12: =+SUMIF($X$5:$BY$5,L$5,$X12:$BY12) -> 14747.92 | M12: =+SUMIF($X$5:$BY$5,M$5,$X12:$BY12) -> 12703.68 | N12: =+SUMIF($X$5:$BY$5,N$5,$X12:$BY12) -> 13603 | O12: =+SUMIF($X$5:$BY$5,O$5,$X12:$BY12) -> 13850 | ... T12: =+SUMIF($X$5:$BY$5,T$5,$X12:$BY12) -> 18004.023 | Y12: =Y23*0.88 -> 3166.24 | Z12: =Z23*0.88 -> 3158.32 | AA12: =AA23*0.88 -> 2966.48 | AB12: =AB23*0.88 -> 2757.92 | AC12: =AC23*0.88 -> 3387.12 | AD12: =AD23*0.88 -> 3511.2 | AE12: =AE23*0.88 -> 3119.6 | AF12: =AF23*0.88 -> 3227.84 | ... AV12: =AV23*0.88 -> 3275.36 | AW12: 3399 | AX12: 3588 | AY12: 3326 | AZ12: 3290 | BA12: 3573 | BB12: 3187 | BC12: 3562 | BD12: 3528 | BE12: 3818 | BF12: =Revenue!BF12 -> 3409.3346 | BG12: =Revenue!BG12 -> 3810.4957 | BH12: =Revenue!BH12 -> 3774.1237 | BI12: =Revenue!BI12 -> 4008.9 | BJ12: =Revenue!BJ12 -> 3579.8013 | BK12: =Revenue!BK12 -> 4001.0205 | BL12: =Revenue!BL12 -> 3962.8299 | BM12: =Revenue!BM12 -> 4209.345 | ... BX12: =Revenue!BX12 -> 4587.471
B13: Composite Materials | G13: =G$10 -> JPY M | H13: =+SUMIF($X$5:$BY$5,H$5,$X13:$BY13) -> 12692.16 | I13: =+SUMIF($X$5:$BY$5,I$5,$X13:$BY13) -> 12008.16 | J13: =+SUMIF($X$5:$BY$5,J$5,$X13:$BY13) -> 11099.52 | K13: =+SUMIF($X$5:$BY$5,K$5,$X13:$BY13) -> 11205.6 | L13: =+SUMIF($X$5:$BY$5,L$5,$X13:$BY13) -> 11504.64 | M13: =+SUMIF($X$5:$BY$5,M$5,$X13:$BY13) -> 12571.68 | N13: =+SUMIF($X$5:$BY$5,N$5,$X13:$BY13) -> 13474 | O13: =+SUMIF($X$5:$BY$5,O$5,$X13:$BY13) -> 13401 | ... T13: =+SUMIF($X$5:$BY$5,T$5,$X13:$BY13) -> 16402.9 | Y13: =Y20*0.48 -> 3249.12 | Z13: =Z20*0.48 -> 3287.04 | AA13: =AA20*0.48 -> 3316.8 | AB13: =AB20*0.48 -> 2839.2 | AC13: =AC20*0.48 -> 3156.48 | AD13: =AD20*0.48 -> 3142.08 | AE13: =AE20*0.48 -> 2779.2 | AF13: =AF20*0.48 -> 2930.4 | ... AV13: =AV20*0.48 -> 3477.6 | AW13: 3289 | AX13: 3238 | AY13: 3492 | AZ13: 3455 | BA13: 3305 | BB13: 3551 | BC13: 3184 | BD13: 3361 | BE13: 3830 | BF13: =Revenue!BF13 -> 3977.12 | BG13: =Revenue!BG13 -> 3502.4 | BH13: =Revenue!BH13 -> 3697.1 | BI13: =Revenue!BI13 -> 3944.9 | BJ13: =Revenue!BJ13 -> 4096.4336 | BK13: =Revenue!BK13 -> 3607.472 | BL13: =Revenue!BL13 -> 3808.013 | BM13: =Revenue!BM13 -> 4023.798 | ... BX13: =Revenue!BX13 -> 4041.0939
B14: Materials Solution | G14: =G$10 -> JPY M | H14: =+SUMIF($X$5:$BY$5,H$5,$X14:$BY14) -> 11515.59 | I14: =+SUMIF($X$5:$BY$5,I$5,$X14:$BY14) -> 10343.32 | J14: =+SUMIF($X$5:$BY$5,J$5,$X14:$BY14) -> 8142.57 | K14: =+SUMIF($X$5:$BY$5,K$5,$X14:$BY14) -> 8658.47 | L14: =+SUMIF($X$5:$BY$5,L$5,$X14:$BY14) -> 9050.09 | M14: =+SUMIF($X$5:$BY$5,M$5,$X14:$BY14) -> 9094.83 | N14: =+SUMIF($X$5:$BY$5,N$5,$X14:$BY14) -> 9431 | O14: =+SUMIF($X$5:$BY$5,O$5,$X14:$BY14) -> 9515 | ... T14: =+SUMIF($X$5:$BY$5,T$5,$X14:$BY14) -> 11590.355 | Y14: =Y23*0.12+Y22*0.23+Y19 -> 2894.22 | Z14: =Z23*0.12+Z22*0.23+Z19 -> 2901.21 | AA14: =AA23*0.12+AA22*0.23+AA19 -> 3080.24 | AB14: =AB23*0.12+AB22*0.23+AB19 -> 2639.92 | AC14: =AC23*0.12+AC22*0.23+AC19 -> 2799.48 | AD14: =AD23*0.12+AD22*0.23+AD19 -> 2598.08 | AE14: =AE23*0.12+AE22*0.23+AE19 -> 2603.62 | AF14: =AF23*0.12+AF22*0.23+AF19 -> 2342.14 | ... AV14: =AV23*0.12+AV22*0.23+AV19 -> 2186.43 | AW14: 2211 | AX14: 2338 | AY14: 2614 | AZ14: 2268 | BA14: 2267 | BB14: 2247 | BC14: 2515 | BD14: 2486 | BE14: 2615 | BF14: =Revenue!BF14 -> 2381.82 | BG14: =Revenue!BG14 -> 2665.9 | BH14: =Revenue!BH14 -> 2635.16 | BI14: =Revenue!BI14 -> 2693.45 | BJ14: =Revenue!BJ14 -> 2453.2746 | BK14: =Revenue!BK14 -> 2745.877 | BL14: =Revenue!BL14 -> 2714.2148 | BM14: =Revenue!BM14 -> 2774.2535 | ... BX14: =Revenue!BX14 -> 2965.8958
B15: Insulation Materials | G15: =G$10 -> JPY M | H15: =+SUMIF($X$5:$BY$5,H$5,$X15:$BY15) -> 14813.8 | I15: =+SUMIF($X$5:$BY$5,I$5,$X15:$BY15) -> 14549.28 | J15: =+SUMIF($X$5:$BY$5,J$5,$X15:$BY15) -> 12620.12 | K15: =+SUMIF($X$5:$BY$5,K$5,$X15:$BY15) -> 12531.72 | L15: =+SUMIF($X$5:$BY$5,L$5,$X15:$BY15) -> 13931.16 | M15: =+SUMIF($X$5:$BY$5,M$5,$X15:$BY15) -> 14713.16 | N15: =+SUMIF($X$5:$BY$5,N$5,$X15:$BY15) -> 15320 | O15: =+SUMIF($X$5:$BY$5,O$5,$X15:$BY15) -> 15136 | ... T15: =+SUMIF($X$5:$BY$5,T$5,$X15:$BY15) -> 21552.081 | Y15: =Y22*0.68 -> 3469.36 | Z15: =Z22*0.68 -> 3679.48 | AA15: =AA22*0.68 -> 4055.52 | AB15: =AB22*0.68 -> 3609.44 | AC15: =AC22*0.68 -> 3549.6 | AD15: =AD22*0.68 -> 3696.48 | AE15: =AE22*0.68 -> 3681.52 | AF15: =AF22*0.68 -> 3621.68 | ... AV15: =AV22*0.68 -> 3653.64 | AW15: 3736 | AX15: 3807 | AY15: 4190 | AZ15: 3587 | BA15: 3543 | BB15: 3751 | BC15: 4126 | BD15: 3716 | BE15: 4399 | BF15: =Revenue!BF15 -> 4313.65 | BG15: =Revenue!BG15 -> 4744.9 | BH15: =Revenue!BH15 -> 4273.4 | BI15: =Revenue!BI15 -> 4618.95 | BJ15: =Revenue!BJ15 -> 4529.3325 | BK15: =Revenue!BK15 -> 4982.145 | BL15: =Revenue!BL15 -> 4487.07 | BM15: =Revenue!BM15 -> 4849.8975 | ... BX15: =Revenue!BX15 -> 5194.3444
B16: Other Business | G16: =G$10 -> JPY M | H16: =+SUMIF($X$5:$BY$5,H$5,$X16:$BY16) -> 11432.54 | I16: =+SUMIF($X$5:$BY$5,I$5,$X16:$BY16) -> 11935.28 | J16: =+SUMIF($X$5:$BY$5,J$5,$X16:$BY16) -> 11611.14 | K16: =+SUMIF($X$5:$BY$5,K$5,$X16:$BY16) -> 12288.26 | L16: =+SUMIF($X$5:$BY$5,L$5,$X16:$BY16) -> 12755.89 | M16: =+SUMIF($X$5:$BY$5,M$5,$X16:$BY16) -> 14353.8 | N16: =+SUMIF($X$5:$BY$5,N$5,$X16:$BY16) -> 16294 | O16: =+SUMIF($X$5:$BY$5,O$5,$X16:$BY16) -> 17059 | ... T16: =+SUMIF($X$5:$BY$5,T$5,$X16:$BY16) -> 31345.513 | Y16: =0.17*Y20+0.25*Y21+0.09*Y22+Y24 -> 2752.66 | Z16: =0.17*Z20+0.25*Z21+0.09*Z22+Z24 -> 3058.65 | AA16: =0.17*AA20+0.25*AA21+0.09*AA22+AA24 -> 3015.71 | AB16: =0.17*AB20+0.25*AB21+0.09*AB22+AB24 -> 2605.52 | AC16: =0.17*AC20+0.25*AC21+0.09*AC22+AC24 -> 2694.22 | AD16: =0.17*AD20+0.25*AD21+0.09*AD22+AD24 -> 3061.81 | AE16: =0.17*AE20+0.25*AE21+0.09*AE22+AE24 -> 3028.31 | AF16: =0.17*AF20+0.25*AF21+0.09*AF22+AF24 -> 3150.94 | ... AV16: =0.17*AV20+0.25*AV21+0.09*AV22+AV24 -> 4020.97 | AW16: 3851 | AX16: 3961 | AY16: 4278 | AZ16: 4204 | BA16: 4276 | BB16: 4291 | BC16: 4127 | BD16: 4365 | BE16: 4780 | BF16: =Revenue!BF16 -> 4848.83 | BG16: =Revenue!BG16 -> 4663.51 | BH16: =Revenue!BH16 -> 4932.45 | BI16: =Revenue!BI16 -> 5401.4 | BJ16: =Revenue!BJ16 -> 5479.1779 | BK16: =Revenue!BK16 -> 5269.7663 | BL16: =Revenue!BL16 -> 5573.6685 | BM16: =Revenue!BM16 -> 6103.582 | ... BX16: =Revenue!BX16 -> 8042.2296
B18: Revenue (Previous Disclosure) | G18: =G$10 -> JPY M | H18: =+SUMIF($X$5:$BY$5,H$5,$X18:$BY18) -> 82290 | I18: =+SUMIF($X$5:$BY$5,I$5,$X18:$BY18) -> 85720 | J18: =+SUMIF($X$5:$BY$5,J$5,$X18:$BY18) -> 78725 | K18: =+SUMIF($X$5:$BY$5,K$5,$X18:$BY18) -> 84049 | L18: =+SUMIF($X$5:$BY$5,L$5,$X18:$BY18) -> 87528 | M18: =+SUMIF($X$5:$BY$5,M$5,$X18:$BY18) -> 93250 | N18: =+SUMIF($X$5:$BY$5,N$5,$X18:$BY18) -> 0 | O18: =+SUMIF($X$5:$BY$5,O$5,$X18:$BY18) -> 0 | ... T18: =+SUMIF($X$5:$BY$5,T$5,$X18:$BY18) -> 0 | Y18: =SUM(Y19:Y24) -> 20447 | Z18: =SUM(Z19:Z24) -> 21054 | AA18: =SUM(AA19:AA24) -> 21677 | AB18: =SUM(AB19:AB24) -> 19112 | AC18: =SUM(AC19:AC24) -> 20620 | AD18: =SUM(AD19:AD24) -> 22140 | AE18: =SUM(AE19:AE24) -> 21297 | AF18: =SUM(AF19:AF24) -> 21663 | ... AV18: =SUM(AV19:AV24) -> 25212
B19: Textile | G19: =G$10 -> JPY M | H19: =+SUMIF($X$5:$BY$5,H$5,$X19:$BY19) -> 4862 | I19: =+SUMIF($X$5:$BY$5,I$5,$X19:$BY19) -> 3616 | J19: =+SUMIF($X$5:$BY$5,J$5,$X19:$BY19) -> 2254 | K19: =+SUMIF($X$5:$BY$5,K$5,$X19:$BY19) -> 2513 | L19: =+SUMIF($X$5:$BY$5,L$5,$X19:$BY19) -> 2327 | M19: =+SUMIF($X$5:$BY$5,M$5,$X19:$BY19) -> 2386 | N19: =+SUMIF($X$5:$BY$5,N$5,$X19:$BY19) -> 0 | O19: =+SUMIF($X$5:$BY$5,O$5,$X19:$BY19) -> 0 | ... T19: =+SUMIF($X$5:$BY$5,T$5,$X19:$BY19) -> 0 | Y19: 1289 | Z19: 1226 | AA19: 1304 | AB19: 1043 | AC19: 1137 | AD19: 869 | AE19: 933 | AF19: 677 | AG19: 552 | AH19: 514 | AI19: 651 | AJ19: 537 | AK19: 668 | AL19: 591 | AM19: 747 | AN19: 507 | AO19: 606 | AP19: 553 | AQ19: 674 | AR19: 494 | AS19: 639 | AT19: 581 | AU19: 662 | AV19: 504
B20: Glass Fiber Yarn | G20: =G$10 -> JPY M | H20: =+SUMIF($X$5:$BY$5,H$5,$X20:$BY20) -> 26442 | I20: =+SUMIF($X$5:$BY$5,I$5,$X20:$BY20) -> 25017 | J20: =+SUMIF($X$5:$BY$5,J$5,$X20:$BY20) -> 23124 | K20: =+SUMIF($X$5:$BY$5,K$5,$X20:$BY20) -> 23345 | L20: =+SUMIF($X$5:$BY$5,L$5,$X20:$BY20) -> 23968 | M20: =+SUMIF($X$5:$BY$5,M$5,$X20:$BY20) -> 26191 | N20: =+SUMIF($X$5:$BY$5,N$5,$X20:$BY20) -> 0 | O20: =+SUMIF($X$5:$BY$5,O$5,$X20:$BY20) -> 0 | ... T20: =+SUMIF($X$5:$BY$5,T$5,$X20:$BY20) -> 0 | Y20: 6769 | Z20: 6848 | AA20: 6910 | AB20: 5915 | AC20: 6576 | AD20: 6546 | AE20: 5790 | AF20: 6105 | AG20: 5686 | AH20: 5120 | AI20: 6266 | AJ20: 6052 | AK20: 5734 | AL20: 5468 | AM20: 5989 | AN20: 6154 | AO20: 6888 | AP20: 6052 | AQ20: 5798 | AR20: 5230 | AS20: 5748 | AT20: 6077 | AU20: 7121 | AV20: 7245
B21: Glass Fiber Cloth | G21: =G$10 -> JPY M | H21: =+SUMIF($X$5:$BY$5,H$5,$X21:$BY21) -> 14043 | I21: =+SUMIF($X$5:$BY$5,I$5,$X21:$BY21) -> 19843 | J21: =+SUMIF($X$5:$BY$5,J$5,$X21:$BY21) -> 20371 | K21: =+SUMIF($X$5:$BY$5,K$5,$X21:$BY21) -> 22948 | L21: =+SUMIF($X$5:$BY$5,L$5,$X21:$BY21) -> 22866 | M21: =+SUMIF($X$5:$BY$5,M$5,$X21:$BY21) -> 27528 | N21: =+SUMIF($X$5:$BY$5,N$5,$X21:$BY21) -> 0 | O21: =+SUMIF($X$5:$BY$5,O$5,$X21:$BY21) -> 0 | ... T21: =+SUMIF($X$5:$BY$5,T$5,$X21:$BY21) -> 0 | Y21: 3395 | Z21: 3430 | AA21: 3765 | AB21: 3453 | AC21: 3642 | AD21: 5119 | AE21: 5411 | AF21: 5671 | AG21: 5538 | AH21: 4517 | AI21: 4789 | AJ21: 5527 | AK21: 5600 | AL21: 5502 | AM21: 5373 | AN21: 6473 | AO21: 6979 | AP21: 6503 | AQ21: 5137 | AR21: 4247 | AS21: 5423 | AT21: 6545 | AU21: 7477 | AV21: 8083
B22: Glass Fiber for Industrial Materials | G22: =G$10 -> JPY M | H22: =+SUMIF($X$5:$BY$5,H$5,$X22:$BY22) -> 21785 | I22: =+SUMIF($X$5:$BY$5,I$5,$X22:$BY22) -> 21396 | J22: =+SUMIF($X$5:$BY$5,J$5,$X22:$BY22) -> 18559 | K22: =+SUMIF($X$5:$BY$5,K$5,$X22:$BY22) -> 18429 | L22: =+SUMIF($X$5:$BY$5,L$5,$X22:$BY22) -> 20487 | M22: =+SUMIF($X$5:$BY$5,M$5,$X22:$BY22) -> 21637 | N22: =+SUMIF($X$5:$BY$5,N$5,$X22:$BY22) -> 0 | O22: =+SUMIF($X$5:$BY$5,O$5,$X22:$BY22) -> 0 | ... T22: =+SUMIF($X$5:$BY$5,T$5,$X22:$BY22) -> 0 | Y22: 5102 | Z22: 5411 | AA22: 5964 | AB22: 5308 | AC22: 5220 | AD22: 5436 | AE22: 5414 | AF22: 5326 | AG22: 4397 | AH22: 4639 | AI22: 4910 | AJ22: 4613 | AK22: 4179 | AL22: 4598 | AM22: 4967 | AN22: 4685 | AO22: 4588 | AP22: 5235 | AQ22: 5489 | AR22: 5175 | AS22: 4936 | AT22: 5386 | AU22: 5942 | AV22: 5373
B23: Life Science | G23: =G$10 -> JPY M | H23: =+SUMIF($X$5:$BY$5,H$5,$X23:$BY23) -> 13692 | I23: =+SUMIF($X$5:$BY$5,I$5,$X23:$BY23) -> 15052 | J23: =+SUMIF($X$5:$BY$5,J$5,$X23:$BY23) -> 13500 | K23: =+SUMIF($X$5:$BY$5,K$5,$X23:$BY23) -> 15890 | L23: =+SUMIF($X$5:$BY$5,L$5,$X23:$BY23) -> 16759 | M23: =+SUMIF($X$5:$BY$5,M$5,$X23:$BY23) -> 14436 | N23: =+SUMIF($X$5:$BY$5,N$5,$X23:$BY23) -> 0 | O23: =+SUMIF($X$5:$BY$5,O$5,$X23:$BY23) -> 0 | ... T23: =+SUMIF($X$5:$BY$5,T$5,$X23:$BY23) -> 0 | Y23: 3598 | Z23: 3589 | AA23: 3371 | AB23: 3134 | AC23: 3849 | AD23: 3990 | AE23: 3545 | AF23: 3668 | AG23: 3229 | AH23: 3625 | AI23: 3218 | AJ23: 3428 | AK23: 4154 | AL23: 4163 | AM23: 3734 | AN23: 3839 | AO23: 4459 | AP23: 4641 | AQ23: 4374 | AR23: 3285 | AS23: 3240 | AT23: 3615 | AU23: 3859 | AV23: 3722
B24: Others | G24: =G$10 -> JPY M | H24: =+SUMIF($X$5:$BY$5,H$5,$X24:$BY24) -> 1466 | I24: =+SUMIF($X$5:$BY$5,I$5,$X24:$BY24) -> 796 | J24: =+SUMIF($X$5:$BY$5,J$5,$X24:$BY24) -> 917 | K24: =+SUMIF($X$5:$BY$5,K$5,$X24:$BY24) -> 924 | L24: =+SUMIF($X$5:$BY$5,L$5,$X24:$BY24) -> 1121 | M24: =+SUMIF($X$5:$BY$5,M$5,$X24:$BY24) -> 1072 | N24: =+SUMIF($X$5:$BY$5,N$5,$X24:$BY24) -> 0 | O24: =+SUMIF($X$5:$BY$5,O$5,$X24:$BY24) -> 0 | ... T24: =+SUMIF($X$5:$BY$5,T$5,$X24:$BY24) -> 0 | Y24: 294 | Z24: 550 | AA24: 363 | AB24: 259 | AC24: 196 | AD24: 180 | AE24: 204 | AF24: 216 | AG24: 179 | AH24: 282 | AI24: 262 | AJ24: 194 | AK24: 181 | AL24: 246 | AM24: 223 | AN24: 274 | AO24: 304 | AP24: 226 | AQ24: 253 | AR24: 338 | AS24: 309 | AT24: 232 | AU24: 246 | AV24: 285
B26: Mix
B27: =B11 -> Electronic Materials | G27: % | H27: =IFERROR(H11/H$10,"nm") -> 0.24044804 | I27: =IFERROR(I11/I$10,"nm") -> 0.27575418 | J27: =IFERROR(J11/J$10,"nm") -> 0.29686956 | K27: =IFERROR(K11/K$10,"nm") -> 0.30198035 | L27: =IFERROR(L11/L$10,"nm") -> 0.29176958 | M27: =IFERROR(M11/M$10,"nm") -> 0.31969856 | N27: =IFERROR(N11/N$10,"nm") -> 0.3752098 | O27: =IFERROR(O11/O$10,"nm") -> 0.41669134 | ... T27: =IFERROR(T11/T$10,"nm") -> 0.4890846 | Y27: =IFERROR(Y11/Y$10,"nm") -> 0.24036186 | Z27: =IFERROR(Z11/Z$10,"nm") -> 0.23604883 | AA27: =IFERROR(AA11/AA$10,"nm") -> 0.24181235 | AB27: =IFERROR(AB11/AB$10,"nm") -> 0.24383863 | AC27: =IFERROR(AC11/AC$10,"nm") -> 0.24407643 | AD27: =IFERROR(AD11/AD$10,"nm") -> 0.27687774 | AE27: =IFERROR(AE11/AE$10,"nm") -> 0.28568243 | AF27: =IFERROR(AF11/AF$10,"nm") -> 0.29500023 | ... BX27: =IFERROR(BX11/BX$10,"nm") -> 0.49343085
B28: =B12 -> Medical | G28: % | H28: =IFERROR(H12/H$10,"nm") -> 0.14641715 | I28: =IFERROR(I12/I$10,"nm") -> 0.15451996 | J28: =IFERROR(J12/J$10,"nm") -> 0.15090122 | K28: =IFERROR(K12/K$10,"nm") -> 0.16636566 | L28: =IFERROR(L12/L$10,"nm") -> 0.16849181 | M28: =IFERROR(M12/M$10,"nm") -> 0.13622811 | N28: =IFERROR(N12/N$10,"nm") -> 0.12475811 | O28: =IFERROR(O12/O$10,"nm") -> 0.11714554 | ... T28: =IFERROR(T12/T$10,"nm") -> 0.093013241 | Y28: =IFERROR(Y12/Y$10,"nm") -> 0.15482836 | Z28: =IFERROR(Z12/Z$10,"nm") -> 0.1500247 | AA28: =IFERROR(AA12/AA$10,"nm") -> 0.13683657 | AB28: =IFERROR(AB12/AB$10,"nm") -> 0.14431061 | AC28: =IFERROR(AC12/AC$10,"nm") -> 0.16425586 | AD28: =IFERROR(AD12/AD$10,"nm") -> 0.15858362 | AE28: =IFERROR(AE12/AE$10,"nm") -> 0.14646697 | AF28: =IFERROR(AF12/AF$10,"nm") -> 0.1490162 | ... BX28: =IFERROR(BX12/BX$10,"nm") -> 0.093587373
B29: =B13 -> Composite Materials | G29: % | H29: =IFERROR(H13/H$10,"nm") -> 0.15423322 | I29: =IFERROR(I13/I$10,"nm") -> 0.14008259 | J29: =IFERROR(J13/J$10,"nm") -> 0.14098746 | K29: =IFERROR(K13/K$10,"nm") -> 0.13331906 | L29: =IFERROR(L13/L$10,"nm") -> 0.13143804 | M29: =IFERROR(M13/M$10,"nm") -> 0.13481261 | N29: =IFERROR(N13/N$10,"nm") -> 0.123575 | O29: =IFERROR(O13/O$10,"nm") -> 0.11334782 | ... T29: =IFERROR(T13/T$10,"nm") -> 0.084741442 | Y29: =IFERROR(Y13/Y$10,"nm") -> 0.15888117 | Z29: =IFERROR(Z13/Z$10,"nm") -> 0.15613908 | AA29: =IFERROR(AA13/AA$10,"nm") -> 0.15299599 | AB29: =IFERROR(AB13/AB$10,"nm") -> 0.14856365 | AC29: =IFERROR(AC13/AC$10,"nm") -> 0.15307114 | AD29: =IFERROR(AD13/AD$10,"nm") -> 0.14191229 | AE29: =IFERROR(AE13/AE$10,"nm") -> 0.130485 | AF29: =IFERROR(AF13/AF$10,"nm") -> 0.13528461 | ... BX29: =IFERROR(BX13/BX$10,"nm") -> 0.082440926
B30: =B14 -> Materials Solution | G30: % | H30: =IFERROR(H14/H$10,"nm") -> 0.13993572 | I30: =IFERROR(I14/I$10,"nm") -> 0.12066121 | J30: =IFERROR(J14/J$10,"nm") -> 0.10342792 | K30: =IFERROR(K14/K$10,"nm") -> 0.10301448 | L30: =IFERROR(L14/L$10,"nm") -> 0.10339533 | M30: =IFERROR(M14/M$10,"nm") -> 0.097528551 | N30: =IFERROR(N14/N$10,"nm") -> 0.086495162 | O30: =IFERROR(O14/O$10,"nm") -> 0.080479409 | ... T30: =IFERROR(T14/T$10,"nm") -> 0.059878643 | Y30: =IFERROR(Y14/Y$10,"nm") -> 0.14152665 | Z30: =IFERROR(Z14/Z$10,"nm") -> 0.13781161 | AA30: =IFERROR(AA14/AA$10,"nm") -> 0.14208404 | AB30: =IFERROR(AB14/AB$10,"nm") -> 0.13813615 | AC30: =IFERROR(AC14/AC$10,"nm") -> 0.13575869 | AD30: =IFERROR(AD14/AD$10,"nm") -> 0.11734249 | AE30: =IFERROR(AE14/AE$10,"nm") -> 0.12224142 | AF30: =IFERROR(AF14/AF$10,"nm") -> 0.10812705 | ... BX30: =IFERROR(BX14/BX$10,"nm") -> 0.060506191
B31: =B15 -> Insulation Materials | G31: % | H31: =IFERROR(H15/H$10,"nm") -> 0.18001507 | I31: =IFERROR(I15/I$10,"nm") -> 0.16972632 | J31: =IFERROR(J15/J$10,"nm") -> 0.16030231 | K31: =IFERROR(K15/K$10,"nm") -> 0.14909662 | L31: =IFERROR(L15/L$10,"nm") -> 0.15916051 | M31: =IFERROR(M15/M$10,"nm") -> 0.1577768 | N31: =IFERROR(N15/N$10,"nm") -> 0.14050534 | O31: =IFERROR(O15/O$10,"nm") -> 0.12802274 | ... T31: =IFERROR(T15/T$10,"nm") -> 0.11134339 | Y31: =IFERROR(Y15/Y$10,"nm") -> 0.16965086 | Z31: =IFERROR(Z15/Z$10,"nm") -> 0.17478054 | AA31: =IFERROR(AA15/AA$10,"nm") -> 0.18707136 | AB31: =IFERROR(AB15/AB$10,"nm") -> 0.18886714 | AC31: =IFERROR(AC15/AC$10,"nm") -> 0.1721352 | AD31: =IFERROR(AD15/AD$10,"nm") -> 0.16695181 | AE31: =IFERROR(AE15/AE$10,"nm") -> 0.17284943 | AF31: =IFERROR(AF15/AF$10,"nm") -> 0.16719819 | ... BX31: =IFERROR(BX15/BX$10,"nm") -> 0.10596798
B32: =B16 -> Other Business | G32: % | H32: =IFERROR(H16/H$10,"nm") -> 0.13892651 | I32: =IFERROR(I16/I$10,"nm") -> 0.1392324 | J32: =IFERROR(J16/J$10,"nm") -> 0.14748612 | K32: =IFERROR(K16/K$10,"nm") -> 0.14620005 | L32: =IFERROR(L16/L$10,"nm") -> 0.1457333 | M32: =IFERROR(M16/M$10,"nm") -> 0.1539232 | N32: =IFERROR(N16/N$10,"nm") -> 0.14943825 | O32: =IFERROR(O16/O$10,"nm") -> 0.14428778 | ... T32: =IFERROR(T16/T$10,"nm") -> 0.16193868 | Y32: =IFERROR(Y16/Y$10,"nm") -> 0.1346044 | Z32: =IFERROR(Z16/Z$10,"nm") -> 0.14529023 | AA32: =IFERROR(AA16/AA$10,"nm") -> 0.13910743 | AB32: =IFERROR(AB16/AB$10,"nm") -> 0.13633614 | AC32: =IFERROR(AC16/AC$10,"nm") -> 0.13065419 | AD32: =IFERROR(AD16/AD$10,"nm") -> 0.13828689 | AE32: =IFERROR(AE16/AE$10,"nm") -> 0.14218085 | AF32: =IFERROR(AF16/AF$10,"nm") -> 0.14546604 | ... BX32: =IFERROR(BX16/BX$10,"nm") -> 0.16406668
B34: Y/Y | I34: =IFERROR(I10/H10-1,"nm") -> 0.041680844 | J34: =IFERROR(J10/I10-1,"nm") -> -0.081600989 | K34: =IFERROR(K10/J10-1,"nm") -> 0.0676261 | L34: =IFERROR(L10/K10-1,"nm") -> 0.041379639 | M34: =IFERROR(M10/L10-1,"nm") -> 0.065395469 | N34: =IFERROR(N10/M10-1,"nm") -> 0.16923852 | O34: =IFERROR(O10/N10-1,"nm") -> 0.084321548 | P34: =IFERROR(P10/O10-1,"nm") -> 0.17254348 | ... T34: =IFERROR(T10/S10-1,"nm") -> 0.064201151
B35: =B11 -> Electronic Materials | G35: % | I35: =IFERROR(I11/H11-1,"nm") -> 0.19463586 | J35: =IFERROR(J11/I11-1,"nm") -> -0.011276239 | K35: =IFERROR(K11/J11-1,"nm") -> 0.086005909 | L35: =IFERROR(L11/K11-1,"nm") -> 0.0061678174 | M35: =IFERROR(M11/L11-1,"nm") -> 0.16737802 | N35: =IFERROR(N11/M11-1,"nm") -> 0.37226062 | O35: =IFERROR(O11/N11-1,"nm") -> 0.20419936 | P35: =IFERROR(P11/O11-1,"nm") -> 0.24945599 | ... T35: =IFERROR(T11/S11-1,"nm") -> 0.06201855 | AC35: =IFERROR(AC11/Y11-1,"nm") -> 0.023945152 | AD35: =IFERROR(AD11/Z11-1,"nm") -> 0.23364458 | AE35: =IFERROR(AE11/AA11-1,"nm") -> 0.16071343 | AF35: =IFERROR(AF11/AB11-1,"nm") -> 0.37124464 | AG35: =IFERROR(AG11/AC11-1,"nm") -> 0.22063937 | AH35: =IFERROR(AH11/AD11-1,"nm") -> -0.15506456 | AI35: =IFERROR(AI11/AE11-1,"nm") -> -0.049287152 | AJ35: =IFERROR(AJ11/AF11-1,"nm") -> -0.019804382 | ... BX35: =IFERROR(BX11/BT11-1,"nm") -> 0.059641915
B36: =B12 -> Medical | G36: % | I36: =IFERROR(I12/H12-1,"nm") -> 0.099328075 | J36: =IFERROR(J12/I12-1,"nm") -> -0.10310922 | K36: =IFERROR(K12/J12-1,"nm") -> 0.17703704 | L36: =IFERROR(L12/K12-1,"nm") -> 0.054688483 | M36: =IFERROR(M12/L12-1,"nm") -> -0.13861209 | N36: =IFERROR(N12/M12-1,"nm") -> 0.070792085 | O36: =IFERROR(O12/N12-1,"nm") -> 0.018157759 | P36: =IFERROR(P12/O12-1,"nm") -> 0.069455163 | ... T36: =IFERROR(T12/S12-1,"nm") -> 0.05 | AC36: =IFERROR(AC12/Y12-1,"nm") -> 0.069760978 | AD36: =IFERROR(AD12/Z12-1,"nm") -> 0.11173029 | AE36: =IFERROR(AE12/AA12-1,"nm") -> 0.051616731 | AF36: =IFERROR(AF12/AB12-1,"nm") -> 0.17038928 | AG36: =IFERROR(AG12/AC12-1,"nm") -> -0.1610808 | AH36: =IFERROR(AH12/AD12-1,"nm") -> -0.091478697 | AI36: =IFERROR(AI12/AE12-1,"nm") -> -0.092242595 | AJ36: =IFERROR(AJ12/AF12-1,"nm") -> -0.065430752 | ... BX36: =IFERROR(BX12/BT12-1,"nm") -> 0.05
B37: =B13 -> Composite Materials | G37: % | I37: =IFERROR(I13/H13-1,"nm") -> -0.053891536 | J37: =IFERROR(J13/I13-1,"nm") -> -0.075668545 | K37: =IFERROR(K13/J13-1,"nm") -> 0.00955717 | L37: =IFERROR(L13/K13-1,"nm") -> 0.026686657 | M37: =IFERROR(M13/L13-1,"nm") -> 0.092748665 | N37: =IFERROR(N13/M13-1,"nm") -> 0.071774019 | O37: =IFERROR(O13/N13-1,"nm") -> -0.0054178418 | P37: =IFERROR(P13/O13-1,"nm") -> 0.11981345 | ... T37: =IFERROR(T13/S13-1,"nm") -> 0.02 | AC37: =IFERROR(AC13/Y13-1,"nm") -> -0.028512336 | AD37: =IFERROR(AD13/Z13-1,"nm") -> -0.044100467 | AE37: =IFERROR(AE13/AA13-1,"nm") -> -0.16208394 | AF37: =IFERROR(AF13/AB13-1,"nm") -> 0.032121724 | AG37: =IFERROR(AG13/AC13-1,"nm") -> -0.13534063 | AH37: =IFERROR(AH13/AD13-1,"nm") -> -0.21784296 | AI37: =IFERROR(AI13/AE13-1,"nm") -> 0.082210708 | AJ37: =IFERROR(AJ13/AF13-1,"nm") -> -0.0086814087 | ... BX37: =IFERROR(BX13/BT13-1,"nm") -> 0.02
B38: =B14 -> Materials Solution | G38: % | I38: =IFERROR(I14/H14-1,"nm") -> -0.10179852 | J38: =IFERROR(J14/I14-1,"nm") -> -0.21277017 | K38: =IFERROR(K14/J14-1,"nm") -> 0.063358375 | L38: =IFERROR(L14/K14-1,"nm") -> 0.0452297 | M38: =IFERROR(M14/L14-1,"nm") -> 0.0049435972 | N38: =IFERROR(N14/M14-1,"nm") -> 0.036962758 | O38: =IFERROR(O14/N14-1,"nm") -> 0.0089067967 | P38: =IFERROR(P14/O14-1,"nm") -> 0.082278508 | ... T38: =IFERROR(T14/S14-1,"nm") -> 0.03 | AC38: =IFERROR(AC14/Y14-1,"nm") -> -0.032734208 | AD38: =IFERROR(AD14/Z14-1,"nm") -> -0.10448399 | AE38: =IFERROR(AE14/AA14-1,"nm") -> -0.1547347 | AF38: =IFERROR(AF14/AB14-1,"nm") -> -0.11279887 | AG38: =IFERROR(AG14/AC14-1,"nm") -> -0.30315987 | AH38: =IFERROR(AH14/AD14-1,"nm") -> -0.22405392 | AI38: =IFERROR(AI14/AE14-1,"nm") -> -0.16790469 | AJ38: =IFERROR(AJ14/AF14-1,"nm") -> -0.142088 | ... BX38: =IFERROR(BX14/BT14-1,"nm") -> 0.03
B39: =B15 -> Insulation Materials | G39: % | I39: =IFERROR(I15/H15-1,"nm") -> -0.017856323 | J39: =IFERROR(J15/I15-1,"nm") -> -0.13259488 | K39: =IFERROR(K15/J15-1,"nm") -> -0.0070046878 | L39: =IFERROR(L15/K15-1,"nm") -> 0.11167182 | M39: =IFERROR(M15/L15-1,"nm") -> 0.056133158 | N39: =IFERROR(N15/M15-1,"nm") -> 0.041244709 | O39: =IFERROR(O15/N15-1,"nm") -> -0.012010444 | P39: =IFERROR(P15/O15-1,"nm") -> 0.17144226 | ... T39: =IFERROR(T15/S15-1,"nm") -> 0.05 | AC39: =IFERROR(AC15/Y15-1,"nm") -> 0.023128185 | AD39: =IFERROR(AD15/Z15-1,"nm") -> 0.0046202181 | AE39: =IFERROR(AE15/AA15-1,"nm") -> -0.092219987 | AF39: =IFERROR(AF15/AB15-1,"nm") -> 0.0033911078 | AG39: =IFERROR(AG15/AC15-1,"nm") -> -0.15766284 | AH39: =IFERROR(AH15/AD15-1,"nm") -> -0.14661516 | AI39: =IFERROR(AI15/AE15-1,"nm") -> -0.093091984 | AJ39: =IFERROR(AJ15/AF15-1,"nm") -> -0.13387157 | ... BX39: =IFERROR(BX15/BT15-1,"nm") -> 0.05
B40: =B16 -> Other Business | G40: % | I40: =IFERROR(I16/H16-1,"nm") -> 0.04397448 | J40: =IFERROR(J16/I16-1,"nm") -> -0.02715814 | K40: =IFERROR(K16/J16-1,"nm") -> 0.05831641 | L40: =IFERROR(L16/K16-1,"nm") -> 0.038055022 | M40: =IFERROR(M16/L16-1,"nm") -> 0.12526841 | N40: =IFERROR(N16/M16-1,"nm") -> 0.13516978 | O40: =IFERROR(O16/N16-1,"nm") -> 0.046949797 | P40: =IFERROR(P16/O16-1,"nm") -> 0.12695879 | ... T40: =IFERROR(T16/S16-1,"nm") -> 0.13 | AC40: =IFERROR(AC16/Y16-1,"nm") -> -0.021230374 | AD40: =IFERROR(AD16/Z16-1,"nm") -> 0.0010331355 | AE40: =IFERROR(AE16/AA16-1,"nm") -> 0.0041781206 | AF40: =IFERROR(AF16/AB16-1,"nm") -> 0.20933249 | AG40: =IFERROR(AG16/AC16-1,"nm") -> 0.085972935 | AH40: =IFERROR(AH16/AD16-1,"nm") -> -0.11844301 | AI40: =IFERROR(AI16/AE16-1,"nm") -> -0.020453652 | AJ40: =IFERROR(AJ16/AF16-1,"nm") -> -0.041632021 | ... BX40: =IFERROR(BX16/BT16-1,"nm") -> 0.13
B42: Operating profit | G42: =G$10 -> JPY M | H42: =+SUMIF($X$5:$BY$5,H$5,$X42:$BY42) -> 8198 | I42: =+SUMIF($X$5:$BY$5,I$5,$X42:$BY42) -> 8160 | J42: =+SUMIF($X$5:$BY$5,J$5,$X42:$BY42) -> 5964 | K42: =+SUMIF($X$5:$BY$5,K$5,$X42:$BY42) -> 7268 | L42: =+SUMIF($X$5:$BY$5,L$5,$X42:$BY42) -> 4880 | M42: =+SUMIF($X$5:$BY$5,M$5,$X42:$BY42) -> 8387 | N42: =+SUMIF($X$5:$BY$5,N$5,$X42:$BY42) -> 16445 | O42: =+SUMIF($X$5:$BY$5,O$5,$X42:$BY42) -> 20819 | ... T42: =+SUMIF($X$5:$BY$5,T$5,$X42:$BY42) -> 39963.536 | Y42: =Y87 -> 2126 | Z42: =Z87 -> 2266 | AA42: =AA87 -> 2473 | AB42: =AB87 -> 1333 | AC42: =AC87 -> 1698 | AD42: =AD87 -> 1696 | AE42: =AE87 -> 1846 | AF42: =AF87 -> 2920 | ... BE42: =BE87 -> 7943 | BF42: =SUM(BF43:BF49) -> 7496.5965 | BG42: =SUM(BG43:BG49) -> 7539.7792 | BH42: =SUM(BH43:BH49) -> 7964.9171 | BI42: =SUM(BI43:BI49) -> 7895.5525 | BJ42: =SUM(BJ43:BJ49) -> 7877.769 | BK42: =SUM(BK43:BK49) -> 8860.3039 | BL42: =SUM(BL43:BL49) -> 10085.001 | BM42: =SUM(BM43:BM49) -> 8903.9173 | ... BX42: =SUM(BX43:BX49) -> 10466.666
B43: =B11 -> Electronic Materials | G43: =G$10 -> JPY M | H43: =+SUMIF($X$5:$BY$5,H$5,$X43:$BY43) -> 1970.07 | I43: =+SUMIF($X$5:$BY$5,I$5,$X43:$BY43) -> 2831.43 | J43: =+SUMIF($X$5:$BY$5,J$5,$X43:$BY43) -> 2547.22 | K43: =+SUMIF($X$5:$BY$5,K$5,$X43:$BY43) -> 2973.05 | L43: =+SUMIF($X$5:$BY$5,L$5,$X43:$BY43) -> 3373.66 | M43: =+SUMIF($X$5:$BY$5,M$5,$X43:$BY43) -> 5382 | N43: =+SUMIF($X$5:$BY$5,N$5,$X43:$BY43) -> 13880 | O43: =+SUMIF($X$5:$BY$5,O$5,$X43:$BY43) -> 19391 | ... T43: =+SUMIF($X$5:$BY$5,T$5,$X43:$BY43) -> 36494.34 | Y43: =0.97*Y54 -> 541.26 | Z43: =0.97*Z54 -> 481.12 | AA43: =0.97*AA54 -> 538.35 | AB43: =0.97*AB54 -> 409.34 | AC43: =0.97*AC54 -> 574.24 | AD43: =0.97*AD54 -> 615.95 | AE43: =0.97*AE54 -> 696.46 | AF43: =0.97*AF54 -> 944.78 | ... AR43: =0.97*AR54 -> 59.17 | AS43: 755 | AT43: 1316 | AU43: 1098 | AV43: 2213 | AW43: 3545 | AX43: 2865 | AY43: 3496 | AZ43: 3974 | BA43: 4139 | BB43: 4847 | BC43: 4841 | BD43: 5564 | BE43: 7036 | BF43: =Revenue!BF35 -> 7240.8159 | BG43: =Revenue!BG35 -> 6670.3097 | BH43: =Revenue!BH35 -> 7196.3575 | BI43: =Revenue!BI35 -> 7048.888 | BJ43: =Revenue!BJ35 -> 7602.3859 | BK43: =Revenue!BK35 -> 7973.2005 | BL43: =Revenue!BL35 -> 9304.7129 | BM43: =Revenue!BM35 -> 8022.5672 | ... BX43: =Revenue!BX35 -> 9498.0834
B44: =B12 -> Medical | G44: =G$10 -> JPY M | H44: =+SUMIF($X$5:$BY$5,H$5,$X44:$BY44) -> 553.52 | I44: =+SUMIF($X$5:$BY$5,I$5,$X44:$BY44) -> 390.72 | J44: =+SUMIF($X$5:$BY$5,J$5,$X44:$BY44) -> 270.16 | K44: =+SUMIF($X$5:$BY$5,K$5,$X44:$BY44) -> 224.4 | L44: =+SUMIF($X$5:$BY$5,L$5,$X44:$BY44) -> 97.68 | M44: =+SUMIF($X$5:$BY$5,M$5,$X44:$BY44) -> 2389 | N44: =+SUMIF($X$5:$BY$5,N$5,$X44:$BY44) -> 2381 | O44: =+SUMIF($X$5:$BY$5,O$5,$X44:$BY44) -> 2431 | ... T44: =+SUMIF($X$5:$BY$5,T$5,$X44:$BY44) -> 3537.773 | Y44: =Y55*0.88 -> -28.16 | Z44: =Z55*0.88 -> 192.72 | AA44: =AA55*0.88 -> 324.72 | AB44: =AB55*0.88 -> 64.24 | AC44: =AC55*0.88 -> -96.8 | AD44: =AD55*0.88 -> 161.04 | AE44: =AE55*0.88 -> 218.24 | AF44: =AF55*0.88 -> 108.24 | ... AR44: =AR55*0.88 -> -58.08 | AS44: 403 | AT44: 511 | AU44: 808 | AV44: 667 | AW44: 685 | AX44: 679 | AY44: 369 | AZ44: 648 | BA44: 422 | BB44: 664 | BC44: 770 | BD44: 575 | BE44: 705 | BF44: =Revenue!BF36 -> 669.93093 | BG44: =Revenue!BG36 -> 748.7587 | BH44: =Revenue!BH36 -> 741.61165 | BI44: =Revenue!BI36 -> 787.74496 | BJ44: =Revenue!BJ36 -> 703.42748 | BK44: =Revenue!BK36 -> 786.19664 | BL44: =Revenue!BL36 -> 778.69223 | BM44: =Revenue!BM36 -> 827.1322 | ... BX44: =Revenue!BX36 -> 901.4336
B45: =B13 -> Composite Materials | G45: =G$10 -> JPY M | H45: =+SUMIF($X$5:$BY$5,H$5,$X45:$BY45) -> 3937 | I45: =+SUMIF($X$5:$BY$5,I$5,$X45:$BY45) -> 3091 | J45: =+SUMIF($X$5:$BY$5,J$5,$X45:$BY45) -> 2368 | K45: =+SUMIF($X$5:$BY$5,K$5,$X45:$BY45) -> 1733 | L45: =+SUMIF($X$5:$BY$5,L$5,$X45:$BY45) -> -1680 | M45: =+SUMIF($X$5:$BY$5,M$5,$X45:$BY45) -> -731 | N45: =+SUMIF($X$5:$BY$5,N$5,$X45:$BY45) -> -900 | O45: =+SUMIF($X$5:$BY$5,O$5,$X45:$BY45) -> -122 | ... T45: =+SUMIF($X$5:$BY$5,T$5,$X45:$BY45) -> -57.462009 | Y45: =Y53 -> 1054 | Z45: =Z53 -> 1126 | AA45: =AA53 -> 974 | AB45: =AB53 -> 783 | AC45: =AC53 -> 659 | AD45: =AD53 -> 396 | AE45: =AE53 -> 659 | AF45: =AF53 -> 1377 | ... AR45: =AR53 -> -1566 | AS45: -340 | AT45: -11 | AU45: 32 | AV45: -412 | AW45: -368 | AX45: -300 | AY45: -63 | AZ45: -169 | BA45: -15 | BB45: -122 | BC45: -48 | BD45: 63 | BE45: 0 | BF45: =Revenue!BF37 -> -113.4776 | BG45: =Revenue!BG37 -> -41.632 | BH45: =Revenue!BH37 -> 69.722 | BI45: =Revenue!BI37 -> 2.298 | BJ45: =Revenue!BJ37 -> -111.09133 | BK45: =Revenue!BK37 -> -39.53056 | BL45: =Revenue!BL37 -> 71.94026 | BM45: =Revenue!BM37 -> 3.87596 | ... BX45: =Revenue!BX37 -> 76.601877
B46: =B14 -> Materials Solution | G46: =G$10 -> JPY M | H46: =+SUMIF($X$5:$BY$5,H$5,$X46:$BY46) -> 542.61 | I46: =+SUMIF($X$5:$BY$5,I$5,$X46:$BY46) -> 724.65 | J46: =+SUMIF($X$5:$BY$5,J$5,$X46:$BY46) -> 640.82 | K46: =+SUMIF($X$5:$BY$5,K$5,$X46:$BY46) -> 735.55 | L46: =+SUMIF($X$5:$BY$5,L$5,$X46:$BY46) -> 813.26 | M46: =+SUMIF($X$5:$BY$5,M$5,$X46:$BY46) -> 824 | N46: =+SUMIF($X$5:$BY$5,N$5,$X46:$BY46) -> 839 | O46: =+SUMIF($X$5:$BY$5,O$5,$X46:$BY46) -> 588 | ... T46: =+SUMIF($X$5:$BY$5,T$5,$X46:$BY46) -> 579.51773 | Y46: =Y55*0.12+Y54*0.23+Y51 -> 124.5 | Z46: =Z55*0.12+Z54*0.23+Z51 -> 140.36 | AA46: =AA55*0.12+AA54*0.23+AA51 -> 171.93 | AB46: =AB55*0.12+AB54*0.23+AB51 -> 105.82 | AC46: =AC55*0.12+AC54*0.23+AC51 -> 122.96 | AD46: =AD55*0.12+AD54*0.23+AD51 -> 168.01 | AE46: =AE55*0.12+AE54*0.23+AE51 -> 194.9 | AF46: =AF55*0.12+AF54*0.23+AF51 -> 238.78 | ... AR46: =AR55*0.12+AR54*0.23+AR51 -> 6.11 | AS46: 222 | AT46: 206 | AU46: 224 | AV46: 172 | AW46: 159 | AX46: 109 | AY46: 294 | AZ46: 277 | BA46: 109 | BB46: 115 | BC46: 162 | BD46: 202 | BE46: 222 | BF46: =Revenue!BF38 -> 119.091 | BG46: =Revenue!BG38 -> 133.295 | BH46: =Revenue!BH38 -> 131.758 | BI46: =Revenue!BI38 -> 134.6725 | BJ46: =Revenue!BJ38 -> 122.66373 | BK46: =Revenue!BK38 -> 137.29385 | BL46: =Revenue!BL38 -> 135.71074 | BM46: =Revenue!BM38 -> 138.71268 | ... BX46: =Revenue!BX38 -> 148.29479
B47: =B15 -> Insulation Materials | G47: =G$10 -> JPY M | H47: =+SUMIF($X$5:$BY$5,H$5,$X47:$BY47) -> 1381.08 | I47: =+SUMIF($X$5:$BY$5,I$5,$X47:$BY47) -> 1984.92 | J47: =+SUMIF($X$5:$BY$5,J$5,$X47:$BY47) -> 1785.68 | K47: =+SUMIF($X$5:$BY$5,K$5,$X47:$BY47) -> 2084.2 | L47: =+SUMIF($X$5:$BY$5,L$5,$X47:$BY47) -> 2365.04 | M47: =+SUMIF($X$5:$BY$5,M$5,$X47:$BY47) -> 914 | N47: =+SUMIF($X$5:$BY$5,N$5,$X47:$BY47) -> 693 | O47: =+SUMIF($X$5:$BY$5,O$5,$X47:$BY47) -> 202 | ... T47: =+SUMIF($X$5:$BY$5,T$5,$X47:$BY47) -> 1059.0081 | Y47: =Y54*0.68 -> 379.44 | Z47: =Z54*0.68 -> 337.28 | AA47: =AA54*0.68 -> 377.4 | AB47: =AB54*0.68 -> 286.96 | AC47: =AC54*0.68 -> 402.56 | AD47: =AD54*0.68 -> 431.8 | AE47: =AE54*0.68 -> 488.24 | AF47: =AF54*0.68 -> 662.32 | ... AR47: =AR54*0.68 -> 41.48 | AS47: -26 | AT47: 267 | AU47: 469 | AV47: 204 | AW47: 166 | AX47: 186 | AY47: 382 | AZ47: -41 | BA47: -50 | BB47: -159 | BC47: 303 | BD47: 108 | BE47: 251 | BF47: =Revenue!BF39 -> -102.735 | BG47: =Revenue!BG39 -> 364.89 | BH47: =Revenue!BH39 -> 163.74 | BI47: =Revenue!BI39 -> 272.995 | BJ47: =Revenue!BJ39 -> -81.16675 | BK47: =Revenue!BK39 -> 388.6145 | BL47: =Revenue!BL39 -> 185.107 | BM47: =Revenue!BM39 -> 296.08975 | ... BX47: =Revenue!BX39 -> 255.83444
...

Sheet Revenue
A1: =Summary!C2 -> Nitto Boseki
A2: =Summary!C3 -> TYO: 3110 | F2: Case | G2: =Summary!C9 -> 2
B4: FQ | H4: A | I4: A | J4: A | K4: A | L4: A | M4: A | N4: A | O4: A | P4: E | Q4: E | R4: E | S4: E | T4: E | Y4: 1 | Z4: 2 | AA4: 3 | AB4: 4 | AC4: =Y4 -> 1 | AD4: =Z4 -> 2 | AE4: =AA4 -> 3 | AF4: =AB4 -> 4 | AG4: =AC4 -> 1 | AH4: =AD4 -> 2 | AI4: =AE4 -> 3 | AJ4: =AF4 -> 4 | ... BX4: =BT4 -> 4
B5: FY | H5: 2019 | I5: =H5+1 -> 2020 | J5: =I5+1 -> 2021 | K5: =J5+1 -> 2022 | L5: =K5+1 -> 2023 | M5: =L5+1 -> 2024 | N5: =M5+1 -> 2025 | O5: =N5+1 -> 2026 | P5: =O5+1 -> 2027 | ... T5: =S5+1 -> 2031 | V5: FY21-26 | W5: FY26-31 | Y5: 2019 | Z5: 2019 | AA5: 2019 | AB5: 2019 | AC5: =Y5+1 -> 2020 | AD5: =Z5+1 -> 2020 | AE5: =AA5+1 -> 2020 | AF5: =AB5+1 -> 2020 | AG5: =AC5+1 -> 2021 | AH5: =AD5+1 -> 2021 | AI5: =AE5+1 -> 2021 | AJ5: =AF5+1 -> 2021 | ... BX5: =BT5+1 -> 2031
B6: FY End | G6: Units | H6: 43555 | I6: =EOMONTH(J6,-12) -> 43921 | J6: =EOMONTH(K6,-12) -> 44286 | K6: =EOMONTH(L6,-12) -> 44651 | L6: =EOMONTH(M6,-12) -> 45016 | M6: =EOMONTH(N6,-12) -> 45382 | N6: =EOMONTH(O6,-12) -> 45747 | O6: =Summary!$C$6 -> 46112 | P6: =EOMONTH(O6,12) -> 46477 | Q6: =EOMONTH(P6,12) -> 46843 | R6: =EOMONTH(Q6,12) -> 47208 | S6: =EOMONTH(R6,12) -> 47573 | T6: =EOMONTH(S6,12) -> 47938 | V6: CAGR | W6: CAGR | Y6: 43281 | Z6: 43373 | AA6: 43465 | AB6: 43555 | AC6: =EOMONTH(AD6,-3) -> 43646 | AD6: =EOMONTH(AE6,-3) -> 43738 | AE6: =EOMONTH(AF6,-3) -> 43830 | AF6: =EOMONTH(AG6,-3) -> 43921 | AG6: =EOMONTH(AH6,-3) -> 44012 | AH6: =EOMONTH(AI6,-3) -> 44104 | AI6: =EOMONTH(AJ6,-3) -> 44196 | AJ6: =EOMONTH(AK6,-3) -> 44286 | ... BC6: =EOMONTH(BD6,-3) -> 46022 | BD6: =Summary!C6 -> 46112 | BE6: =EOMONTH(BD6,3) -> 46203 | BF6: =EOMONTH(BE6,3) -> 46295 | BG6: =EOMONTH(BF6,3) -> 46387 | BH6: =EOMONTH(BG6,3) -> 46477 | BI6: =EOMONTH(BH6,3) -> 46568 | BJ6: =EOMONTH(BI6,3) -> 46660 | BK6: =EOMONTH(BJ6,3) -> 46752 | BL6: =EOMONTH(BK6,3) -> 46843 | ... BX6: =EOMONTH(BW6,3) -> 47938 | BZ6: Source | CA6: Notes
A8: x | B8: SUMMARY
B10: Revenue | G10: =Summary!C8 -> JPY M | H10: =+SUMIF($X$5:$BY$5,H$5,$X10:$BY10) -> 82290 | I10: =+SUMIF($X$5:$BY$5,I$5,$X10:$BY10) -> 85720 | J10: =+SUMIF($X$5:$BY$5,J$5,$X10:$BY10) -> 78725 | K10: =+SUMIF($X$5:$BY$5,K$5,$X10:$BY10) -> 84049 | L10: =+SUMIF($X$5:$BY$5,L$5,$X10:$BY10) -> 87528 | M10: =+SUMIF($X$5:$BY$5,M$5,$X10:$BY10) -> 93250 | N10: =+SUMIF($X$5:$BY$5,N$5,$X10:$BY10) -> 109033 | O10: =+SUMIF($X$5:$BY$5,O$5,$X10:$BY10) -> 118226 | ... T10: =+SUMIF($X$5:$BY$5,T$5,$X10:$BY10) -> 193564.08 | V10: =(O10/J10)^(1/(O$5-J$5))-1 -> 0.084726038 | W10: =(T10/O10)^(1/(T$5-O$5))-1 -> 0.1036271 | Y10: =SUM(Y11:Y16) -> 20447 | Z10: =SUM(Z11:Z16) -> 21054 | AA10: =SUM(AA11:AA16) -> 21677 | AB10: =SUM(AB11:AB16) -> 19112 | AC10: =SUM(AC11:AC16) -> 20620 | AD10: =SUM(AD11:AD16) -> 22140 | AE10: =SUM(AE11:AE16) -> 21297 | AF10: =SUM(AF11:AF16) -> 21663 | ... BX10: =SUM(BX11:BX16) -> 49018.055
B11: Electronic Materials | G11: =G$10 -> JPY M | H11: =+SUMIF($X$5:$BY$5,H$5,$X11:$BY11) -> 19786.95 | I11: =+SUMIF($X$5:$BY$5,I$5,$X11:$BY11) -> 23638.2 | J11: =+SUMIF($X$5:$BY$5,J$5,$X11:$BY11) -> 23371.65 | K11: =+SUMIF($X$5:$BY$5,K$5,$X11:$BY11) -> 25381.75 | L11: =+SUMIF($X$5:$BY$5,L$5,$X11:$BY11) -> 25538.3 | M11: =+SUMIF($X$5:$BY$5,M$5,$X11:$BY11) -> 29812.85 | N11: =+SUMIF($X$5:$BY$5,N$5,$X11:$BY11) -> 40911 | O11: =+SUMIF($X$5:$BY$5,O$5,$X11:$BY11) -> 49265 | ... T11: =+SUMIF($X$5:$BY$5,T$5,$X11:$BY11) -> 94669.213 | Y11: ='3FS'!Y11 -> 4915.4 | Z11: ='3FS'!Z11 -> 4969.3 | AA11: ='3FS'!AA11 -> 5242.25 | AB11: ='3FS'!AB11 -> 4660 | AC11: ='3FS'!AC11 -> 5033.1 | AD11: ='3FS'!AD11 -> 6130.35 | AE11: ='3FS'!AE11 -> 6084.75 | AF11: ='3FS'!AF11 -> 6390 | ... BE11: ='3FS'!BE11 -> 14589 | BF11: =BF71 -> 15134.711 | BG11: =BG71 -> 15438.299 | BH11: =BH71 -> 16392.44 | BI11: =BI71 -> 17139.195 | BJ11: =BJ71 -> 18369.786 | BK11: =BK71 -> 19144.496 | BL11: =BL71 -> 20394.819 | BM11: =BM71 -> 19946.043 | ... BX11: =BX71 -> 24187.021
B12: Medical | G12: =G$10 -> JPY M | H12: =+SUMIF($X$5:$BY$5,H$5,$X12:$BY12) -> 12048.96 | I12: =+SUMIF($X$5:$BY$5,I$5,$X12:$BY12) -> 13245.76 | J12: =+SUMIF($X$5:$BY$5,J$5,$X12:$BY12) -> 11880 | K12: =+SUMIF($X$5:$BY$5,K$5,$X12:$BY12) -> 13983.2 | L12: =+SUMIF($X$5:$BY$5,L$5,$X12:$BY12) -> 14747.92 | M12: =+SUMIF($X$5:$BY$5,M$5,$X12:$BY12) -> 12703.68 | N12: =+SUMIF($X$5:$BY$5,N$5,$X12:$BY12) -> 13603 | O12: =+SUMIF($X$5:$BY$5,O$5,$X12:$BY12) -> 13850 | ... T12: =+SUMIF($X$5:$BY$5,T$5,$X12:$BY12) -> 18004.023 | Y12: ='3FS'!Y12 -> 3166.24 | Z12: ='3FS'!Z12 -> 3158.32 | AA12: ='3FS'!AA12 -> 2966.48 | AB12: ='3FS'!AB12 -> 2757.92 | AC12: ='3FS'!AC12 -> 3387.12 | AD12: ='3FS'!AD12 -> 3511.2 | AE12: ='3FS'!AE12 -> 3119.6 | AF12: ='3FS'!AF12 -> 3227.84 | ... BE12: ='3FS'!BE12 -> 3818 | BF12: =BF156 -> 3409.3346 | BG12: =BG156 -> 3810.4957 | BH12: =BH156 -> 3774.1237 | BI12: =BI156 -> 4008.9 | BJ12: =BJ156 -> 3579.8013 | BK12: =BK156 -> 4001.0205 | BL12: =BL156 -> 3962.8299 | BM12: =BM156 -> 4209.345 | ... BX12: =BX156 -> 4587.471
B13: Composite Materials | G13: =G$10 -> JPY M | H13: =+SUMIF($X$5:$BY$5,H$5,$X13:$BY13) -> 12692.16 | I13: =+SUMIF($X$5:$BY$5,I$5,$X13:$BY13) -> 12008.16 | J13: =+SUMIF($X$5:$BY$5,J$5,$X13:$BY13) -> 11099.52 | K13: =+SUMIF($X$5:$BY$5,K$5,$X13:$BY13) -> 11205.6 | L13: =+SUMIF($X$5:$BY$5,L$5,$X13:$BY13) -> 11504.64 | M13: =+SUMIF($X$5:$BY$5,M$5,$X13:$BY13) -> 12571.68 | N13: =+SUMIF($X$5:$BY$5,N$5,$X13:$BY13) -> 13474 | O13: =+SUMIF($X$5:$BY$5,O$5,$X13:$BY13) -> 13401 | ... T13: =+SUMIF($X$5:$BY$5,T$5,$X13:$BY13) -> 16402.9 | Y13: ='3FS'!Y13 -> 3249.12 | Z13: ='3FS'!Z13 -> 3287.04 | AA13: ='3FS'!AA13 -> 3316.8 | AB13: ='3FS'!AB13 -> 2839.2 | AC13: ='3FS'!AC13 -> 3156.48 | AD13: ='3FS'!AD13 -> 3142.08 | AE13: ='3FS'!AE13 -> 2779.2 | AF13: ='3FS'!AF13 -> 2930.4 | ... BE13: ='3FS'!BE13 -> 3830 | BF13: =BF166 -> 3977.12 | BG13: =BG166 -> 3502.4 | BH13: =BH166 -> 3697.1 | BI13: =BI166 -> 3944.9 | BJ13: =BJ166 -> 4096.4336 | BK13: =BK166 -> 3607.472 | BL13: =BL166 -> 3808.013 | BM13: =BM166 -> 4023.798 | ... BX13: =BX166 -> 4041.0939
B14: Materials Solution | G14: =G$10 -> JPY M | H14: =+SUMIF($X$5:$BY$5,H$5,$X14:$BY14) -> 11515.59 | I14: =+SUMIF($X$5:$BY$5,I$5,$X14:$BY14) -> 10343.32 | J14: =+SUMIF($X$5:$BY$5,J$5,$X14:$BY14) -> 8142.57 | K14: =+SUMIF($X$5:$BY$5,K$5,$X14:$BY14) -> 8658.47 | L14: =+SUMIF($X$5:$BY$5,L$5,$X14:$BY14) -> 9050.09 | M14: =+SUMIF($X$5:$BY$5,M$5,$X14:$BY14) -> 9094.83 | N14: =+SUMIF($X$5:$BY$5,N$5,$X14:$BY14) -> 9431 | O14: =+SUMIF($X$5:$BY$5,O$5,$X14:$BY14) -> 9515 | ... T14: =+SUMIF($X$5:$BY$5,T$5,$X14:$BY14) -> 11590.355 | Y14: ='3FS'!Y14 -> 2894.22 | Z14: ='3FS'!Z14 -> 2901.21 | AA14: ='3FS'!AA14 -> 3080.24 | AB14: ='3FS'!AB14 -> 2639.92 | AC14: ='3FS'!AC14 -> 2799.48 | AD14: ='3FS'!AD14 -> 2598.08 | AE14: ='3FS'!AE14 -> 2603.62 | AF14: ='3FS'!AF14 -> 2342.14 | ... BE14: ='3FS'!BE14 -> 2615 | BF14: =BF176 -> 2381.82 | BG14: =BG176 -> 2665.9 | BH14: =BH176 -> 2635.16 | BI14: =BI176 -> 2693.45 | BJ14: =BJ176 -> 2453.2746 | BK14: =BK176 -> 2745.877 | BL14: =BL176 -> 2714.2148 | BM14: =BM176 -> 2774.2535 | ... BX14: =BX176 -> 2965.8958
B15: Insulation Materials | G15: =G$10 -> JPY M | H15: =+SUMIF($X$5:$BY$5,H$5,$X15:$BY15) -> 14813.8 | I15: =+SUMIF($X$5:$BY$5,I$5,$X15:$BY15) -> 14549.28 | J15: =+SUMIF($X$5:$BY$5,J$5,$X15:$BY15) -> 12620.12 | K15: =+SUMIF($X$5:$BY$5,K$5,$X15:$BY15) -> 12531.72 | L15: =+SUMIF($X$5:$BY$5,L$5,$X15:$BY15) -> 13931.16 | M15: =+SUMIF($X$5:$BY$5,M$5,$X15:$BY15) -> 14713.16 | N15: =+SUMIF($X$5:$BY$5,N$5,$X15:$BY15) -> 15320 | O15: =+SUMIF($X$5:$BY$5,O$5,$X15:$BY15) -> 15136 | ... T15: =+SUMIF($X$5:$BY$5,T$5,$X15:$BY15) -> 21552.081 | Y15: ='3FS'!Y15 -> 3469.36 | Z15: ='3FS'!Z15 -> 3679.48 | AA15: ='3FS'!AA15 -> 4055.52 | AB15: ='3FS'!AB15 -> 3609.44 | AC15: ='3FS'!AC15 -> 3549.6 | AD15: ='3FS'!AD15 -> 3696.48 | AE15: ='3FS'!AE15 -> 3681.52 | AF15: ='3FS'!AF15 -> 3621.68 | ... BE15: ='3FS'!BE15 -> 4399 | BF15: =BF186 -> 4313.65 | BG15: =BG186 -> 4744.9 | BH15: =BH186 -> 4273.4 | BI15: =BI186 -> 4618.95 | BJ15: =BJ186 -> 4529.3325 | BK15: =BK186 -> 4982.145 | BL15: =BL186 -> 4487.07 | BM15: =BM186 -> 4849.8975 | ... BX15: =BX186 -> 5194.3444
B16: Other Business | G16: =G$10 -> JPY M | H16: =+SUMIF($X$5:$BY$5,H$5,$X16:$BY16) -> 11432.54 | I16: =+SUMIF($X$5:$BY$5,I$5,$X16:$BY16) -> 11935.28 | J16: =+SUMIF($X$5:$BY$5,J$5,$X16:$BY16) -> 11611.14 | K16: =+SUMIF($X$5:$BY$5,K$5,$X16:$BY16) -> 12288.26 | L16: =+SUMIF($X$5:$BY$5,L$5,$X16:$BY16) -> 12755.89 | M16: =+SUMIF($X$5:$BY$5,M$5,$X16:$BY16) -> 14353.8 | N16: =+SUMIF($X$5:$BY$5,N$5,$X16:$BY16) -> 16294 | O16: =+SUMIF($X$5:$BY$5,O$5,$X16:$BY16) -> 17059 | ... T16: =+SUMIF($X$5:$BY$5,T$5,$X16:$BY16) -> 31345.513 | Y16: ='3FS'!Y16 -> 2752.66 | Z16: ='3FS'!Z16 -> 3058.65 | AA16: ='3FS'!AA16 -> 3015.71 | AB16: ='3FS'!AB16 -> 2605.52 | AC16: ='3FS'!AC16 -> 2694.22 | AD16: ='3FS'!AD16 -> 3061.81 | AE16: ='3FS'!AE16 -> 3028.31 | AF16: ='3FS'!AF16 -> 3150.94 | ... BE16: ='3FS'!BE16 -> 4780 | BF16: =BF196 -> 4848.83 | BG16: =BG196 -> 4663.51 | BH16: =BH196 -> 4932.45 | BI16: =BI196 -> 5401.4 | BJ16: =BJ196 -> 5479.1779 | BK16: =BK196 -> 5269.7663 | BL16: =BL196 -> 5573.6685 | BM16: =BM196 -> 6103.582 | ... BX16: =BX196 -> 8042.2296
B18: Mix
B19: =B11 -> Electronic Materials | G19: % | H19: =IFERROR(H11/H$10,"nm") -> 0.24045388 | I19: =IFERROR(I11/I$10,"nm") -> 0.27576062 | J19: =IFERROR(J11/J$10,"nm") -> 0.2968771 | K19: =IFERROR(K11/K$10,"nm") -> 0.30198753 | L19: =IFERROR(L11/L$10,"nm") -> 0.29177292 | M19: =IFERROR(M11/M$10,"nm") -> 0.31970885 | N19: =IFERROR(N11/N$10,"nm") -> 0.37521668 | O19: =IFERROR(O11/O$10,"nm") -> 0.41670191 | ... T19: =IFERROR(T11/T$10,"nm") -> 0.4890846 | Y19: =IFERROR(Y11/Y$10,"nm") -> 0.24039712 | Z19: =IFERROR(Z11/Z$10,"nm") -> 0.23602641 | AA19: =IFERROR(AA11/AA$10,"nm") -> 0.24183466 | AB19: =IFERROR(AB11/AB$10,"nm") -> 0.24382587 | AC19: =IFERROR(AC11/AC$10,"nm") -> 0.24408826 | AD19: =IFERROR(AD11/AD$10,"nm") -> 0.27689024 | AE19: =IFERROR(AE11/AE$10,"nm") -> 0.28570925 | AF19: =IFERROR(AF11/AF$10,"nm") -> 0.294973 | ... BX19: =IFERROR(BX11/BX$10,"nm") -> 0.49343085
B20: =B12 -> Medical | G20: % | H20: =IFERROR(H12/H$10,"nm") -> 0.14642071 | I20: =IFERROR(I12/I$10,"nm") -> 0.15452357 | J20: =IFERROR(J12/J$10,"nm") -> 0.15090505 | K20: =IFERROR(K12/K$10,"nm") -> 0.16636962 | L20: =IFERROR(L12/L$10,"nm") -> 0.16849374 | M20: =IFERROR(M12/M$10,"nm") -> 0.13623249 | N20: =IFERROR(N12/N$10,"nm") -> 0.12476039 | O20: =IFERROR(O12/O$10,"nm") -> 0.11714851 | ... T20: =IFERROR(T12/T$10,"nm") -> 0.093013241 | Y20: =IFERROR(Y12/Y$10,"nm") -> 0.15485108 | Z20: =IFERROR(Z12/Z$10,"nm") -> 0.15001045 | AA20: =IFERROR(AA12/AA$10,"nm") -> 0.13684919 | AB20: =IFERROR(AB12/AB$10,"nm") -> 0.14430306 | AC20: =IFERROR(AC12/AC$10,"nm") -> 0.16426382 | AD20: =IFERROR(AD12/AD$10,"nm") -> 0.15859079 | AE20: =IFERROR(AE12/AE$10,"nm") -> 0.14648072 | AF20: =IFERROR(AF12/AF$10,"nm") -> 0.14900245 | ... BX20: =IFERROR(BX12/BX$10,"nm") -> 0.093587373
B21: =B13 -> Composite Materials | G21: % | H21: =IFERROR(H13/H$10,"nm") -> 0.15423697 | I21: =IFERROR(I13/I$10,"nm") -> 0.14008586 | J21: =IFERROR(J13/J$10,"nm") -> 0.14099104 | K21: =IFERROR(K13/K$10,"nm") -> 0.13332223 | L21: =IFERROR(L13/L$10,"nm") -> 0.13143954 | M21: =IFERROR(M13/M$10,"nm") -> 0.13481694 | N21: =IFERROR(N13/N$10,"nm") -> 0.12357727 | O21: =IFERROR(O13/O$10,"nm") -> 0.1133507 | ... T21: =IFERROR(T13/T$10,"nm") -> 0.084741442 | Y21: =IFERROR(Y13/Y$10,"nm") -> 0.15890448 | Z21: =IFERROR(Z13/Z$10,"nm") -> 0.15612425 | AA21: =IFERROR(AA13/AA$10,"nm") -> 0.1530101 | AB21: =IFERROR(AB13/AB$10,"nm") -> 0.14855588 | AC21: =IFERROR(AC13/AC$10,"nm") -> 0.15307856 | AD21: =IFERROR(AD13/AD$10,"nm") -> 0.1419187 | AE21: =IFERROR(AE13/AE$10,"nm") -> 0.13049725 | AF21: =IFERROR(AF13/AF$10,"nm") -> 0.13527212 | ... BX21: =IFERROR(BX13/BX$10,"nm") -> 0.082440926
B22: =B14 -> Materials Solution | G22: % | H22: =IFERROR(H14/H$10,"nm") -> 0.13993912 | I22: =IFERROR(I14/I$10,"nm") -> 0.12066402 | J22: =IFERROR(J14/J$10,"nm") -> 0.10343055 | K22: =IFERROR(K14/K$10,"nm") -> 0.10301693 | L22: =IFERROR(L14/L$10,"nm") -> 0.10339651 | M22: =IFERROR(M14/M$10,"nm") -> 0.097531689 | N22: =IFERROR(N14/N$10,"nm") -> 0.086496749 | O22: =IFERROR(O14/O$10,"nm") -> 0.080481451 | ... T22: =IFERROR(T14/T$10,"nm") -> 0.059878643 | Y22: =IFERROR(Y14/Y$10,"nm") -> 0.14154742 | Z22: =IFERROR(Z14/Z$10,"nm") -> 0.13779852 | AA22: =IFERROR(AA14/AA$10,"nm") -> 0.14209715 | AB22: =IFERROR(AB14/AB$10,"nm") -> 0.13812892 | AC22: =IFERROR(AC14/AC$10,"nm") -> 0.13576528 | AD22: =IFERROR(AD14/AD$10,"nm") -> 0.11734779 | AE22: =IFERROR(AE14/AE$10,"nm") -> 0.1222529 | AF22: =IFERROR(AF14/AF$10,"nm") -> 0.10811707 | ... BX22: =IFERROR(BX14/BX$10,"nm") -> 0.060506191
B23: =B15 -> Insulation Materials | G23: % | H23: =IFERROR(H15/H$10,"nm") -> 0.18001944 | I23: =IFERROR(I15/I$10,"nm") -> 0.16973028 | J23: =IFERROR(J15/J$10,"nm") -> 0.16030638 | K23: =IFERROR(K15/K$10,"nm") -> 0.14910017 | L23: =IFERROR(L15/L$10,"nm") -> 0.15916233 | M23: =IFERROR(M15/M$10,"nm") -> 0.15778188 | N23: =IFERROR(N15/N$10,"nm") -> 0.14050792 | O23: =IFERROR(O15/O$10,"nm") -> 0.12802598 | ... T23: =IFERROR(T15/T$10,"nm") -> 0.11134339 | Y23: =IFERROR(Y15/Y$10,"nm") -> 0.16967575 | Z23: =IFERROR(Z15/Z$10,"nm") -> 0.17476394 | AA23: =IFERROR(AA15/AA$10,"nm") -> 0.18708862 | AB23: =IFERROR(AB15/AB$10,"nm") -> 0.18885726 | AC23: =IFERROR(AC15/AC$10,"nm") -> 0.17214355 | AD23: =IFERROR(AD15/AD$10,"nm") -> 0.16695935 | AE23: =IFERROR(AE15/AE$10,"nm") -> 0.17286566 | AF23: =IFERROR(AF15/AF$10,"nm") -> 0.16718275 | ... BX23: =IFERROR(BX15/BX$10,"nm") -> 0.10596798
B24: =B16 -> Other Business | G24: % | H24: =IFERROR(H16/H$10,"nm") -> 0.13892988 | I24: =IFERROR(I16/I$10,"nm") -> 0.13923565 | J24: =IFERROR(J16/J$10,"nm") -> 0.14748987 | K24: =IFERROR(K16/K$10,"nm") -> 0.14620352 | L24: =IFERROR(L16/L$10,"nm") -> 0.14573496 | M24: =IFERROR(M16/M$10,"nm") -> 0.15392815 | N24: =IFERROR(N16/N$10,"nm") -> 0.14944099 | O24: =IFERROR(O16/O$10,"nm") -> 0.14429144 | ... T24: =IFERROR(T16/T$10,"nm") -> 0.16193868 | Y24: =IFERROR(Y16/Y$10,"nm") -> 0.13462415 | Z24: =IFERROR(Z16/Z$10,"nm") -> 0.14527643 | AA24: =IFERROR(AA16/AA$10,"nm") -> 0.13912027 | AB24: =IFERROR(AB16/AB$10,"nm") -> 0.13632901 | AC24: =IFERROR(AC16/AC$10,"nm") -> 0.13066052 | AD24: =IFERROR(AD16/AD$10,"nm") -> 0.13829313 | AE24: =IFERROR(AE16/AE$10,"nm") -> 0.14219421 | AF24: =IFERROR(AF16/AF$10,"nm") -> 0.14545262 | ... BX24: =IFERROR(BX16/BX$10,"nm") -> 0.16406668
B26: Y/Y | I26: =IFERROR(I10/H10-1,"nm") -> 0.041681857 | J26: =IFERROR(J10/I10-1,"nm") -> -0.081602893 | K26: =IFERROR(K10/J10-1,"nm") -> 0.067627818 | L26: =IFERROR(L10/K10-1,"nm") -> 0.041392521 | M26: =IFERROR(M10/L10-1,"nm") -> 0.065373366 | N26: =IFERROR(N10/M10-1,"nm") -> 0.16925469 | O26: =IFERROR(O10/N10-1,"nm") -> 0.084313923 | P26: =IFERROR(P10/O10-1,"nm") -> 0.17255632 | ... T26: =IFERROR(T10/S10-1,"nm") -> 0.064201151
B27: =B11 -> Electronic Materials | G27: % | I27: =IFERROR(I11/H11-1,"nm") -> 0.19463586 | J27: =IFERROR(J11/I11-1,"nm") -> -0.011276239 | K27: =IFERROR(K11/J11-1,"nm") -> 0.086005909 | L27: =IFERROR(L11/K11-1,"nm") -> 0.0061678174 | M27: =IFERROR(M11/L11-1,"nm") -> 0.16737802 | N27: =IFERROR(N11/M11-1,"nm") -> 0.37226062 | O27: =IFERROR(O11/N11-1,"nm") -> 0.20419936 | P27: =IFERROR(P11/O11-1,"nm") -> 0.24945599 | ... T27: =IFERROR(T11/S11-1,"nm") -> 0.06201855 | AC27: =IFERROR(AC11/Y11-1,"nm") -> 0.023945152 | AD27: =IFERROR(AD11/Z11-1,"nm") -> 0.23364458 | AE27: =IFERROR(AE11/AA11-1,"nm") -> 0.16071343 | AF27: =IFERROR(AF11/AB11-1,"nm") -> 0.37124464 | AG27: =IFERROR(AG11/AC11-1,"nm") -> 0.22063937 | AH27: =IFERROR(AH11/AD11-1,"nm") -> -0.15506456 | AI27: =IFERROR(AI11/AE11-1,"nm") -> -0.049287152 | AJ27: =IFERROR(AJ11/AF11-1,"nm") -> -0.019804382 | ... BX27: =IFERROR(BX11/BT11-1,"nm") -> 0.059641915
B28: =B12 -> Medical | G28: % | I28: =IFERROR(I12/H12-1,"nm") -> 0.099328075 | J28: =IFERROR(J12/I12-1,"nm") -> -0.10310922 | K28: =IFERROR(K12/J12-1,"nm") -> 0.17703704 | L28: =IFERROR(L12/K12-1,"nm") -> 0.054688483 | M28: =IFERROR(M12/L12-1,"nm") -> -0.13861209 | N28: =IFERROR(N12/M12-1,"nm") -> 0.070792085 | O28: =IFERROR(O12/N12-1,"nm") -> 0.018157759 | P28: =IFERROR(P12/O12-1,"nm") -> 0.069455163 | ... T28: =IFERROR(T12/S12-1,"nm") -> 0.05 | AC28: =IFERROR(AC12/Y12-1,"nm") -> 0.069760978 | AD28: =IFERROR(AD12/Z12-1,"nm") -> 0.11173029 | AE28: =IFERROR(AE12/AA12-1,"nm") -> 0.051616731 | AF28: =IFERROR(AF12/AB12-1,"nm") -> 0.17038928 | AG28: =IFERROR(AG12/AC12-1,"nm") -> -0.1610808 | AH28: =IFERROR(AH12/AD12-1,"nm") -> -0.091478697 | AI28: =IFERROR(AI12/AE12-1,"nm") -> -0.092242595 | AJ28: =IFERROR(AJ12/AF12-1,"nm") -> -0.065430752 | ... BX28: =IFERROR(BX12/BT12-1,"nm") -> 0.05
B29: =B13 -> Composite Materials | G29: % | I29: =IFERROR(I13/H13-1,"nm") -> -0.053891536 | J29: =IFERROR(J13/I13-1,"nm") -> -0.075668545 | K29: =IFERROR(K13/J13-1,"nm") -> 0.00955717 | L29: =IFERROR(L13/K13-1,"nm") -> 0.026686657 | M29: =IFERROR(M13/L13-1,"nm") -> 0.092748665 | N29: =IFERROR(N13/M13-1,"nm") -> 0.071774019 | O29: =IFERROR(O13/N13-1,"nm") -> -0.0054178418 | P29: =IFERROR(P13/O13-1,"nm") -> 0.11981345 | ... T29: =IFERROR(T13/S13-1,"nm") -> 0.02 | AC29: =IFERROR(AC13/Y13-1,"nm") -> -0.028512336 | AD29: =IFERROR(AD13/Z13-1,"nm") -> -0.044100467 | AE29: =IFERROR(AE13/AA13-1,"nm") -> -0.16208394 | AF29: =IFERROR(AF13/AB13-1,"nm") -> 0.032121724 | AG29: =IFERROR(AG13/AC13-1,"nm") -> -0.13534063 | AH29: =IFERROR(AH13/AD13-1,"nm") -> -0.21784296 | AI29: =IFERROR(AI13/AE13-1,"nm") -> 0.082210708 | AJ29: =IFERROR(AJ13/AF13-1,"nm") -> -0.0086814087 | ... BX29: =IFERROR(BX13/BT13-1,"nm") -> 0.02
B30: =B14 -> Materials Solution | G30: % | I30: =IFERROR(I14/H14-1,"nm") -> -0.10179852 | J30: =IFERROR(J14/I14-1,"nm") -> -0.21277017 | K30: =IFERROR(K14/J14-1,"nm") -> 0.063358375 | L30: =IFERROR(L14/K14-1,"nm") -> 0.0452297 | M30: =IFERROR(M14/L14-1,"nm") -> 0.0049435972 | N30: =IFERROR(N14/M14-1,"nm") -> 0.036962758 | O30: =IFERROR(O14/N14-1,"nm") -> 0.0089067967 | P30: =IFERROR(P14/O14-1,"nm") -> 0.082278508 | ... T30: =IFERROR(T14/S14-1,"nm") -> 0.03 | AC30: =IFERROR(AC14/Y14-1,"nm") -> -0.032734208 | AD30: =IFERROR(AD14/Z14-1,"nm") -> -0.10448399 | AE30: =IFERROR(AE14/AA14-1,"nm") -> -0.1547347 | AF30: =IFERROR(AF14/AB14-1,"nm") -> -0.11279887 | AG30: =IFERROR(AG14/AC14-1,"nm") -> -0.30315987 | AH30: =IFERROR(AH14/AD14-1,"nm") -> -0.22405392 | AI30: =IFERROR(AI14/AE14-1,"nm") -> -0.16790469 | AJ30: =IFERROR(AJ14/AF14-1,"nm") -> -0.142088 | ... BX30: =IFERROR(BX14/BT14-1,"nm") -> 0.03
B31: =B15 -> Insulation Materials | G31: % | I31: =IFERROR(I15/H15-1,"nm") -> -0.017856323 | J31: =IFERROR(J15/I15-1,"nm") -> -0.13259488 | K31: =IFERROR(K15/J15-1,"nm") -> -0.0070046878 | L31: =IFERROR(L15/K15-1,"nm") -> 0.11167182 | M31: =IFERROR(M15/L15-1,"nm") -> 0.056133158 | N31: =IFERROR(N15/M15-1,"nm") -> 0.041244709 | O31: =IFERROR(O15/N15-1,"nm") -> -0.012010444 | P31: =IFERROR(P15/O15-1,"nm") -> 0.17144226 | ... T31: =IFERROR(T15/S15-1,"nm") -> 0.05 | AC31: =IFERROR(AC15/Y15-1,"nm") -> 0.023128185 | AD31: =IFERROR(AD15/Z15-1,"nm") -> 0.0046202181 | AE31: =IFERROR(AE15/AA15-1,"nm") -> -0.092219987 | AF31: =IFERROR(AF15/AB15-1,"nm") -> 0.0033911078 | AG31: =IFERROR(AG15/AC15-1,"nm") -> -0.15766284 | AH31: =IFERROR(AH15/AD15-1,"nm") -> -0.14661516 | AI31: =IFERROR(AI15/AE15-1,"nm") -> -0.093091984 | AJ31: =IFERROR(AJ15/AF15-1,"nm") -> -0.13387157 | ... BX31: =IFERROR(BX15/BT15-1,"nm") -> 0.05
B32: =B16 -> Other Business | G32: % | I32: =IFERROR(I16/H16-1,"nm") -> 0.04397448 | J32: =IFERROR(J16/I16-1,"nm") -> -0.02715814 | K32: =IFERROR(K16/J16-1,"nm") -> 0.05831641 | L32: =IFERROR(L16/K16-1,"nm") -> 0.038055022 | M32: =IFERROR(M16/L16-1,"nm") -> 0.12526841 | N32: =IFERROR(N16/M16-1,"nm") -> 0.13516978 | O32: =IFERROR(O16/N16-1,"nm") -> 0.046949797 | P32: =IFERROR(P16/O16-1,"nm") -> 0.12695879 | ... T32: =IFERROR(T16/S16-1,"nm") -> 0.13 | AC32: =IFERROR(AC16/Y16-1,"nm") -> -0.021230374 | AD32: =IFERROR(AD16/Z16-1,"nm") -> 0.0010331355 | AE32: =IFERROR(AE16/AA16-1,"nm") -> 0.0041781206 | AF32: =IFERROR(AF16/AB16-1,"nm") -> 0.20933249 | AG32: =IFERROR(AG16/AC16-1,"nm") -> 0.085972935 | AH32: =IFERROR(AH16/AD16-1,"nm") -> -0.11844301 | AI32: =IFERROR(AI16/AE16-1,"nm") -> -0.020453652 | AJ32: =IFERROR(AJ16/AF16-1,"nm") -> -0.041632021 | ... BX32: =IFERROR(BX16/BT16-1,"nm") -> 0.13
B34: Operating profit | G34: =G$10 -> JPY M | H34: =+SUMIF($X$5:$BY$5,H$5,$X34:$BY34) -> 8198 | I34: =+SUMIF($X$5:$BY$5,I$5,$X34:$BY34) -> 8160 | J34: =+SUMIF($X$5:$BY$5,J$5,$X34:$BY34) -> 5964 | K34: =+SUMIF($X$5:$BY$5,K$5,$X34:$BY34) -> 7268 | L34: =+SUMIF($X$5:$BY$5,L$5,$X34:$BY34) -> 4880 | M34: =+SUMIF($X$5:$BY$5,M$5,$X34:$BY34) -> 8386 | N34: =+SUMIF($X$5:$BY$5,N$5,$X34:$BY34) -> 16444 | O34: =+SUMIF($X$5:$BY$5,O$5,$X34:$BY34) -> 20818 | ... T34: =+SUMIF($X$5:$BY$5,T$5,$X34:$BY34) -> 39963.536 | V34: =(O34/J34)^(1/(O$5-J$5))-1 -> 0.28404509 | W34: =(T34/O34)^(1/(T$5-O$5))-1 -> 0.13931806 | Y34: =SUM(Y35:Y41) -> 2126 | Z34: =SUM(Z35:Z41) -> 2266 | AA34: =SUM(AA35:AA41) -> 2473 | AB34: =SUM(AB35:AB41) -> 1333 | AC34: =SUM(AC35:AC41) -> 1698 | AD34: =SUM(AD35:AD41) -> 1696 | AE34: =SUM(AE35:AE41) -> 1846 | AF34: =SUM(AF35:AF41) -> 2920 | ... BX34: =SUM(BX35:BX41) -> 10466.666
B35: =B11 -> Electronic Materials | G35: =G$10 -> JPY M | H35: =+SUMIF($X$5:$BY$5,H$5,$X35:$BY35) -> 1970.07 | I35: =+SUMIF($X$5:$BY$5,I$5,$X35:$BY35) -> 2831.43 | J35: =+SUMIF($X$5:$BY$5,J$5,$X35:$BY35) -> 2547.22 | K35: =+SUMIF($X$5:$BY$5,K$5,$X35:$BY35) -> 2973.05 | L35: =+SUMIF($X$5:$BY$5,L$5,$X35:$BY35) -> 3373.66 | M35: =+SUMIF($X$5:$BY$5,M$5,$X35:$BY35) -> 5382 | N35: =+SUMIF($X$5:$BY$5,N$5,$X35:$BY35) -> 13880 | O35: =+SUMIF($X$5:$BY$5,O$5,$X35:$BY35) -> 19391 | ... T35: =+SUMIF($X$5:$BY$5,T$5,$X35:$BY35) -> 36494.34 | Y35: ='3FS'!Y43 -> 541.26 | Z35: ='3FS'!Z43 -> 481.12 | AA35: ='3FS'!AA43 -> 538.35 | AB35: ='3FS'!AB43 -> 409.34 | AC35: ='3FS'!AC43 -> 574.24 | AD35: ='3FS'!AD43 -> 615.95 | AE35: ='3FS'!AE43 -> 696.46 | AF35: ='3FS'!AF43 -> 944.78 | ... BE35: ='3FS'!BE43 -> 7036 | BF35: =BF79 -> 7240.8159 | BG35: =BG79 -> 6670.3097 | BH35: =BH79 -> 7196.3575 | BI35: =BI79 -> 7048.888 | BJ35: =BJ79 -> 7602.3859 | BK35: =BK79 -> 7973.2005 | BL35: =BL79 -> 9304.7129 | BM35: =BM79 -> 8022.5672 | ... BX35: =BX79 -> 9498.0834
B36: =B12 -> Medical | G36: =G$10 -> JPY M | H36: =+SUMIF($X$5:$BY$5,H$5,$X36:$BY36) -> 553.52 | I36: =+SUMIF($X$5:$BY$5,I$5,$X36:$BY36) -> 390.72 | J36: =+SUMIF($X$5:$BY$5,J$5,$X36:$BY36) -> 270.16 | K36: =+SUMIF($X$5:$BY$5,K$5,$X36:$BY36) -> 224.4 | L36: =+SUMIF($X$5:$BY$5,L$5,$X36:$BY36) -> 97.68 | M36: =+SUMIF($X$5:$BY$5,M$5,$X36:$BY36) -> 2389 | N36: =+SUMIF($X$5:$BY$5,N$5,$X36:$BY36) -> 2381 | O36: =+SUMIF($X$5:$BY$5,O$5,$X36:$BY36) -> 2431 | ... T36: =+SUMIF($X$5:$BY$5,T$5,$X36:$BY36) -> 3537.773 | Y36: ='3FS'!Y44 -> -28.16 | Z36: ='3FS'!Z44 -> 192.72 | AA36: ='3FS'!AA44 -> 324.72 | AB36: ='3FS'!AB44 -> 64.24 | AC36: ='3FS'!AC44 -> -96.8 | AD36: ='3FS'!AD44 -> 161.04 | AE36: ='3FS'!AE44 -> 218.24 | AF36: ='3FS'!AF44 -> 108.24 | ... BE36: ='3FS'!BE44 -> 705 | BF36: =BF159 -> 669.93093 | BG36: =BG159 -> 748.7587 | BH36: =BH159 -> 741.61165 | BI36: =BI159 -> 787.74496 | BJ36: =BJ159 -> 703.42748 | BK36: =BK159 -> 786.19664 | BL36: =BL159 -> 778.69223 | BM36: =BM159 -> 827.1322 | ... BX36: =BX159 -> 901.4336
